Workbook

Sheet Population Definitions
A1: Abbreviation | B1: Full Name | C1: Population type
A2: PWID_males | B2: People Who Inject Drugs (males) | C2: human
A3: PWID_females | B3: People Who Inject Drugs (females) | C3: human
A4: 0-9_males | B4: General Population 0-9 males | C4: human
A5: 0-9_females | B5: General Population 0-9 females | C5: human
A6: 10-17_males | B6: General Population 10-17 males | C6: human
A7: 10-17_females | B7: General Population 10-17 females | C7: human
A8: 18-64_males | B8: General Population 18-64 males | C8: human
A9: 18-64_females | B9: General Population 18-64 females | C9: human
A10: 65+_males | B10: General Population 65+ males | C10: human
A11: 65+_females | B11: General Population 65+ females | C11: human
A12: Prisoners_males | B12: Prisoners (males) | C12: human
A13: Prisoners_females | B13: Prisoners (females) | C13: human

Sheet Disease Burden
A1: Population living with chronic HCV | B1: Provenance | C1: Units | D1: Uncertainty | E1: 2000 | F1: 2001 | G1: 2002 | H1: 2003 | I1: 2004 | J1: 2005 | K1: 2006 | L1: 2007 | M1: 2008 | N1: 2009 | O1: 2010 | P1: 2011 | Q1: 2012 | R1: 2013 | S1: 2014 | T1: 2015 | U1: 2016 | V1: 2017 | W1: 2018 | X1: 2019 | Y1: 2020 | Z1: 2021 | AA1: 2022 | AB1: 2023 | AC1: 2024 | AD1: 2025 | AE1: 2026 | AF1: 2027 | AG1: 2028 | AH1: 2029 | AI1: 2030 | AJ1: 2031 | AK1: 2032 | AL1: 2033 | AM1: 2034 | AN1: 2035 | AO1: 2036 | AP1: 2037 | AQ1: 2038 | AR1: 2039 | AS1: 2040 | AT1: 2041 | AU1: 2042 | AV1: 2043 | AW1: 2044 | AX1: 2045 | AY1: 2046 | AZ1: 2047 | BA1: 2048 | BB1: 2049 | BC1: 2050
A2: ='Population Definitions'!$A$2 -> PWID_males | C2: Number | E2: 38.687876
A3: ='Population Definitions'!$A$3 -> PWID_females | C3: Number | E3: 11.847114
A4: ='Population Definitions'!$A$4 -> 0-9_males | C4: Number | E4: 0
A5: ='Population Definitions'!$A$5 -> 0-9_females | C5: Number | E5: 0
A6: ='Population Definitions'!$A$6 -> 10-17_males | C6: Number | E6: 0
A7: ='Population Definitions'!$A$7 -> 10-17_females | C7: Number | E7: 0
A8: ='Population Definitions'!$A$8 -> 18-64_males | C8: Number | E8: 0
A9: ='Population Definitions'!$A$9 -> 18-64_females | C9: Number | E9: 0
A10: ='Population Definitions'!$A$10 -> 65+_males | C10: Number | E10: 0
A11: ='Population Definitions'!$A$11 -> 65+_females | C11: Number | E11: 0
A12: ='Population Definitions'!$A$12 -> Prisoners_males | C12: Number | E12: 41.678
A13: ='Population Definitions'!$A$13 -> Prisoners_females | C13: Number | E13: 0
A15: HCV Prevalence | B15: Provenance | C15: Units | D15: Uncertainty | E15: 2000 | F15: 2001 | G15: 2002 | H15: 2003 | I15: 2004 | J15: 2005 | K15: 2006 | L15: 2007 | M15: 2008 | N15: 2009 | O15: 2010 | P15: 2011 | Q15: 2012 | R15: 2013 | S15: 2014 | T15: 2015 | U15: 2016 | V15: 2017 | W15: 2018 | X15: 2019 | Y15: 2020 | Z15: 2021 | AA15: 2022 | AB15: 2023 | AC15: 2024 | AD15: 2025 | AE15: 2026 | AF15: 2027 | AG15: 2028 | AH15: 2029 | AI15: 2030 | AJ15: 2031 | AK15: 2032 | AL15: 2033 | AM15: 2034 | AN15: 2035 | AO15: 2036 | AP15: 2037 | AQ15: 2038 | AR15: 2039 | AS15: 2040 | AT15: 2041 | AU15: 2042 | AV15: 2043 | AW15: 2044 | AX15: 2045 | AY15: 2046 | AZ15: 2047 | BA15: 2048 | BB15: 2049 | BC15: 2050
A16: ='Population Definitions'!$A$2 -> PWID_males | C16: Fraction | E16: 0.388 | O16: 0.388
A17: ='Population Definitions'!$A$3 -> PWID_females | C17: Fraction | E17: 0.388 | O17: 0.388
A18: ='Population Definitions'!$A$4 -> 0-9_males | C18: Fraction | E18: 0 | O18: 0
A19: ='Population Definitions'!$A$5 -> 0-9_females | C19: Fraction | E19: 0 | O19: 0
A20: ='Population Definitions'!$A$6 -> 10-17_males | C20: Fraction | E20: 0 | O20: 0
A21: ='Population Definitions'!$A$7 -> 10-17_females | C21: Fraction | E21: 0 | O21: 0
A22: ='Population Definitions'!$A$8 -> 18-64_males | C22: Fraction | E22: 0 | O22: 0
A23: ='Population Definitions'!$A$9 -> 18-64_females | C23: Fraction | E23: 0 | O23: 0
A24: ='Population Definitions'!$A$10 -> 65+_males | C24: Fraction | E24: 0 | O24: 0
A25: ='Population Definitions'!$A$11 -> 65+_females | C25: Fraction | E25: 0 | O25: 0
A26: ='Population Definitions'!$A$12 -> Prisoners_males | C26: Fraction | E26: 0.458 | J26: 0.458 | O26: 0.458
A27: ='Population Definitions'!$A$13 -> Prisoners_females | C27: Fraction | E27: 0.458 | J27: 0.458 | O27: 0.458
A29: Proportion who have F0-F2 | B29: Provenance | C29: Units | D29: Uncertainty | E29: Constant | G29: 2000 | H29: 2001 | I29: 2002 | J29: 2003 | K29: 2004 | L29: 2005 | M29: 2006 | N29: 2007 | O29: 2008 | P29: 2009 | Q29: 2010 | R29: 2011 | S29: 2012 | T29: 2013 | U29: 2014 | V29: 2015 | W29: 2016 | X29: 2017 | Y29: 2018 | Z29: 2019 | AA29: 2020 | AB29: 2021 | AC29: 2022 | AD29: 2023 | AE29: 2024 | AF29: 2025 | AG29: 2026 | AH29: 2027 | AI29: 2028 | AJ29: 2029 | AK29: 2030 | AL29: 2031 | AM29: 2032 | AN29: 2033 | AO29: 2034 | AP29: 2035 | AQ29: 2036 | AR29: 2037 | AS29: 2038 | AT29: 2039 | AU29: 2040 | AV29: 2041 | AW29: 2042 | AX29: 2043 | AY29: 2044 | AZ29: 2045 | BA29: 2046 | BB29: 2047 | BC29: 2048 | BD29: 2049 | BE29: 2050
A30: ='Population Definitions'!$A$2 -> PWID_males | C30: Fraction | E30: 0.945 | F30: OR
A31: ='Population Definitions'!$A$3 -> PWID_females | C31: Fraction | E31: 0.945 | F31: OR
A32: ='Population Definitions'!$A$4 -> 0-9_males | C32: Fraction | E32: 0.945 | F32: OR
A33: ='Population Definitions'!$A$5 -> 0-9_females | C33: Fraction | E33: 0.945 | F33: OR
A34: ='Population Definitions'!$A$6 -> 10-17_males | C34: Fraction | E34: 0.945 | F34: OR
A35: ='Population Definitions'!$A$7 -> 10-17_females | C35: Fraction | E35: 0.945 | F35: OR
A36: ='Population Definitions'!$A$8 -> 18-64_males | C36: Fraction | E36: 0.945 | F36: OR
A37: ='Population Definitions'!$A$9 -> 18-64_females | C37: Fraction | E37: 0.945 | F37: OR
A38: ='Population Definitions'!$A$10 -> 65+_males | C38: Fraction | E38: 0.945 | F38: OR
A39: ='Population Definitions'!$A$11 -> 65+_females | C39: Fraction | E39: 0.945 | F39: OR
A40: ='Population Definitions'!$A$12 -> Prisoners_males | C40: Fraction | E40: 0.945 | F40: OR
A41: ='Population Definitions'!$A$13 -> Prisoners_females | C41: Fraction | E41: 0.945 | F41: OR
A43: Proportion who have F3 | B43: Provenance | C43: Units | D43: Uncertainty | E43: Constant | G43: 2000 | H43: 2001 | I43: 2002 | J43: 2003 | K43: 2004 | L43: 2005 | M43: 2006 | N43: 2007 | O43: 2008 | P43: 2009 | Q43: 2010 | R43: 2011 | S43: 2012 | T43: 2013 | U43: 2014 | V43: 2015 | W43: 2016 | X43: 2017 | Y43: 2018 | Z43: 2019 | AA43: 2020 | AB43: 2021 | AC43: 2022 | AD43: 2023 | AE43: 2024 | AF43: 2025 | AG43: 2026 | AH43: 2027 | AI43: 2028 | AJ43: 2029 | AK43: 2030 | AL43: 2031 | AM43: 2032 | AN43: 2033 | AO43: 2034 | AP43: 2035 | AQ43: 2036 | AR43: 2037 | AS43: 2038 | AT43: 2039 | AU43: 2040 | AV43: 2041 | AW43: 2042 | AX43: 2043 | AY43: 2044 | AZ43: 2045 | BA43: 2046 | BB43: 2047 | BC43: 2048 | BD43: 2049 | BE43: 2050
...

Sheet Demographics
A1: Population size | B1: Provenance | C1: Units | D1: Uncertainty | E1: 2000 | F1: 2001 | G1: 2002 | H1: 2003 | I1: 2004 | J1: 2005 | K1: 2006 | L1: 2007 | M1: 2008 | N1: 2009 | O1: 2010 | P1: 2011 | Q1: 2012 | R1: 2013 | S1: 2014 | T1: 2015 | U1: 2016 | V1: 2017 | W1: 2018 | X1: 2019 | Y1: 2020 | Z1: 2021 | AA1: 2022 | AB1: 2023 | AC1: 2024 | AD1: 2025 | AE1: 2026 | AF1: 2027 | AG1: 2028 | AH1: 2029 | AI1: 2030 | AJ1: 2031 | AK1: 2032 | AL1: 2033 | AM1: 2034 | AN1: 2035 | AO1: 2036 | AP1: 2037 | AQ1: 2038 | AR1: 2039 | AS1: 2040 | AT1: 2041 | AU1: 2042 | AV1: 2043 | AW1: 2044 | AX1: 2045 | AY1: 2046 | AZ1: 2047 | BA1: 2048 | BB1: 2049 | BC1: 2050
A2: ='Population Definitions'!$A$2 -> PWID_males | C2: Number | E2: 99.71102 | O2: 99.71102 | T2: 99.71102
A3: ='Population Definitions'!$A$3 -> PWID_females | C3: Number | E3: 30.5338 | O3: 30.5338 | T3: 30.5338
A4: ='Population Definitions'!$A$4 -> 0-9_males | C4: Number | E4: 15598 | F4: 15542.5 | G4: 15420 | H4: 15211 | I4: 14919.5 | J4: 14553.5 | K4: 14136.5 | L4: 13700.5 | M4: 13267.5 | N4: 12861.5 | O4: 12625 | P4: 12584.5 | Q4: 12596 | R4: 12602 | S4: 12592 | T4: 12568 | U4: 12573 | V4: 12597.5 | W4: 12595.5 | X4: 12561.5 | Y4: 12509.5 | Z4: 12464.5 | AA4: 12429.5 | AB4: 12404 | AC4: 12365.5 | AD4: 12311.5 | AE4: 12261.5 | AF4: 12221.5 | AG4: 12188 | AH4: 12156.5 | AI4: 12128.5 | AJ4: 12100 | AK4: 12070 | AL4: 12038 | AM4: 12002 | AN4: 11960 | AO4: 11908 | AP4: 11846 | AQ4: 11774 | AR4: 11691 | AS4: 11599 | AT4: 11500 | AU4: 11398.5 | AV4: 11298 | AW4: 11196.5 | AX4: 11094 | AY4: 10993 | AZ4: 10894.5 | BA4: 10800 | BB4: 10710.5 | BC4: 10625.5
A5: ='Population Definitions'!$A$5 -> 0-9_females | C5: Number | E5: 15044 | F5: 14984 | G5: 14841 | H5: 14631.5 | I5: 14386 | J5: 14114.5 | K5: 13825 | L5: 13469.5 | M5: 13056.5 | N5: 12707.5 | O5: 12517 | P5: 12457 | Q5: 12417.5 | R5: 12338 | S5: 12244.5 | T5: 12135.5 | U5: 12023 | V5: 11954.5 | W5: 11902 | X5: 11825.5 | Y5: 11756.5 | Z5: 11713.5 | AA5: 11677.5 | AB5: 11652 | AC5: 11614 | AD5: 11559.5 | AE5: 11511 | AF5: 11470.5 | AG5: 11436.5 | AH5: 11407.5 | AI5: 11382 | AJ5: 11356 | AK5: 11328.5 | AL5: 11301.5 | AM5: 11271.5 | AN5: 11234.5 | AO5: 11187.5 | AP5: 11132 | AQ5: 11067.5 | AR5: 10991.5 | AS5: 10906 | AT5: 10815 | AU5: 10722.5 | AV5: 10629 | AW5: 10533.5 | AX5: 10438.5 | AY5: 10345 | AZ5: 10254.5 | BA5: 10167.5 | BB5: 10082.5 | BC5: 10003
A6: ='Population Definitions'!$A$6 -> 10-17_males | C6: Number | E6: 11910 | F6: 11659.5 | G6: 11358 | H6: 11087 | I6: 10887.5 | J6: 10791 | K6: 10770 | L6: 10744 | M6: 10693 | N6: 10627 | O6: 10580.5 | P6: 10517 | Q6: 10388.5 | R6: 10238.5 | S6: 10121 | T6: 10042 | U6: 9921 | V6: 9769 | W6: 9635 | X6: 9583 | Y6: 9634.5 | Z6: 9692 | AA6: 9714.5 | AB6: 9716.5 | AC6: 9741.5 | AD6: 9775 | AE6: 9768.5 | AF6: 9727 | AG6: 9653.5 | AH6: 9575 | AI6: 9511 | AJ6: 9460 | AK6: 9419 | AL6: 9380.5 | AM6: 9348.5 | AN6: 9325 | AO6: 9304.5 | AP6: 9288.5 | AQ6: 9277 | AR6: 9265.5 | AS6: 9255.5 | AT6: 9250.5 | AU6: 9241 | AV6: 9223.5 | AW6: 9201.5 | AX6: 9172 | AY6: 9133 | AZ6: 9084.5 | BA6: 9027.5 | BB6: 8963 | BC6: 8892.5
A7: ='Population Definitions'!$A$7 -> 10-17_females | C7: Number | E7: 11250 | F7: 10967.5 | G7: 10720.5 | H7: 10536.5 | I7: 10411.5 | J7: 10359.5 | K7: 10350.5 | L7: 10373.5 | M7: 10434.5 | N7: 10448 | O7: 10388.5 | P7: 10281.5 | Q7: 10160.5 | R7: 10077.5 | S7: 10020.5 | T7: 9953.5 | U7: 9837.5 | V7: 9707 | W7: 9608 | X7: 9581 | Y7: 9602.5 | Z7: 9575 | AA7: 9514 | AB7: 9431 | AC7: 9341.5 | AD7: 9290 | AE7: 9239 | AF7: 9155.5 | AG7: 9065 | AH7: 8990.5 | AI7: 8927 | AJ7: 8877 | AK7: 8836.5 | AL7: 8797 | AM7: 8764 | AN7: 8740 | AO7: 8720.5 | AP7: 8706 | AQ7: 8695.5 | AR7: 8686 | AS7: 8678.5 | AT7: 8675.5 | AU7: 8670 | AV7: 8658 | AW7: 8640.5 | AX7: 8615 | AY7: 8581 | AZ7: 8539 | BA7: 8489 | BB7: 8429.5 | BC7: 8365.5
A8: ='Population Definitions'!$A$8 -> 18-64_males | C8: Number | E8: 26859 | F8: 27275.5 | G8: 27695.5 | H8: 28066 | I8: 28370 | J8: 28606.5 | K8: 28717.5 | L8: 28770 | M8: 28802 | N8: 28793.5 | O8: 28829.5 | P8: 28984 | Q8: 29141.5 | R8: 29309.5 | S8: 29443 | T8: 29597.5 | U8: 29778 | V8: 30001.5 | W8: 30231 | X8: 30363.5 | Y8: 30525.5 | Z8: 30719 | AA8: 30853.5 | AB8: 31022 | AC8: 31181.5 | AD8: 31336.5 | AE8: 31535 | AF8: 31794.5 | AG8: 32096.5 | AH8: 32394 | AI8: 32678 | AJ8: 32976 | AK8: 33299 | AL8: 33631.5 | AM8: 33951 | AN8: 34265.5 | AO8: 34595 | AP8: 34936 | AQ8: 35274.5 | AR8: 35609 | AS8: 35936 | AT8: 36252 | AU8: 36567.5 | AV8: 36915 | AW8: 37276.5 | AX8: 37631 | AY8: 37996.5 | AZ8: 38373.5 | BA8: 38734 | BB8: 39070.5 | BC8: 39388
A9: ='Population Definitions'!$A$9 -> 18-64_females | C9: Number | E9: 27758 | F9: 28179 | G9: 28521.5 | H9: 28780 | I9: 28960 | J9: 29056 | K9: 29080 | L9: 29065 | M9: 29012 | N9: 28928 | O9: 28999 | P9: 29210.5 | Q9: 29411 | R9: 29617.5 | S9: 29807 | T9: 30031 | U9: 30325 | V9: 30605.5 | W9: 30835 | X9: 30972 | Y9: 31172.5 | Z9: 31426.5 | AA9: 31604.5 | AB9: 31818 | AC9: 32052 | AD9: 32249.5 | AE9: 32460 | AF9: 32717.5 | AG9: 32980 | AH9: 33245.5 | AI9: 33492.5 | AJ9: 33726.5 | AK9: 33970 | AL9: 34210.5 | AM9: 34447 | AN9: 34691 | AO9: 34967 | AP9: 35257 | AQ9: 35517 | AR9: 35759.5 | AS9: 36019 | AT9: 36316 | AU9: 36646.5 | AV9: 36989.5 | AW9: 37314.5 | AX9: 37625 | AY9: 37939 | AZ9: 38256.5 | BA9: 38579 | BB9: 38906 | BC9: 39239.5
A10: ='Population Definitions'!$A$10 -> 65+_males | C10: Number | E10: 1542 | F10: 1603.5 | G10: 1667 | H10: 1704 | I10: 1705.5 | J10: 1674 | K10: 1621.5 | L10: 1560 | M10: 1501.5 | N10: 1450.5 | O10: 1433.5 | P10: 1460 | Q10: 1511.5 | R10: 1596.5 | S10: 1693 | T10: 1795 | U10: 1905 | V10: 2007 | W10: 2116.5 | X10: 2247.5 | Y10: 2385 | Z10: 2509 | AA10: 2610 | AB10: 2701 | AC10: 2796.5 | AD10: 2900.5 | AE10: 2984 | AF10: 3044 | AG10: 3106.5 | AH10: 3173.5 | AI10: 3239.5 | AJ10: 3284 | AK10: 3300 | AL10: 3304 | AM10: 3323.5 | AN10: 3349.5 | AO10: 3353.5 | AP10: 3350 | AQ10: 3351.5 | AR10: 3352.5 | AS10: 3361 | AT10: 3387.5 | AU10: 3423 | AV10: 3438 | AW10: 3444 | AX10: 3460 | AY10: 3474 | AZ10: 3480.5 | BA10: 3512 | BB10: 3567.5 | BC10: 3633.5
A11: ='Population Definitions'!$A$11 -> 65+_females | C11: Number | E11: 1992 | F11: 2063 | G11: 2133.5 | H11: 2178 | I11: 2194.5 | J11: 2185 | K11: 2156 | L11: 2126 | M11: 2097.5 | N11: 2069.5 | O11: 2066.5 | P11: 2103.5 | Q11: 2163.5 | R11: 2241 | S11: 2343 | T11: 2461 | U11: 2580 | V11: 2707.5 | W11: 2854.5 | X11: 3016 | Y11: 3198.5 | Z11: 3393 | AA11: 3578 | AB11: 3754 | AC11: 3936 | AD11: 4128.5 | AE11: 4291.5 | AF11: 4437 | AG11: 4590.5 | AH11: 4725 | AI11: 4859 | AJ11: 4991.5 | AK11: 5108.5 | AL11: 5224 | AM11: 5340.5 | AN11: 5445.5 | AO11: 5509.5 | AP11: 5562.5 | AQ11: 5642 | AR11: 5725 | AS11: 5794 | AT11: 5826 | AU11: 5826 | AV11: 5826 | AW11: 5851 | AX11: 5897 | AY11: 5946 | AZ11: 5994 | BA11: 6044 | BB11: 6091 | BC11: 6128.5
A12: ='Population Definitions'!$A$12 -> Prisoners_males | C12: Number | E12: 91 | J12: 72 | O12: 100 | S12: 132
A13: ='Population Definitions'!$A$13 -> Prisoners_females | C13: Number | E13: 0 | J13: 0 | O13: 0 | S13: 0
A15: Number of live births | B15: Provenance | C15: Units | D15: Uncertainty | E15: Constant | G15: 2000 | H15: 2001 | I15: 2002 | J15: 2003 | K15: 2004 | L15: 2005 | M15: 2006 | N15: 2007 | O15: 2008 | P15: 2009 | Q15: 2010 | R15: 2011 | S15: 2012 | T15: 2013 | U15: 2014 | V15: 2015 | W15: 2016 | X15: 2017 | Y15: 2018 | Z15: 2019 | AA15: 2020 | AB15: 2021 | AC15: 2022 | AD15: 2023 | AE15: 2024 | AF15: 2025 | AG15: 2026 | AH15: 2027 | AI15: 2028 | AJ15: 2029 | AK15: 2030 | AL15: 2031 | AM15: 2032 | AN15: 2033 | AO15: 2034 | AP15: 2035 | AQ15: 2036 | AR15: 2037 | AS15: 2038 | AT15: 2039 | AU15: 2040 | AV15: 2041 | AW15: 2042 | AX15: 2043 | AY15: 2044 | AZ15: 2045 | BA15: 2046 | BB15: 2047 | BC15: 2048 | BD15: 2049 | BE15: 2050
A16: ='Population Definitions'!$A$2 -> PWID_males | C16: Number (per year) | E16: 0 | F16: OR
A17: ='Population Definitions'!$A$3 -> PWID_females | C17: Number (per year) | E17: 0 | F17: OR
A18: ='Population Definitions'!$A$4 -> 0-9_males | C18: Number (per year) | F18: OR | G18: 1861.9034 | H18: 1826.2367 | I18: 1771.4444 | J18: 1717.686 | K18: 1675.8164 | L18: 1634.9807 | M18: 1588.9758 | N18: 1538.8357 | O18: 1487.1449 | P18: 1441.1401 | Q18: 1401.3382 | R18: 1377.5604 | S18: 1358.9517 | T18: 1342.9275 | U18: 1332.5894 | V18: 1324.8357 | W18: 1316.5652 | X18: 1311.3961 | Y18: 1309.8454 | Z18: 1305.1932 | AA18: 1301.058 | AB18: 1308.8116 | AC18: 1304.6763 | AD18: 1298.4734 | AE18: 1305.7101 | AF18: 1301.058 | AG18: 1296.9227 | AH18: 1293.3043 | AI18: 1291.2367 | AJ18: 1286.5845 | AK18: 1282.4493 | AL18: 1275.2126 | AM18: 1265.9082 | AN18: 1256.6039 | AO18: 1246.2657 | AP18: 1235.4106 | AQ18: 1222.4879 | AR18: 1209.5652 | AS18: 1196.1256 | AT18: 1183.7198 | AU18: 1169.7633 | AV18: 1158.3913 | AW18: 1148.0531 | AX18: 1136.1643 | AY18: 1124.7923 | AZ18: 1114.4541 | BA18: 1105.1498 | BB18: 1094.8116 | BC18: 1086.0242 | BD18: 1078.2705 | BE18: 1071.0338
A19: ='Population Definitions'!$A$5 -> 0-9_females | C19: Number (per year) | F19: OR | G19: 1740.0966 | H19: 1706.7633 | I19: 1655.5556 | J19: 1605.314 | K19: 1566.1836 | L19: 1528.0193 | M19: 1485.0242 | N19: 1438.1643 | O19: 1389.8551 | P19: 1346.8599 | Q19: 1309.6618 | R19: 1287.4396 | S19: 1270.0483 | T19: 1255.0725 | U19: 1245.4106 | V19: 1238.1643 | W19: 1230.4348 | X19: 1225.6039 | Y19: 1224.1546 | Z19: 1219.8068 | AA19: 1215.942 | AB19: 1223.1884 | AC19: 1219.3237 | AD19: 1213.5266 | AE19: 1220.2899 | AF19: 1215.942 | AG19: 1212.0773 | AH19: 1208.6957 | AI19: 1206.7633 | AJ19: 1202.4155 | AK19: 1198.5507 | AL19: 1191.7874 | AM19: 1183.0918 | AN19: 1174.3961 | AO19: 1164.7343 | AP19: 1154.5894 | AQ19: 1142.5121 | AR19: 1130.4348 | AS19: 1117.8744 | AT19: 1106.2802 | AU19: 1093.2367 | AV19: 1082.6087 | AW19: 1072.9469 | AX19: 1061.8357 | AY19: 1051.2077 | AZ19: 1041.5459 | BA19: 1032.8502 | BB19: 1023.1884 | BC19: 1014.9758 | BD19: 1007.7295 | BE19: 1000.9662
A20: ='Population Definitions'!$A$6 -> 10-17_males | C20: Number (per year) | E20: 0 | F20: OR
A21: ='Population Definitions'!$A$7 -> 10-17_females | C21: Number (per year) | E21: 0 | F21: OR
A22: ='Population Definitions'!$A$8 -> 18-64_males | C22: Number (per year) | E22: 0 | F22: OR
A23: ='Population Definitions'!$A$9 -> 18-64_females | C23: Number (per year) | E23: 0 | F23: OR
A24: ='Population Definitions'!$A$10 -> 65+_males | C24: Number (per year) | E24: 0 | F24: OR
A25: ='Population Definitions'!$A$11 -> 65+_females | C25: Number (per year) | E25: 0 | F25: OR
A26: ='Population Definitions'!$A$12 -> Prisoners_males | C26: Number (per year) | E26: 0 | F26: OR
A27: ='Population Definitions'!$A$13 -> Prisoners_females | C27: Number (per year) | E27: 0 | F27: OR
A29: Net migration rate | B29: Provenance | C29: Units | D29: Uncertainty | E29: Constant | G29: 2000 | H29: 2001 | I29: 2002 | J29: 2003 | K29: 2004 | L29: 2005 | M29: 2006 | N29: 2007 | O29: 2008 | P29: 2009 | Q29: 2010 | R29: 2011 | S29: 2012 | T29: 2013 | U29: 2014 | V29: 2015 | W29: 2016 | X29: 2017 | Y29: 2018 | Z29: 2019 | AA29: 2020 | AB29: 2021 | AC29: 2022 | AD29: 2023 | AE29: 2024 | AF29: 2025 | AG29: 2026 | AH29: 2027 | AI29: 2028 | AJ29: 2029 | AK29: 2030 | AL29: 2031 | AM29: 2032 | AN29: 2033 | AO29: 2034 | AP29: 2035 | AQ29: 2036 | AR29: 2037 | AS29: 2038 | AT29: 2039 | AU29: 2040 | AV29: 2041 | AW29: 2042 | AX29: 2043 | AY29: 2044 | AZ29: 2045 | BA29: 2046 | BB29: 2047 | BC29: 2048 | BD29: 2049 | BE29: 2050
A30: ='Population Definitions'!$A$2 -> PWID_males | C30: Rate (per year) | E30: 0 | F30: OR
A31: ='Population Definitions'!$A$3 -> PWID_females | C31: Rate (per year) | E31: 0 | F31: OR
A32: ='Population Definitions'!$A$4 -> 0-9_males | C32: Rate (per year) | F32: OR | G32: -0.021406807 | H32: -0.026169324 | I32: -0.029244127 | J32: -0.032587337 | K32: -0.034673845 | L32: -0.037996405 | M32: -0.039647427 | N32: -0.037468395 | O32: -0.033212356 | P32: -0.019215496 | Q32: -0.0067990625 | R32: -0.0063220936 | S32: -0.0060298262 | T32: -0.0054695712 | U32: -0.0053279361 | V32: -0.0049996617 | W32: -0.0045387113 | X32: -0.0041989391 | Y32: -0.0045925458 | Z32: -0.0036375621 | AA32: -0.0028025078 | AB32: -0.0040363909 | AC32: -0.0040368743 | AD32: -0.0054799605 | AE32: -0.0079827055 | AF32: -0.0080053585 | AG32: -0.0075376345 | AH32: -0.0071435051 | AI32: -0.0073216865 | AJ32: -0.0071224893 | AK32: -0.0069628788 | AL32: -0.0068357488 | AM32: -0.0068689488 | AN32: -0.0066127151 | AO32: -0.0062710965 | AP32: -0.0063470425 | AQ32: -0.0062552841 | AR32: -0.0061257148 | AS32: -0.0061258369 | AT32: -0.0060490811 | AU32: -0.0058852733 | AV32: -0.0056862004 | AW32: -0.0053562434 | AX32: -0.0051481901 | AY32: -0.0049830099 | AZ32: -0.0049084285 | BA32: -0.0049258399 | BB32: -0.0046639675 | BC32: -0.0044929773 | BD32: -0.0044134757 | BE32: -0.0044265038
A33: ='Population Definitions'!$A$5 -> 0-9_females | C33: Rate (per year) | F33: OR | G33: -0.019615569 | H33: -0.023776247 | I33: -0.025204202 | J33: -0.027428084 | K33: -0.028130375 | L33: -0.028447293 | M33: -0.029549668 | N33: -0.028669531 | O33: -0.024114814 | P33: -0.014232532 | Q33: -0.0068436395 | R33: -0.0063369683 | S33: -0.0060437535 | T33: -0.0056794022 | U33: -0.0053420416 | V33: -0.0050401097 | W33: -0.0049018367 | X33: -0.0046931168 | Y33: -0.0050121483 | Z33: -0.0039158398 | AA33: -0.0030997345 | AB33: -0.0044127209 | AC33: -0.0043094559 | AD33: -0.005709455 | AE33: -0.0083338949 | AF33: -0.0082133335 | AG33: -0.00799907 | AH33: -0.0076017307 | AI33: -0.0074990849 | AJ33: -0.0073123348 | AK33: -0.0072527433 | AL33: -0.0072461641 | AM33: -0.0070699375 | AN33: -0.0069367903 | AO33: -0.0066303775 | AP33: -0.0068618427 | AQ33: -0.0066602974 | AR33: -0.0064619819 | AS33: -0.006449008 | AT33: -0.0066214978 | AU33: -0.006256805 | AV33: -0.0059277573 | AW33: -0.0059171704 | AX33: -0.0057235628 | AY33: -0.005620898 | AZ33: -0.0054170517 | BA33: -0.0052537691 | BB33: -0.0051868356 | BC33: -0.0051611355 | BD33: -0.0048826649 | BE33: -0.0048951498
A34: ='Population Definitions'!$A$6 -> 10-17_males | C34: Rate (per year) | F34: OR | G34: -0.028883291 | H34: -0.028860586 | I34: -0.025576686 | J34: -0.02299991 | K34: -0.020344432 | L34: -0.017792605 | M34: -0.016248839 | N34: -0.015822785 | O34: -0.016365847 | P34: -0.011574292 | Q34: -0.0060016067 | R34: -0.005705049 | S34: -0.0056312268 | T34: -0.0054207159 | U34: -0.0050390278 | V34: -0.0047799243 | W34: -0.0047374257 | X34: -0.0047087726 | Y34: -0.0047223664 | Z34: -0.0037566524 | AA34: -0.0034770875 | AB34: -0.004230293 | AC34: -0.0041175562 | AD34: -0.0041167087 | AE34: -0.0042601242 | AF34: -0.0042966752 | AG34: -0.0039924246 | AH34: -0.0038552483 | AI34: -0.0038328068 | AJ34: -0.0036031332 | AK34: -0.0036273788 | AL34: -0.0035412262 | AM34: -0.0033973883 | AN34: -0.0032514258 | AO34: -0.0032625555 | AP34: -0.0032171582 | AQ34: -0.0031167715 | AR34: -0.0031221403 | AS34: -0.0030721138 | AT34: -0.0029140359 | AU34: -0.0027010966 | AV34: -0.0026485055 | AW34: -0.0025430148 | AX34: -0.0023310023 | AY34: -0.0023909145 | AZ34: -0.0023986044 | BA34: -0.002408847 | BB34: -0.0023116297 | BC34: -0.0023262254 | BD34: -0.0023987504 | BE34: -0.0022490863
A35: ='Population Definitions'!$A$7 -> 10-17_females | C35: Rate (per year) | F35: OR | G35: -0.028977778 | H35: -0.029268293 | I35: -0.025698428 | J35: -0.023110141 | K35: -0.020266052 | L35: -0.017954534 | M35: -0.016279407 | N35: -0.015134718 | O35: -0.014758733 | P35: -0.010863323 | Q35: -0.0068344804 | R35: -0.006662452 | S35: -0.0062496924 | T35: -0.0060530886 | U35: -0.0057881343 | V35: -0.0055759281 | W35: -0.0053367217 | X35: -0.005150922 | Y35: -0.0053601166 | Z35: -0.0041749295 | AA35: -0.0037490237 | AB35: -0.0046997389 | AC35: -0.0046773176 | AD35: -0.0044003817 | AE35: -0.004228443 | AF35: -0.0043057051 | AG35: -0.0043294729 | AH35: -0.0040412867 | AI35: -0.0039161611 | AJ35: -0.0039486124 | AK35: -0.0038646802 | AL35: -0.0038301228 | AM35: -0.0038476772 | AN35: -0.003864954 | AO35: -0.0037083524 | AP35: -0.0034897025 | AQ35: -0.0033828336 | AR35: -0.0035607627 | AS35: -0.0035075614 | AT35: -0.0033962699 | AU35: -0.0032839776 | AV35: -0.0031122126 | AW35: -0.0029411765 | AX35: -0.0029452529 | AY35: -0.0028933511 | AZ35: -0.0027858387 | BA35: -0.0025638038 | BB35: -0.0024007495 | BC35: -0.0025915891 | BD35: -0.002609882 | BE35: -0.0023907716
A36: ='Population Definitions'!$A$8 -> 18-64_males | C36: Rate (per year) | F36: OR | G36: -0.019962894 | H36: -0.020335081 | I36: -0.021809152 | J36: -0.023528785 | K36: -0.025227504 | L36: -0.026797078 | M36: -0.028308932 | N36: -0.029540254 | O36: -0.030633096 | P36: -0.028147789 | Q36: -0.024697973 | R36: -0.023466511 | S36: -0.022279979 | T36: -0.020996617 | U36: -0.019746407 | V36: -0.018786054 | W36: -0.017703109 | X36: -0.017239949 | Y36: -0.01755426 | Z36: -0.013526586 | AA36: -0.01216668 | AB36: -0.015137273 | AC36: -0.015007019 | AD36: -0.013802401 | AE36: -0.012646303 | AF36: -0.012663457 | AG36: -0.012236713 | AH36: -0.011432509 | AI36: -0.011185752 | AJ36: -0.010822112 | AK36: -0.010469369 | AL36: -0.010073094 | AM36: -0.0096616912 | AN36: -0.0091667037 | AO36: -0.0086846815 | AP36: -0.0086198125 | AQ36: -0.0082788608 | AR36: -0.0078704232 | AS36: -0.0079363959 | AT36: -0.007596318 | AU36: -0.0071392924 | AV36: -0.0067886983 | AW36: -0.0063897328 | AX36: -0.0063028045 | AY36: -0.005974578 | AZ36: -0.0057198845 | BA36: -0.0054945775 | BB36: -0.0050642116 | BC36: -0.0048371327 | BD36: -0.0047190868 | BE36: -0.0047191296
A37: ='Population Definitions'!$A$9 -> 18-64_females | C37: Rate (per year) | F37: OR | G37: -0.021399236 | H37: -0.022658717 | I37: -0.023876725 | J37: -0.025625434 | K37: -0.027106354 | L37: -0.028789235 | M37: -0.030003439 | N37: -0.031309135 | O37: -0.032572729 | P37: -0.029279591 | Q37: -0.024759474 | R37: -0.02339912 | S37: -0.022117575 | T37: -0.020764751 | U37: -0.019643037 | V37: -0.018647398 | W37: -0.017609233 | X37: -0.016892389 | Y37: -0.017480136 | Z37: -0.013399199 | AA37: -0.012222311 | AB37: -0.014764609 | AC37: -0.014507428 | AD37: -0.013247219 | AE37: -0.012152128 | AF37: -0.012155227 | AG37: -0.011706716 | AH37: -0.01109498 | AI37: -0.01077926 | AJ37: -0.01054278 | AK37: -0.010450101 | AL37: -0.010066268 | AM37: -0.0096408596 | AN37: -0.0091638532 | AO37: -0.008912242 | AP37: -0.0087774927 | AQ37: -0.0081934395 | AR37: -0.0078707774 | AS37: -0.0079820931 | AT37: -0.007732211 | AU37: -0.0072739388 | AV37: -0.0069803943 | AW37: -0.0065763443 | AX37: -0.0062314981 | AY37: -0.0060030283 | AZ37: -0.0056478405 | BA37: -0.0053506945 | BB37: -0.005097173 | BC37: -0.0049768009 | BD37: -0.0047293477 | BE37: -0.0045744722
A38: ='Population Definitions'!$A$10 -> 65+_males | C38: Rate (per year) | F38: OR | G38: -0.025291829 | H38: -0.021827253 | I38: -0.028494301 | J38: -0.032276995 | K38: -0.03488713 | L38: -0.037037037 | M38: -0.042861548 | N38: -0.048717949 | O38: -0.053613054 | P38: -0.038952085 | Q38: -0.019881409 | R38: -0.020205479 | S38: -0.019186239 | T38: -0.01597244 | U38: -0.016538689 | V38: -0.01448468 | W38: -0.01312336 | X38: -0.012954659 | Y38: -0.011811954 | Z38: -0.014238042 | AA38: -0.0056603774 | AB38: -0.0097648466 | AC38: -0.0097701149 | AD38: -0.0096260644 | AE38: -0.011085285 | AF38: -0.01017066 | AG38: -0.0097184987 | AH38: -0.0091984231 | AI38: -0.0099790761 | AJ38: -0.0083504018 | AK38: -0.0083346195 | AL38: -0.0068514007 | AM38: -0.0063636364 | AN38: -0.0069612591 | AO38: -0.007070859 | AP38: -0.0071652485 | AQ38: -0.0065603101 | AR38: -0.0064179104 | AS38: -0.0055199165 | AT38: -0.0062639821 | AU38: -0.0058018447 | AV38: -0.0054612546 | AW38: -0.0051124744 | AX38: -0.0052356021 | AY38: -0.0049361208 | AZ38: -0.0059248555 | BA38: -0.0048934945 | BB38: -0.0041660681 | BC38: -0.0049829157 | BD38: -0.0046250876 | BE38: -0.0050915096
A39: ='Population Definitions'!$A$11 -> 65+_females | C39: Rate (per year) | F39: OR | G39: -0.023343373 | H39: -0.022782356 | I39: -0.027419733 | J39: -0.032139578 | K39: -0.033037138 | L39: -0.035926773 | M39: -0.037569573 | N39: -0.041157103 | O39: -0.044576877 | P39: -0.026818072 | Q39: -0.0099201549 | R39: -0.009745662 | S39: -0.0085509591 | T39: -0.010709505 | U39: -0.0091762697 | V39: -0.0069077611 | W39: -0.0073643411 | X39: -0.0064635272 | Y39: -0.0080574531 | Z39: -0.0072944297 | AA39: -0.0042207285 | AB39: -0.0042735043 | AC39: -0.0044717719 | AD39: -0.0065263719 | AE39: -0.0080030488 | AF39: -0.007024343 | AG39: -0.0062915065 | AH39: -0.0063105702 | AI39: -0.0066441564 | AJ39: -0.0050793651 | AK39: -0.0055566989 | AL39: -0.0051086848 | AM39: -0.0046980523 | AN39: -0.0052641654 | AO39: -0.0042130887 | AP39: -0.0040400331 | AQ39: -0.0038115981 | AR39: -0.003505618 | AS39: -0.0039879475 | AT39: -0.0038427948 | AU39: -0.0038833276 | AV39: -0.0036903536 | AW39: -0.0028321318 | AX39: -0.0025746653 | AY39: -0.0023927534 | AZ39: -0.0018653553 | BA39: -0.0027749748 | BB39: -0.0021688355 | BC39: -0.0016545334 | BD39: -0.0019701198 | BE39: -0.0022844089
A40: ='Population Definitions'!$A$12 -> Prisoners_males | C40: Rate (per year) | E40: 0 | F40: OR
A41: ='Population Definitions'!$A$13 -> Prisoners_females | C41: Rate (per year) | E41: 0 | F41: OR
A43: All cause death rate | B43: Provenance | C43: Units | D43: Uncertainty | E43: Constant | G43: 2000 | H43: 2001 | I43: 2002 | J43: 2003 | K43: 2004 | L43: 2005 | M43: 2006 | N43: 2007 | O43: 2008 | P43: 2009 | Q43: 2010 | R43: 2011 | S43: 2012 | T43: 2013 | U43: 2014 | V43: 2015 | W43: 2016 | X43: 2017 | Y43: 2018 | Z43: 2019 | AA43: 2020 | AB43: 2021 | AC43: 2022 | AD43: 2023 | AE43: 2024 | AF43: 2025 | AG43: 2026 | AH43: 2027 | AI43: 2028 | AJ43: 2029 | AK43: 2030 | AL43: 2031 | AM43: 2032 | AN43: 2033 | AO43: 2034 | AP43: 2035 | AQ43: 2036 | AR43: 2037 | AS43: 2038 | AT43: 2039 | AU43: 2040 | AV43: 2041 | AW43: 2042 | AX43: 2043 | AY43: 2044 | AZ43: 2045 | BA43: 2046 | BB43: 2047 | BC43: 2048 | BD43: 2049 | BE43: 2050
...

Sheet Infectiousness
A1: Force of Infection constant | B1: Provenance | C1: Units | D1: Uncertainty | E1: Constant | G1: 2000 | H1: 2001 | I1: 2002 | J1: 2003 | K1: 2004 | L1: 2005 | M1: 2006 | N1: 2007 | O1: 2008 | P1: 2009 | Q1: 2010 | R1: 2011 | S1: 2012 | T1: 2013 | U1: 2014 | V1: 2015 | W1: 2016 | X1: 2017 | Y1: 2018 | Z1: 2019 | AA1: 2020 | AB1: 2021 | AC1: 2022 | AD1: 2023 | AE1: 2024 | AF1: 2025 | AG1: 2026 | AH1: 2027 | AI1: 2028 | AJ1: 2029 | AK1: 2030 | AL1: 2031 | AM1: 2032 | AN1: 2033 | AO1: 2034 | AP1: 2035 | AQ1: 2036 | AR1: 2037 | AS1: 2038 | AT1: 2039 | AU1: 2040 | AV1: 2041 | AW1: 2042 | AX1: 2043 | AY1: 2044 | AZ1: 2045 | BA1: 2046 | BB1: 2047 | BC1: 2048 | BD1: 2049 | BE1: 2050
A2: ='Population Definitions'!$A$2 -> PWID_males | C2: N.A. | E2: 0.1 | F2: OR
A3: ='Population Definitions'!$A$3 -> PWID_females | C3: N.A. | E3: 0.1 | F3: OR
A4: ='Population Definitions'!$A$4 -> 0-9_males | C4: N.A. | E4: 0 | F4: OR
A5: ='Population Definitions'!$A$5 -> 0-9_females | C5: N.A. | E5: 0 | F5: OR
A6: ='Population Definitions'!$A$6 -> 10-17_males | C6: N.A. | E6: 0 | F6: OR
A7: ='Population Definitions'!$A$7 -> 10-17_females | C7: N.A. | E7: 0 | F7: OR
A8: ='Population Definitions'!$A$8 -> 18-64_males | C8: N.A. | E8: 0 | F8: OR
A9: ='Population Definitions'!$A$9 -> 18-64_females | C9: N.A. | E9: 0 | F9: OR
A10: ='Population Definitions'!$A$10 -> 65+_males | C10: N.A. | E10: 0 | F10: OR
A11: ='Population Definitions'!$A$11 -> 65+_females | C11: N.A. | E11: 0 | F11: OR
A12: ='Population Definitions'!$A$12 -> Prisoners_males | C12: N.A. | E12: 0.1 | F12: OR
A13: ='Population Definitions'!$A$13 -> Prisoners_females | C13: N.A. | E13: 0.1 | F13: OR
A15: Infectivity among the general population | B15: Provenance | C15: Units | D15: Uncertainty | E15: Constant | G15: 2000 | H15: 2001 | I15: 2002 | J15: 2003 | K15: 2004 | L15: 2005 | M15: 2006 | N15: 2007 | O15: 2008 | P15: 2009 | Q15: 2010 | R15: 2011 | S15: 2012 | T15: 2013 | U15: 2014 | V15: 2015 | W15: 2016 | X15: 2017 | Y15: 2018 | Z15: 2019 | AA15: 2020 | AB15: 2021 | AC15: 2022 | AD15: 2023 | AE15: 2024 | AF15: 2025 | AG15: 2026 | AH15: 2027 | AI15: 2028 | AJ15: 2029 | AK15: 2030 | AL15: 2031 | AM15: 2032 | AN15: 2033 | AO15: 2034 | AP15: 2035 | AQ15: 2036 | AR15: 2037 | AS15: 2038 | AT15: 2039 | AU15: 2040 | AV15: 2041 | AW15: 2042 | AX15: 2043 | AY15: 2044 | AZ15: 2045 | BA15: 2046 | BB15: 2047 | BC15: 2048 | BD15: 2049 | BE15: 2050
A16: ='Population Definitions'!$A$2 -> PWID_males | C16: Probability (per year) | E16: 0 | F16: OR
A17: ='Population Definitions'!$A$3 -> PWID_females | C17: Probability (per year) | E17: 0 | F17: OR
A18: ='Population Definitions'!$A$4 -> 0-9_males | C18: Probability (per year) | E18: 0 | F18: OR
A19: ='Population Definitions'!$A$5 -> 0-9_females | C19: Probability (per year) | E19: 0 | F19: OR
A20: ='Population Definitions'!$A$6 -> 10-17_males | C20: Probability (per year) | E20: 0 | F20: OR
A21: ='Population Definitions'!$A$7 -> 10-17_females | C21: Probability (per year) | E21: 0 | F21: OR
A22: ='Population Definitions'!$A$8 -> 18-64_males | C22: Probability (per year) | E22: 0 | F22: OR
A23: ='Population Definitions'!$A$9 -> 18-64_females | C23: Probability (per year) | E23: 0 | F23: OR
A24: ='Population Definitions'!$A$10 -> 65+_males | C24: Probability (per year) | E24: 0 | F24: OR
A25: ='Population Definitions'!$A$11 -> 65+_females | C25: Probability (per year) | E25: 0 | F25: OR
A26: ='Population Definitions'!$A$12 -> Prisoners_males | C26: Probability (per year) | E26: 0 | F26: OR
A27: ='Population Definitions'!$A$13 -> Prisoners_females | C27: Probability (per year) | E27: 0 | F27: OR

Sheet Disease Progression
A1: Proportion of HCV infections spontaneously clearing | B1: Provenance | C1: Units | D1: Uncertainty | E1: Constant | G1: 2000 | H1: 2001 | I1: 2002 | J1: 2003 | K1: 2004 | L1: 2005 | M1: 2006 | N1: 2007 | O1: 2008 | P1: 2009 | Q1: 2010 | R1: 2011 | S1: 2012 | T1: 2013 | U1: 2014 | V1: 2015 | W1: 2016 | X1: 2017 | Y1: 2018 | Z1: 2019 | AA1: 2020 | AB1: 2021 | AC1: 2022 | AD1: 2023 | AE1: 2024 | AF1: 2025 | AG1: 2026 | AH1: 2027 | AI1: 2028 | AJ1: 2029 | AK1: 2030 | AL1: 2031 | AM1: 2032 | AN1: 2033 | AO1: 2034 | AP1: 2035 | AQ1: 2036 | AR1: 2037 | AS1: 2038 | AT1: 2039 | AU1: 2040 | AV1: 2041 | AW1: 2042 | AX1: 2043 | AY1: 2044 | AZ1: 2045 | BA1: 2046 | BB1: 2047 | BC1: 2048 | BD1: 2049 | BE1: 2050
A2: ='Population Definitions'!$A$2 -> PWID_males | C2: Proportion | D2: 0.028061224 | E2: 0.19889503 | F2: OR
A3: ='Population Definitions'!$A$3 -> PWID_females | C3: Proportion | D3: 0.033163265 | E3: 0.42105263 | F3: OR
A4: ='Population Definitions'!$A$4 -> 0-9_males | C4: Proportion | D4: 0.028061224 | E4: 0.19889503 | F4: OR
A5: ='Population Definitions'!$A$5 -> 0-9_females | C5: Proportion | D5: 0.033163265 | E5: 0.42105263 | F5: OR
A6: ='Population Definitions'!$A$6 -> 10-17_males | C6: Proportion | D6: 0.028061224 | E6: 0.19889503 | F6: OR
A7: ='Population Definitions'!$A$7 -> 10-17_females | C7: Proportion | D7: 0.033163265 | E7: 0.42105263 | F7: OR
A8: ='Population Definitions'!$A$8 -> 18-64_males | C8: Proportion | D8: 0.028061224 | E8: 0.19889503 | F8: OR
A9: ='Population Definitions'!$A$9 -> 18-64_females | C9: Proportion | D9: 0.033163265 | E9: 0.42105263 | F9: OR
A10: ='Population Definitions'!$A$10 -> 65+_males | C10: Proportion | D10: 0.028061224 | E10: 0.19889503 | F10: OR
A11: ='Population Definitions'!$A$11 -> 65+_females | C11: Proportion | D11: 0.033163265 | E11: 0.42105263 | F11: OR
A12: ='Population Definitions'!$A$12 -> Prisoners_males | C12: Proportion | D12: 0.028061224 | E12: 0.19889503 | F12: OR
A13: ='Population Definitions'!$A$13 -> Prisoners_females | C13: Proportion | D13: 0.033163265 | E13: 0.42105263 | F13: OR
A15: Average duration for spontaneous viral clearance | B15: Provenance | C15: Units | D15: Uncertainty | E15: Constant | G15: 2000 | H15: 2001 | I15: 2002 | J15: 2003 | K15: 2004 | L15: 2005 | M15: 2006 | N15: 2007 | O15: 2008 | P15: 2009 | Q15: 2010 | R15: 2011 | S15: 2012 | T15: 2013 | U15: 2014 | V15: 2015 | W15: 2016 | X15: 2017 | Y15: 2018 | Z15: 2019 | AA15: 2020 | AB15: 2021 | AC15: 2022 | AD15: 2023 | AE15: 2024 | AF15: 2025 | AG15: 2026 | AH15: 2027 | AI15: 2028 | AJ15: 2029 | AK15: 2030 | AL15: 2031 | AM15: 2032 | AN15: 2033 | AO15: 2034 | AP15: 2035 | AQ15: 2036 | AR15: 2037 | AS15: 2038 | AT15: 2039 | AU15: 2040 | AV15: 2041 | AW15: 2042 | AX15: 2043 | AY15: 2044 | AZ15: 2045 | BA15: 2046 | BB15: 2047 | BC15: 2048 | BD15: 2049 | BE15: 2050
A16: ='Population Definitions'!$A$2 -> PWID_males | B16: Framework-supplied default | C16: Duration (years) | E16: 1 | F16: OR
A17: ='Population Definitions'!$A$3 -> PWID_females | B17: Framework-supplied default | C17: Duration (years) | E17: 1 | F17: OR
A18: ='Population Definitions'!$A$4 -> 0-9_males | B18: Framework-supplied default | C18: Duration (years) | E18: 1 | F18: OR
A19: ='Population Definitions'!$A$5 -> 0-9_females | B19: Framework-supplied default | C19: Duration (years) | E19: 1 | F19: OR
A20: ='Population Definitions'!$A$6 -> 10-17_males | B20: Framework-supplied default | C20: Duration (years) | E20: 1 | F20: OR
A21: ='Population Definitions'!$A$7 -> 10-17_females | B21: Framework-supplied default | C21: Duration (years) | E21: 1 | F21: OR
A22: ='Population Definitions'!$A$8 -> 18-64_males | B22: Framework-supplied default | C22: Duration (years) | E22: 1 | F22: OR
A23: ='Population Definitions'!$A$9 -> 18-64_females | B23: Framework-supplied default | C23: Duration (years) | E23: 1 | F23: OR
A24: ='Population Definitions'!$A$10 -> 65+_males | B24: Framework-supplied default | C24: Duration (years) | E24: 1 | F24: OR
A25: ='Population Definitions'!$A$11 -> 65+_females | B25: Framework-supplied default | C25: Duration (years) | E25: 1 | F25: OR
A26: ='Population Definitions'!$A$12 -> Prisoners_males | B26: Framework-supplied default | C26: Duration (years) | E26: 1 | F26: OR
A27: ='Population Definitions'!$A$13 -> Prisoners_females | B27: Framework-supplied default | C27: Duration (years) | E27: 1 | F27: OR
A29: F0 to F1 progression rate (intermediate step) | B29: Provenance | C29: Units | D29: Uncertainty | E29: Constant | G29: 2000 | H29: 2001 | I29: 2002 | J29: 2003 | K29: 2004 | L29: 2005 | M29: 2006 | N29: 2007 | O29: 2008 | P29: 2009 | Q29: 2010 | R29: 2011 | S29: 2012 | T29: 2013 | U29: 2014 | V29: 2015 | W29: 2016 | X29: 2017 | Y29: 2018 | Z29: 2019 | AA29: 2020 | AB29: 2021 | AC29: 2022 | AD29: 2023 | AE29: 2024 | AF29: 2025 | AG29: 2026 | AH29: 2027 | AI29: 2028 | AJ29: 2029 | AK29: 2030 | AL29: 2031 | AM29: 2032 | AN29: 2033 | AO29: 2034 | AP29: 2035 | AQ29: 2036 | AR29: 2037 | AS29: 2038 | AT29: 2039 | AU29: 2040 | AV29: 2041 | AW29: 2042 | AX29: 2043 | AY29: 2044 | AZ29: 2045 | BA29: 2046 | BB29: 2047 | BC29: 2048 | BD29: 2049 | BE29: 2050
A30: ='Population Definitions'!$A$2 -> PWID_males | C30: Rate (per year) | D30: 0.094387755 | E30: 0.39 | F30: OR
A31: ='Population Definitions'!$A$3 -> PWID_females | C31: Rate (per year) | D31: 0.094387755 | E31: 0.39 | F31: OR
A32: ='Population Definitions'!$A$4 -> 0-9_males | C32: Rate (per year) | D32: 0.094387755 | E32: 0.39 | F32: OR
A33: ='Population Definitions'!$A$5 -> 0-9_females | C33: Rate (per year) | D33: 0.094387755 | E33: 0.39 | F33: OR
A34: ='Population Definitions'!$A$6 -> 10-17_males | C34: Rate (per year) | D34: 0.094387755 | E34: 0.39 | F34: OR
A35: ='Population Definitions'!$A$7 -> 10-17_females | C35: Rate (per year) | D35: 0.094387755 | E35: 0.39 | F35: OR
A36: ='Population Definitions'!$A$8 -> 18-64_males | C36: Rate (per year) | D36: 0.094387755 | E36: 0.39 | F36: OR
A37: ='Population Definitions'!$A$9 -> 18-64_females | C37: Rate (per year) | D37: 0.094387755 | E37: 0.39 | F37: OR
A38: ='Population Definitions'!$A$10 -> 65+_males | C38: Rate (per year) | D38: 0.094387755 | E38: 0.39 | F38: OR
A39: ='Population Definitions'!$A$11 -> 65+_females | C39: Rate (per year) | D39: 0.094387755 | E39: 0.39 | F39: OR
A40: ='Population Definitions'!$A$12 -> Prisoners_males | C40: Rate (per year) | D40: 0.094387755 | E40: 0.39 | F40: OR
A41: ='Population Definitions'!$A$13 -> Prisoners_females | C41: Rate (per year) | D41: 0.094387755 | E41: 0.39 | F41: OR
A43: F1 to F2 progression rate (intermediate step) | B43: Provenance | C43: Units | D43: Uncertainty | E43: Constant | G43: 2000 | H43: 2001 | I43: 2002 | J43: 2003 | K43: 2004 | L43: 2005 | M43: 2006 | N43: 2007 | O43: 2008 | P43: 2009 | Q43: 2010 | R43: 2011 | S43: 2012 | T43: 2013 | U43: 2014 | V43: 2015 | W43: 2016 | X43: 2017 | Y43: 2018 | Z43: 2019 | AA43: 2020 | AB43: 2021 | AC43: 2022 | AD43: 2023 | AE43: 2024 | AF43: 2025 | AG43: 2026 | AH43: 2027 | AI43: 2028 | AJ43: 2029 | AK43: 2030 | AL43: 2031 | AM43: 2032 | AN43: 2033 | AO43: 2034 | AP43: 2035 | AQ43: 2036 | AR43: 2037 | AS43: 2038 | AT43: 2039 | AU43: 2040 | AV43: 2041 | AW43: 2042 | AX43: 2043 | AY43: 2044 | AZ43: 2045 | BA43: 2046 | BB43: 2047 | BC43: 2048 | BD43: 2049 | BE43: 2050
...

Sheet Diagnosis
A1: Antibody testing rate in F0-F2, undiagnosed, in care (intermediate step) | B1: Provenance | C1: Units | D1: Uncertainty | E1: Constant | G1: 2000 | H1: 2001 | I1: 2002 | J1: 2003 | K1: 2004 | L1: 2005 | M1: 2006 | N1: 2007 | O1: 2008 | P1: 2009 | Q1: 2010 | R1: 2011 | S1: 2012 | T1: 2013 | U1: 2014 | V1: 2015 | W1: 2016 | X1: 2017 | Y1: 2018 | Z1: 2019 | AA1: 2020 | AB1: 2021 | AC1: 2022 | AD1: 2023 | AE1: 2024 | AF1: 2025 | AG1: 2026 | AH1: 2027 | AI1: 2028 | AJ1: 2029 | AK1: 2030 | AL1: 2031 | AM1: 2032 | AN1: 2033 | AO1: 2034 | AP1: 2035 | AQ1: 2036 | AR1: 2037 | AS1: 2038 | AT1: 2039 | AU1: 2040 | AV1: 2041 | AW1: 2042 | AX1: 2043 | AY1: 2044 | AZ1: 2045 | BA1: 2046 | BB1: 2047 | BC1: 2048 | BD1: 2049 | BE1: 2050
A2: ='Population Definitions'!$A$2 -> PWID_males | C2: Rate (per year) | D2: 0.025765306 | F2: OR | G2: 0.13 | V2: 0.26
A3: ='Population Definitions'!$A$3 -> PWID_females | C3: Rate (per year) | D3: 0.025765306 | F3: OR | G3: 0.13 | V3: 0.26
A4: ='Population Definitions'!$A$4 -> 0-9_males | C4: Rate (per year) | E4: 0 | F4: OR
A5: ='Population Definitions'!$A$5 -> 0-9_females | C5: Rate (per year) | E5: 0 | F5: OR
A6: ='Population Definitions'!$A$6 -> 10-17_males | C6: Rate (per year) | E6: 0 | F6: OR
A7: ='Population Definitions'!$A$7 -> 10-17_females | C7: Rate (per year) | E7: 0 | F7: OR
A8: ='Population Definitions'!$A$8 -> 18-64_males | C8: Rate (per year) | E8: 0.05 | F8: OR
A9: ='Population Definitions'!$A$9 -> 18-64_females | C9: Rate (per year) | E9: 0.05 | F9: OR
A10: ='Population Definitions'!$A$10 -> 65+_males | C10: Rate (per year) | E10: 0.05 | F10: OR
A11: ='Population Definitions'!$A$11 -> 65+_females | C11: Rate (per year) | E11: 0.05 | F11: OR
A12: ='Population Definitions'!$A$12 -> Prisoners_males | C12: Rate (per year) | E12: 0 | F12: OR
A13: ='Population Definitions'!$A$13 -> Prisoners_females | C13: Rate (per year) | E13: 0 | F13: OR
A15: Antibody testing rate in F3+, undiagnosed, in care (intermediate step) | B15: Provenance | C15: Units | D15: Uncertainty | E15: Constant | G15: 2000 | H15: 2001 | I15: 2002 | J15: 2003 | K15: 2004 | L15: 2005 | M15: 2006 | N15: 2007 | O15: 2008 | P15: 2009 | Q15: 2010 | R15: 2011 | S15: 2012 | T15: 2013 | U15: 2014 | V15: 2015 | W15: 2016 | X15: 2017 | Y15: 2018 | Z15: 2019 | AA15: 2020 | AB15: 2021 | AC15: 2022 | AD15: 2023 | AE15: 2024 | AF15: 2025 | AG15: 2026 | AH15: 2027 | AI15: 2028 | AJ15: 2029 | AK15: 2030 | AL15: 2031 | AM15: 2032 | AN15: 2033 | AO15: 2034 | AP15: 2035 | AQ15: 2036 | AR15: 2037 | AS15: 2038 | AT15: 2039 | AU15: 2040 | AV15: 2041 | AW15: 2042 | AX15: 2043 | AY15: 2044 | AZ15: 2045 | BA15: 2046 | BB15: 2047 | BC15: 2048 | BD15: 2049 | BE15: 2050
A16: ='Population Definitions'!$A$2 -> PWID_males | C16: Rate (per year) | D16: 0.025765306 | F16: OR | G16: 0.13 | V16: 0.26
A17: ='Population Definitions'!$A$3 -> PWID_females | C17: Rate (per year) | D17: 0.025765306 | F17: OR | G17: 0.13 | V17: 0.26
A18: ='Population Definitions'!$A$4 -> 0-9_males | C18: Rate (per year) | E18: 0 | F18: OR
A19: ='Population Definitions'!$A$5 -> 0-9_females | C19: Rate (per year) | E19: 0 | F19: OR
A20: ='Population Definitions'!$A$6 -> 10-17_males | C20: Rate (per year) | E20: 0 | F20: OR
A21: ='Population Definitions'!$A$7 -> 10-17_females | C21: Rate (per year) | E21: 0 | F21: OR
A22: ='Population Definitions'!$A$8 -> 18-64_males | C22: Rate (per year) | E22: 0.05 | F22: OR
A23: ='Population Definitions'!$A$9 -> 18-64_females | C23: Rate (per year) | E23: 0.05 | F23: OR
A24: ='Population Definitions'!$A$10 -> 65+_males | C24: Rate (per year) | E24: 0.05 | F24: OR
A25: ='Population Definitions'!$A$11 -> 65+_females | C25: Rate (per year) | E25: 0.05 | F25: OR
A26: ='Population Definitions'!$A$12 -> Prisoners_males | C26: Rate (per year) | E26: 0 | F26: OR
A27: ='Population Definitions'!$A$13 -> Prisoners_females | C27: Rate (per year) | E27: 0 | F27: OR
A29: RNA testing rate in F0-F2, Ab diagnosed, in care (intermediate step) | B29: Provenance | C29: Units | D29: Uncertainty | E29: Constant | G29: 2000 | H29: 2001 | I29: 2002 | J29: 2003 | K29: 2004 | L29: 2005 | M29: 2006 | N29: 2007 | O29: 2008 | P29: 2009 | Q29: 2010 | R29: 2011 | S29: 2012 | T29: 2013 | U29: 2014 | V29: 2015 | W29: 2016 | X29: 2017 | Y29: 2018 | Z29: 2019 | AA29: 2020 | AB29: 2021 | AC29: 2022 | AD29: 2023 | AE29: 2024 | AF29: 2025 | AG29: 2026 | AH29: 2027 | AI29: 2028 | AJ29: 2029 | AK29: 2030 | AL29: 2031 | AM29: 2032 | AN29: 2033 | AO29: 2034 | AP29: 2035 | AQ29: 2036 | AR29: 2037 | AS29: 2038 | AT29: 2039 | AU29: 2040 | AV29: 2041 | AW29: 2042 | AX29: 2043 | AY29: 2044 | AZ29: 2045 | BA29: 2046 | BB29: 2047 | BC29: 2048 | BD29: 2049 | BE29: 2050
A30: ='Population Definitions'!$A$2 -> PWID_males | C30: Rate (per year) | E30: 0.8 | F30: OR
A31: ='Population Definitions'!$A$3 -> PWID_females | C31: Rate (per year) | E31: 0.8 | F31: OR
A32: ='Population Definitions'!$A$4 -> 0-9_males | C32: Rate (per year) | E32: 0 | F32: OR
A33: ='Population Definitions'!$A$5 -> 0-9_females | C33: Rate (per year) | E33: 0 | F33: OR
A34: ='Population Definitions'!$A$6 -> 10-17_males | C34: Rate (per year) | E34: 0 | F34: OR
A35: ='Population Definitions'!$A$7 -> 10-17_females | C35: Rate (per year) | E35: 0 | F35: OR
A36: ='Population Definitions'!$A$8 -> 18-64_males | C36: Rate (per year) | E36: 0.3 | F36: OR
A37: ='Population Definitions'!$A$9 -> 18-64_females | C37: Rate (per year) | E37: 0.3 | F37: OR
A38: ='Population Definitions'!$A$10 -> 65+_males | C38: Rate (per year) | E38: 0.3 | F38: OR
A39: ='Population Definitions'!$A$11 -> 65+_females | C39: Rate (per year) | E39: 0.3 | F39: OR
A40: ='Population Definitions'!$A$12 -> Prisoners_males | C40: Rate (per year) | E40: 0 | F40: OR
A41: ='Population Definitions'!$A$13 -> Prisoners_females | C41: Rate (per year) | E41: 0 | F41: OR
A43: RNA testing rate in F3+, Ab diagnosed, in care (intermediate step) | B43: Provenance | C43: Units | D43: Uncertainty | E43: Constant | G43: 2000 | H43: 2001 | I43: 2002 | J43: 2003 | K43: 2004 | L43: 2005 | M43: 2006 | N43: 2007 | O43: 2008 | P43: 2009 | Q43: 2010 | R43: 2011 | S43: 2012 | T43: 2013 | U43: 2014 | V43: 2015 | W43: 2016 | X43: 2017 | Y43: 2018 | Z43: 2019 | AA43: 2020 | AB43: 2021 | AC43: 2022 | AD43: 2023 | AE43: 2024 | AF43: 2025 | AG43: 2026 | AH43: 2027 | AI43: 2028 | AJ43: 2029 | AK43: 2030 | AL43: 2031 | AM43: 2032 | AN43: 2033 | AO43: 2034 | AP43: 2035 | AQ43: 2036 | AR43: 2037 | AS43: 2038 | AT43: 2039 | AU43: 2040 | AV43: 2041 | AW43: 2042 | AX43: 2043 | AY43: 2044 | AZ43: 2045 | BA43: 2046 | BB43: 2047 | BC43: 2048 | BD43: 2049 | BE43: 2050
...

Sheet Loss to follow-up
A1: Loss to follow-up rate on antibody test in F0-F2 | B1: Provenance | C1: Units | D1: Uncertainty | E1: Constant | G1: 2000 | H1: 2001 | I1: 2002 | J1: 2003 | K1: 2004 | L1: 2005 | M1: 2006 | N1: 2007 | O1: 2008 | P1: 2009 | Q1: 2010 | R1: 2011 | S1: 2012 | T1: 2013 | U1: 2014 | V1: 2015 | W1: 2016 | X1: 2017 | Y1: 2018 | Z1: 2019 | AA1: 2020 | AB1: 2021 | AC1: 2022 | AD1: 2023 | AE1: 2024 | AF1: 2025 | AG1: 2026 | AH1: 2027 | AI1: 2028 | AJ1: 2029 | AK1: 2030 | AL1: 2031 | AM1: 2032 | AN1: 2033 | AO1: 2034 | AP1: 2035 | AQ1: 2036 | AR1: 2037 | AS1: 2038 | AT1: 2039 | AU1: 2040 | AV1: 2041 | AW1: 2042 | AX1: 2043 | AY1: 2044 | AZ1: 2045 | BA1: 2046 | BB1: 2047 | BC1: 2048 | BD1: 2049 | BE1: 2050
A2: ='Population Definitions'!$A$2 -> PWID_males | B2: Framework-supplied default | C2: Proportion | E2: 0 | F2: OR
A3: ='Population Definitions'!$A$3 -> PWID_females | B3: Framework-supplied default | C3: Proportion | E3: 0 | F3: OR
A4: ='Population Definitions'!$A$4 -> 0-9_males | B4: Framework-supplied default | C4: Proportion | E4: 0 | F4: OR
A5: ='Population Definitions'!$A$5 -> 0-9_females | B5: Framework-supplied default | C5: Proportion | E5: 0 | F5: OR
A6: ='Population Definitions'!$A$6 -> 10-17_males | B6: Framework-supplied default | C6: Proportion | E6: 0 | F6: OR
A7: ='Population Definitions'!$A$7 -> 10-17_females | B7: Framework-supplied default | C7: Proportion | E7: 0 | F7: OR
A8: ='Population Definitions'!$A$8 -> 18-64_males | B8: Framework-supplied default | C8: Proportion | E8: 0 | F8: OR
A9: ='Population Definitions'!$A$9 -> 18-64_females | B9: Framework-supplied default | C9: Proportion | E9: 0 | F9: OR
A10: ='Population Definitions'!$A$10 -> 65+_males | B10: Framework-supplied default | C10: Proportion | E10: 0 | F10: OR
A11: ='Population Definitions'!$A$11 -> 65+_females | B11: Framework-supplied default | C11: Proportion | E11: 0 | F11: OR
A12: ='Population Definitions'!$A$12 -> Prisoners_males | B12: Framework-supplied default | C12: Proportion | E12: 0 | F12: OR
A13: ='Population Definitions'!$A$13 -> Prisoners_females | B13: Framework-supplied default | C13: Proportion | E13: 0 | F13: OR
A15: Loss to follow-up rate on antibody test in F3+ | B15: Provenance | C15: Units | D15: Uncertainty | E15: Constant | G15: 2000 | H15: 2001 | I15: 2002 | J15: 2003 | K15: 2004 | L15: 2005 | M15: 2006 | N15: 2007 | O15: 2008 | P15: 2009 | Q15: 2010 | R15: 2011 | S15: 2012 | T15: 2013 | U15: 2014 | V15: 2015 | W15: 2016 | X15: 2017 | Y15: 2018 | Z15: 2019 | AA15: 2020 | AB15: 2021 | AC15: 2022 | AD15: 2023 | AE15: 2024 | AF15: 2025 | AG15: 2026 | AH15: 2027 | AI15: 2028 | AJ15: 2029 | AK15: 2030 | AL15: 2031 | AM15: 2032 | AN15: 2033 | AO15: 2034 | AP15: 2035 | AQ15: 2036 | AR15: 2037 | AS15: 2038 | AT15: 2039 | AU15: 2040 | AV15: 2041 | AW15: 2042 | AX15: 2043 | AY15: 2044 | AZ15: 2045 | BA15: 2046 | BB15: 2047 | BC15: 2048 | BD15: 2049 | BE15: 2050
A16: ='Population Definitions'!$A$2 -> PWID_males | B16: Framework-supplied default | C16: Proportion | E16: 0 | F16: OR
A17: ='Population Definitions'!$A$3 -> PWID_females | B17: Framework-supplied default | C17: Proportion | E17: 0 | F17: OR
A18: ='Population Definitions'!$A$4 -> 0-9_males | B18: Framework-supplied default | C18: Proportion | E18: 0 | F18: OR
A19: ='Population Definitions'!$A$5 -> 0-9_females | B19: Framework-supplied default | C19: Proportion | E19: 0 | F19: OR
A20: ='Population Definitions'!$A$6 -> 10-17_males | B20: Framework-supplied default | C20: Proportion | E20: 0 | F20: OR
A21: ='Population Definitions'!$A$7 -> 10-17_females | B21: Framework-supplied default | C21: Proportion | E21: 0 | F21: OR
A22: ='Population Definitions'!$A$8 -> 18-64_males | B22: Framework-supplied default | C22: Proportion | E22: 0 | F22: OR
A23: ='Population Definitions'!$A$9 -> 18-64_females | B23: Framework-supplied default | C23: Proportion | E23: 0 | F23: OR
A24: ='Population Definitions'!$A$10 -> 65+_males | B24: Framework-supplied default | C24: Proportion | E24: 0 | F24: OR
A25: ='Population Definitions'!$A$11 -> 65+_females | B25: Framework-supplied default | C25: Proportion | E25: 0 | F25: OR
A26: ='Population Definitions'!$A$12 -> Prisoners_males | B26: Framework-supplied default | C26: Proportion | E26: 0 | F26: OR
A27: ='Population Definitions'!$A$13 -> Prisoners_females | B27: Framework-supplied default | C27: Proportion | E27: 0 | F27: OR
A29: Loss to follow-up rate on PCR test in F0-F2 | B29: Provenance | C29: Units | D29: Uncertainty | E29: Constant | G29: 2000 | H29: 2001 | I29: 2002 | J29: 2003 | K29: 2004 | L29: 2005 | M29: 2006 | N29: 2007 | O29: 2008 | P29: 2009 | Q29: 2010 | R29: 2011 | S29: 2012 | T29: 2013 | U29: 2014 | V29: 2015 | W29: 2016 | X29: 2017 | Y29: 2018 | Z29: 2019 | AA29: 2020 | AB29: 2021 | AC29: 2022 | AD29: 2023 | AE29: 2024 | AF29: 2025 | AG29: 2026 | AH29: 2027 | AI29: 2028 | AJ29: 2029 | AK29: 2030 | AL29: 2031 | AM29: 2032 | AN29: 2033 | AO29: 2034 | AP29: 2035 | AQ29: 2036 | AR29: 2037 | AS29: 2038 | AT29: 2039 | AU29: 2040 | AV29: 2041 | AW29: 2042 | AX29: 2043 | AY29: 2044 | AZ29: 2045 | BA29: 2046 | BB29: 2047 | BC29: 2048 | BD29: 2049 | BE29: 2050
A30: ='Population Definitions'!$A$2 -> PWID_males | B30: Framework-supplied default | C30: Proportion | E30: 0 | F30: OR
A31: ='Population Definitions'!$A$3 -> PWID_females | B31: Framework-supplied default | C31: Proportion | E31: 0 | F31: OR
A32: ='Population Definitions'!$A$4 -> 0-9_males | B32: Framework-supplied default | C32: Proportion | E32: 0 | F32: OR
A33: ='Population Definitions'!$A$5 -> 0-9_females | B33: Framework-supplied default | C33: Proportion | E33: 0 | F33: OR
A34: ='Population Definitions'!$A$6 -> 10-17_males | B34: Framework-supplied default | C34: Proportion | E34: 0 | F34: OR
A35: ='Population Definitions'!$A$7 -> 10-17_females | B35: Framework-supplied default | C35: Proportion | E35: 0 | F35: OR
A36: ='Population Definitions'!$A$8 -> 18-64_males | B36: Framework-supplied default | C36: Proportion | E36: 0 | F36: OR
A37: ='Population Definitions'!$A$9 -> 18-64_females | B37: Framework-supplied default | C37: Proportion | E37: 0 | F37: OR
A38: ='Population Definitions'!$A$10 -> 65+_males | B38: Framework-supplied default | C38: Proportion | E38: 0 | F38: OR
A39: ='Population Definitions'!$A$11 -> 65+_females | B39: Framework-supplied default | C39: Proportion | E39: 0 | F39: OR
A40: ='Population Definitions'!$A$12 -> Prisoners_males | B40: Framework-supplied default | C40: Proportion | E40: 0 | F40: OR
A41: ='Population Definitions'!$A$13 -> Prisoners_females | B41: Framework-supplied default | C41: Proportion | E41: 0 | F41: OR
A43: Loss to follow-up rate on PCR test in F3+ | B43: Provenance | C43: Units | D43: Uncertainty | E43: Constant | G43: 2000 | H43: 2001 | I43: 2002 | J43: 2003 | K43: 2004 | L43: 2005 | M43: 2006 | N43: 2007 | O43: 2008 | P43: 2009 | Q43: 2010 | R43: 2011 | S43: 2012 | T43: 2013 | U43: 2014 | V43: 2015 | W43: 2016 | X43: 2017 | Y43: 2018 | Z43: 2019 | AA43: 2020 | AB43: 2021 | AC43: 2022 | AD43: 2023 | AE43: 2024 | AF43: 2025 | AG43: 2026 | AH43: 2027 | AI43: 2028 | AJ43: 2029 | AK43: 2030 | AL43: 2031 | AM43: 2032 | AN43: 2033 | AO43: 2034 | AP43: 2035 | AQ43: 2036 | AR43: 2037 | AS43: 2038 | AT43: 2039 | AU43: 2040 | AV43: 2041 | AW43: 2042 | AX43: 2043 | AY43: 2044 | AZ43: 2045 | BA43: 2046 | BB43: 2047 | BC43: 2048 | BD43: 2049 | BE43: 2050
...

Sheet Re-engagement
A1: Antibody re-engagement in care, F0-F2, lost to follow-up after Ab test | B1: Provenance | C1: Units | D1: Uncertainty | E1: Constant | G1: 2000 | H1: 2001 | I1: 2002 | J1: 2003 | K1: 2004 | L1: 2005 | M1: 2006 | N1: 2007 | O1: 2008 | P1: 2009 | Q1: 2010 | R1: 2011 | S1: 2012 | T1: 2013 | U1: 2014 | V1: 2015 | W1: 2016 | X1: 2017 | Y1: 2018 | Z1: 2019 | AA1: 2020 | AB1: 2021 | AC1: 2022 | AD1: 2023 | AE1: 2024 | AF1: 2025 | AG1: 2026 | AH1: 2027 | AI1: 2028 | AJ1: 2029 | AK1: 2030 | AL1: 2031 | AM1: 2032 | AN1: 2033 | AO1: 2034 | AP1: 2035 | AQ1: 2036 | AR1: 2037 | AS1: 2038 | AT1: 2039 | AU1: 2040 | AV1: 2041 | AW1: 2042 | AX1: 2043 | AY1: 2044 | AZ1: 2045 | BA1: 2046 | BB1: 2047 | BC1: 2048 | BD1: 2049 | BE1: 2050
A2: ='Population Definitions'!$A$2 -> PWID_males | B2: Framework-supplied default | C2: Rate (per year) | E2: 0 | F2: OR
A3: ='Population Definitions'!$A$3 -> PWID_females | B3: Framework-supplied default | C3: Rate (per year) | E3: 0 | F3: OR
A4: ='Population Definitions'!$A$4 -> 0-9_males | B4: Framework-supplied default | C4: Rate (per year) | E4: 0 | F4: OR
A5: ='Population Definitions'!$A$5 -> 0-9_females | B5: Framework-supplied default | C5: Rate (per year) | E5: 0 | F5: OR
A6: ='Population Definitions'!$A$6 -> 10-17_males | B6: Framework-supplied default | C6: Rate (per year) | E6: 0 | F6: OR
A7: ='Population Definitions'!$A$7 -> 10-17_females | B7: Framework-supplied default | C7: Rate (per year) | E7: 0 | F7: OR
A8: ='Population Definitions'!$A$8 -> 18-64_males | B8: Framework-supplied default | C8: Rate (per year) | E8: 0 | F8: OR
A9: ='Population Definitions'!$A$9 -> 18-64_females | B9: Framework-supplied default | C9: Rate (per year) | E9: 0 | F9: OR
A10: ='Population Definitions'!$A$10 -> 65+_males | B10: Framework-supplied default | C10: Rate (per year) | E10: 0 | F10: OR
A11: ='Population Definitions'!$A$11 -> 65+_females | B11: Framework-supplied default | C11: Rate (per year) | E11: 0 | F11: OR
A12: ='Population Definitions'!$A$12 -> Prisoners_males | B12: Framework-supplied default | C12: Rate (per year) | E12: 0 | F12: OR
A13: ='Population Definitions'!$A$13 -> Prisoners_females | B13: Framework-supplied default | C13: Rate (per year) | E13: 0 | F13: OR
A15: Antibody re-engagement in care, F3+, lost to follow-up after Ab test | B15: Provenance | C15: Units | D15: Uncertainty | E15: Constant | G15: 2000 | H15: 2001 | I15: 2002 | J15: 2003 | K15: 2004 | L15: 2005 | M15: 2006 | N15: 2007 | O15: 2008 | P15: 2009 | Q15: 2010 | R15: 2011 | S15: 2012 | T15: 2013 | U15: 2014 | V15: 2015 | W15: 2016 | X15: 2017 | Y15: 2018 | Z15: 2019 | AA15: 2020 | AB15: 2021 | AC15: 2022 | AD15: 2023 | AE15: 2024 | AF15: 2025 | AG15: 2026 | AH15: 2027 | AI15: 2028 | AJ15: 2029 | AK15: 2030 | AL15: 2031 | AM15: 2032 | AN15: 2033 | AO15: 2034 | AP15: 2035 | AQ15: 2036 | AR15: 2037 | AS15: 2038 | AT15: 2039 | AU15: 2040 | AV15: 2041 | AW15: 2042 | AX15: 2043 | AY15: 2044 | AZ15: 2045 | BA15: 2046 | BB15: 2047 | BC15: 2048 | BD15: 2049 | BE15: 2050
A16: ='Population Definitions'!$A$2 -> PWID_males | B16: Framework-supplied default | C16: Rate (per year) | E16: 0 | F16: OR
A17: ='Population Definitions'!$A$3 -> PWID_females | B17: Framework-supplied default | C17: Rate (per year) | E17: 0 | F17: OR
A18: ='Population Definitions'!$A$4 -> 0-9_males | B18: Framework-supplied default | C18: Rate (per year) | E18: 0 | F18: OR
A19: ='Population Definitions'!$A$5 -> 0-9_females | B19: Framework-supplied default | C19: Rate (per year) | E19: 0 | F19: OR
A20: ='Population Definitions'!$A$6 -> 10-17_males | B20: Framework-supplied default | C20: Rate (per year) | E20: 0 | F20: OR
A21: ='Population Definitions'!$A$7 -> 10-17_females | B21: Framework-supplied default | C21: Rate (per year) | E21: 0 | F21: OR
A22: ='Population Definitions'!$A$8 -> 18-64_males | B22: Framework-supplied default | C22: Rate (per year) | E22: 0 | F22: OR
A23: ='Population Definitions'!$A$9 -> 18-64_females | B23: Framework-supplied default | C23: Rate (per year) | E23: 0 | F23: OR
A24: ='Population Definitions'!$A$10 -> 65+_males | B24: Framework-supplied default | C24: Rate (per year) | E24: 0 | F24: OR
A25: ='Population Definitions'!$A$11 -> 65+_females | B25: Framework-supplied default | C25: Rate (per year) | E25: 0 | F25: OR
A26: ='Population Definitions'!$A$12 -> Prisoners_males | B26: Framework-supplied default | C26: Rate (per year) | E26: 0 | F26: OR
A27: ='Population Definitions'!$A$13 -> Prisoners_females | B27: Framework-supplied default | C27: Rate (per year) | E27: 0 | F27: OR
A29: RNA re-engagement in care, F0-F2, lost to follow up after RNA test | B29: Provenance | C29: Units | D29: Uncertainty | E29: Constant | G29: 2000 | H29: 2001 | I29: 2002 | J29: 2003 | K29: 2004 | L29: 2005 | M29: 2006 | N29: 2007 | O29: 2008 | P29: 2009 | Q29: 2010 | R29: 2011 | S29: 2012 | T29: 2013 | U29: 2014 | V29: 2015 | W29: 2016 | X29: 2017 | Y29: 2018 | Z29: 2019 | AA29: 2020 | AB29: 2021 | AC29: 2022 | AD29: 2023 | AE29: 2024 | AF29: 2025 | AG29: 2026 | AH29: 2027 | AI29: 2028 | AJ29: 2029 | AK29: 2030 | AL29: 2031 | AM29: 2032 | AN29: 2033 | AO29: 2034 | AP29: 2035 | AQ29: 2036 | AR29: 2037 | AS29: 2038 | AT29: 2039 | AU29: 2040 | AV29: 2041 | AW29: 2042 | AX29: 2043 | AY29: 2044 | AZ29: 2045 | BA29: 2046 | BB29: 2047 | BC29: 2048 | BD29: 2049 | BE29: 2050
A30: ='Population Definitions'!$A$2 -> PWID_males | B30: Framework-supplied default | C30: Rate (per year) | E30: 0 | F30: OR
A31: ='Population Definitions'!$A$3 -> PWID_females | B31: Framework-supplied default | C31: Rate (per year) | E31: 0 | F31: OR
A32: ='Population Definitions'!$A$4 -> 0-9_males | B32: Framework-supplied default | C32: Rate (per year) | E32: 0 | F32: OR
A33: ='Population Definitions'!$A$5 -> 0-9_females | B33: Framework-supplied default | C33: Rate (per year) | E33: 0 | F33: OR
A34: ='Population Definitions'!$A$6 -> 10-17_males | B34: Framework-supplied default | C34: Rate (per year) | E34: 0 | F34: OR
A35: ='Population Definitions'!$A$7 -> 10-17_females | B35: Framework-supplied default | C35: Rate (per year) | E35: 0 | F35: OR
