Workbook

Sheet Population Definitions
A1: Abbreviation | B1: Full Name | C1: Population type
A2: PWID_males | B2: People Who Inject Drugs (males) | C2: human
A3: PWID_females | B3: People Who Inject Drugs (females) | C3: human
A4: 0-9_males | B4: General Population 0-9 males | C4: human
A5: 0-9_females | B5: General Population 0-9 females | C5: human
A6: 10-17_males | B6: General Population 10-17 males | C6: human
A7: 10-17_females | B7: General Population 10-17 females | C7: human
A8: 18-64_males | B8: General Population 18-64 males | C8: human
A9: 18-64_females | B9: General Population 18-64 females | C9: human
A10: 65+_males | B10: General Population 65+ males | C10: human
A11: 65+_females | B11: General Population 65+ females | C11: human
A12: Prisoners_males | B12: Prisoners (males) | C12: human
... A15: Prisoners_PWID_females | B15: Prisoners (females) | C15: human

Sheet Disease Burden
A1: Population living with chronic HCV | B1: Provenance | C1: Units | D1: Uncertainty | E1: 2000 | F1: 2001 | G1: 2002 | H1: 2003 | I1: 2004 | J1: 2005 | K1: 2006 | L1: 2007 | M1: 2008 | N1: 2009 | O1: 2010 | P1: 2011 | Q1: 2012 | R1: 2013 | S1: 2014 | T1: 2015 | U1: 2016 | V1: 2017 | W1: 2018 | X1: 2019 | Y1: 2020 | Z1: 2021 | AA1: 2022 | AB1: 2023 | AC1: 2024 | AD1: 2025 | AE1: 2026 | AF1: 2027 | AG1: 2028 | AH1: 2029 | AI1: 2030 | AJ1: 2031 | AK1: 2032 | AL1: 2033 | AM1: 2034 | AN1: 2035 | AO1: 2036 | AP1: 2037 | AQ1: 2038 | AR1: 2039 | AS1: 2040 | AT1: 2041 | AU1: 2042 | AV1: 2043 | AW1: 2044 | AX1: 2045 | AY1: 2046 | AZ1: 2047 | BA1: 2048 | BB1: 2049 | BC1: 2050
A2: ='Population Definitions'!$A$2 -> PWID_males | C2: Number | E2: 18484.024
A3: ='Population Definitions'!$A$3 -> PWID_females | C3: Number | E3: 5216.1312
A4: ='Population Definitions'!$A$4 -> 0-9_males | C4: Number | E4: 0
A5: ='Population Definitions'!$A$5 -> 0-9_females | C5: Number | E5: 0
A6: ='Population Definitions'!$A$6 -> 10-17_males | C6: Number | E6: 0
A7: ='Population Definitions'!$A$7 -> 10-17_females | C7: Number | E7: 0
A8: ='Population Definitions'!$A$8 -> 18-64_males | C8: Number | E8: 35651.658
A9: ='Population Definitions'!$A$9 -> 18-64_females | C9: Number | E9: 37715.531
A10: ='Population Definitions'!$A$10 -> 65+_males | C10: Number | E10: 2042.6865
A11: ='Population Definitions'!$A$11 -> 65+_females | C11: Number | E11: 2514.0493
A12: ='Population Definitions'!$A$12 -> Prisoners_males | C12: Number | E12: 52.517131
A13: ='Population Definitions'!$A$13 -> Prisoners_females | C13: Number | E13: 1.7922082
A14: ='Population Definitions'!$A$14 -> Prisoners_PWID_males | C14: Number | E14: 5656.5736
A15: ='Population Definitions'!$A$15 -> Prisoners_PWID_females | C15: Number | E15: 193.03715
A17: HCV Prevalence | B17: Provenance | C17: Units | D17: Uncertainty | E17: 2000 | F17: 2001 | G17: 2002 | H17: 2003 | I17: 2004 | J17: 2005 | K17: 2006 | L17: 2007 | M17: 2008 | N17: 2009 | O17: 2010 | P17: 2011 | Q17: 2012 | R17: 2013 | S17: 2014 | T17: 2015 | U17: 2016 | V17: 2017 | W17: 2018 | X17: 2019 | Y17: 2020 | Z17: 2021 | AA17: 2022 | AB17: 2023 | AC17: 2024 | AD17: 2025 | AE17: 2026 | AF17: 2027 | AG17: 2028 | AH17: 2029 | AI17: 2030 | AJ17: 2031 | AK17: 2032 | AL17: 2033 | AM17: 2034 | AN17: 2035 | AO17: 2036 | AP17: 2037 | AQ17: 2038 | AR17: 2039 | AS17: 2040 | AT17: 2041 | AU17: 2042 | AV17: 2043 | AW17: 2044 | AX17: 2045 | AY17: 2046 | AZ17: 2047 | BA17: 2048 | BB17: 2049 | BC17: 2050
A18: ='Population Definitions'!$A$2 -> PWID_males | C18: Fraction | E18: 0.208 | O18: 0.208 | T18: 0.208 | V18: 0.171
A19: ='Population Definitions'!$A$3 -> PWID_females | C19: Fraction | E19: 0.208 | O19: 0.208 | T19: 0.208 | V19: 0.171
A20: ='Population Definitions'!$A$4 -> 0-9_males | C20: Fraction | E20: 0 | O20: 0
A21: ='Population Definitions'!$A$5 -> 0-9_females | C21: Fraction | E21: 0 | O21: 0
A22: ='Population Definitions'!$A$6 -> 10-17_males | C22: Fraction | E22: 0 | O22: 0
A23: ='Population Definitions'!$A$7 -> 10-17_females | C23: Fraction | E23: 0 | O23: 0
A24: ='Population Definitions'!$A$8 -> 18-64_males | C24: Fraction | E24: 0.0047628282 | O24: 0
A25: ='Population Definitions'!$A$9 -> 18-64_females | C25: Fraction | E25: 0.0047628282 | O25: 0
A26: ='Population Definitions'!$A$10 -> 65+_males | C26: Fraction | E26: 0.0047628282 | O26: 0
A27: ='Population Definitions'!$A$11 -> 65+_females | C27: Fraction | E27: 0.0047628282 | O27: 0
A28: ='Population Definitions'!$A$12 -> Prisoners_males | C28: Fraction | E28: 0.0047628282 | O28: 0
A29: ='Population Definitions'!$A$13 -> Prisoners_females | C29: Fraction | E29: 0.0047628282 | O29: 0
A30: ='Population Definitions'!$A$14 -> Prisoners_PWID_males | C30: Fraction | E30: 0.171 | O30: 0.171
A31: ='Population Definitions'!$A$15 -> Prisoners_PWID_females | C31: Fraction | E31: 0.171 | O31: 0.171
A33: Proportion who have F0-F2 | B33: Provenance | C33: Units | D33: Uncertainty | E33: Constant | G33: 2000 | H33: 2001 | I33: 2002 | J33: 2003 | K33: 2004 | L33: 2005 | M33: 2006 | N33: 2007 | O33: 2008 | P33: 2009 | Q33: 2010 | R33: 2011 | S33: 2012 | T33: 2013 | U33: 2014 | V33: 2015 | W33: 2016 | X33: 2017 | Y33: 2018 | Z33: 2019 | AA33: 2020 | AB33: 2021 | AC33: 2022 | AD33: 2023 | AE33: 2024 | AF33: 2025 | AG33: 2026 | AH33: 2027 | AI33: 2028 | AJ33: 2029 | AK33: 2030 | AL33: 2031 | AM33: 2032 | AN33: 2033 | AO33: 2034 | AP33: 2035 | AQ33: 2036 | AR33: 2037 | AS33: 2038 | AT33: 2039 | AU33: 2040 | AV33: 2041 | AW33: 2042 | AX33: 2043 | AY33: 2044 | AZ33: 2045 | BA33: 2046 | BB33: 2047 | BC33: 2048 | BD33: 2049 | BE33: 2050
A34: ='Population Definitions'!$A$2 -> PWID_males | C34: Fraction | E34: 0.945 | F34: OR
A35: ='Population Definitions'!$A$3 -> PWID_females | C35: Fraction | E35: 0.945 | F35: OR
A36: ='Population Definitions'!$A$4 -> 0-9_males | C36: Fraction | E36: 0.945 | F36: OR
A37: ='Population Definitions'!$A$5 -> 0-9_females | C37: Fraction | E37: 0.945 | F37: OR
A38: ='Population Definitions'!$A$6 -> 10-17_males | C38: Fraction | E38: 0.945 | F38: OR
A39: ='Population Definitions'!$A$7 -> 10-17_females | C39: Fraction | E39: 0.945 | F39: OR
A40: ='Population Definitions'!$A$8 -> 18-64_males | C40: Fraction | E40: 0.945 | F40: OR
A41: ='Population Definitions'!$A$9 -> 18-64_females | C41: Fraction | E41: 0.945 | F41: OR
A42: ='Population Definitions'!$A$10 -> 65+_males | C42: Fraction | E42: 0.945 | F42: OR
...

Sheet Demographics
A1: Population size | B1: Provenance | C1: Units | D1: Uncertainty | E1: 2000 | F1: 2001 | G1: 2002 | H1: 2003 | I1: 2004 | J1: 2005 | K1: 2006 | L1: 2007 | M1: 2008 | N1: 2009 | O1: 2010 | P1: 2011 | Q1: 2012 | R1: 2013 | S1: 2014 | T1: 2015 | U1: 2016 | V1: 2017 | W1: 2018 | X1: 2019 | Y1: 2020 | Z1: 2021 | AA1: 2022 | AB1: 2023 | AC1: 2024 | AD1: 2025 | AE1: 2026 | AF1: 2027 | AG1: 2028 | AH1: 2029 | AI1: 2030 | AJ1: 2031 | AK1: 2032 | AL1: 2033 | AM1: 2034 | AN1: 2035 | AO1: 2036 | AP1: 2037 | AQ1: 2038 | AR1: 2039 | AS1: 2040 | AT1: 2041 | AU1: 2042 | AV1: 2043 | AW1: 2044 | AX1: 2045 | AY1: 2046 | AZ1: 2047 | BA1: 2048 | BB1: 2049 | BC1: 2050
A2: ='Population Definitions'!$A$2 -> PWID_males | C2: Number | E2: 88865.5 | O2: 88865.5 | Q2: 88865.5
A3: ='Population Definitions'!$A$3 -> PWID_females | C3: Number | E3: 25077.554 | O3: 25077.554 | Q3: 25077.554
A4: ='Population Definitions'!$A$4 -> 0-9_males | C4: Number | E4: 5496435.5 | F4: 5654456 | G4: 5820044.5 | H4: 5997669.5 | I4: 6188140 | J4: 6384993 | K4: 6581814 | L4: 6776079 | M4: 6964779.5 | N4: 7146785 | O4: 7328745 | P4: 7510044 | Q4: 7693403 | R4: 7887884.5 | S4: 8089046 | T4: 8289534.5 | U4: 8497360.5 | V4: 8725621 | W4: 8969952 | X4: 9221171 | Y4: 9477342.5 | Z4: 9740394 | AA4: 10005196 | AB4: 10259843 | AC4: 10501854 | AD4: 10740174 | AE4: 10972616 | AF4: 11189496 | AG4: 11394108 | AH4: 11595192 | AI4: 11795790 | AJ4: 11995766 | AK4: 12192366 | AL4: 12384580 | AM4: 12578612 | AN4: 12776232 | AO4: 12974713 | AP4: 13171382 | AQ4: 13369346 | AR4: 13569805 | AS4: 13769714 | AT4: 13965998 | AU4: 14162940 | AV4: 14363198 | AW4: 14561610 | AX4: 14754628 | AY4: 14947092 | AZ4: 15145052 | BA4: 15339733 | BB4: 15523236 | BC4: 15701498
A5: ='Population Definitions'!$A$5 -> 0-9_females | C5: Number | E5: 5428218.5 | F5: 5585890 | G5: 5751513.5 | H5: 5929275.5 | I5: 6119774 | J5: 6316481 | K5: 6512554 | L5: 6704988.5 | M5: 6890862 | N5: 7069197 | O5: 7246217 | P5: 7421380 | Q5: 7597435 | R5: 7783386 | S5: 7975216.5 | T5: 8166025.5 | U5: 8363809.5 | V5: 8581411 | W5: 8814190.5 | X5: 9052903.5 | Y5: 9296462 | Z5: 9547543.5 | AA5: 9800557.5 | AB5: 10043351 | AC5: 10274006 | AD5: 10501792 | AE5: 10724832 | AF5: 10933631 | AG5: 11131159 | AH5: 11325725 | AI5: 11520421 | AJ5: 11715113 | AK5: 11906974 | AL5: 12094876 | AM5: 12284754 | AN5: 12478393 | AO5: 12673120 | AP5: 12866176 | AQ5: 13060408 | AR5: 13257086 | AS5: 13453225 | AT5: 13645440 | AU5: 13838186 | AV5: 14034344 | AW5: 14228782 | AX5: 14417939 | AY5: 14606427 | AZ5: 14800148 | BA5: 14990674 | BB5: 15170100 | BC5: 15344050
A6: ='Population Definitions'!$A$6 -> 10-17_males | C6: Number | E6: 3362471 | F6: 3435115.5 | G6: 3507199.5 | H6: 3582993.5 | I6: 3665830 | J6: 3760245.5 | K6: 3864528.5 | L6: 3975091 | M6: 4093054.5 | N6: 4215733 | O6: 4348047 | P6: 4494735.5 | Q6: 4646665.5 | R6: 4801682 | S6: 4961721.5 | T6: 5134144 | U6: 5311730 | V6: 5480378 | W6: 5638372 | X6: 5788664 | Y6: 5938850.5 | Z6: 6084186 | AA6: 6223099 | AB6: 6368015 | AC6: 6525898 | AD6: 6692886.5 | AE6: 6872389 | AF6: 7070927.5 | AG6: 7282703.5 | AH6: 7502680.5 | AI6: 7723206.5 | AJ6: 7933163 | AK6: 8132520.5 | AL6: 8331168 | AM6: 8525934.5 | AN6: 8705459 | AO6: 8873937.5 | AP6: 9038635 | AQ6: 9200670 | AR6: 9360476 | AS6: 9517563.5 | AT6: 9673107 | AU6: 9826711 | AV6: 9979369 | AW6: 10134926 | AX6: 10293788 | AY6: 10454552 | AZ6: 10613397 | BA6: 10772130 | BB6: 10931772 | BC6: 11092368
A7: ='Population Definitions'!$A$7 -> 10-17_females | C7: Number | E7: 3334351.5 | F7: 3404909.5 | G7: 3475800.5 | H7: 3550159 | I7: 3631556 | J7: 3724555 | K7: 3827689.5 | L7: 3937409.5 | M7: 4055389.5 | N7: 4179983.5 | O7: 4313113 | P7: 4458307.5 | Q7: 4608922.5 | R7: 4762767.5 | S7: 4922075 | T7: 5092128 | U7: 5265927 | V7: 5431463 | W7: 5587430 | X7: 5735910.5 | Y7: 5881996.5 | Z7: 6021321 | AA7: 6153303.5 | AB7: 6290565.5 | AC7: 6439921 | AD7: 6598003.5 | AE7: 6768316.5 | AF7: 6956955.5 | AG7: 7158597 | AH7: 7368487 | AI7: 7579237 | AJ7: 7779885 | AK7: 7970233 | AL7: 8160254.5 | AM7: 8347304.5 | AN7: 8520381 | AO7: 8683331.5 | AP7: 8843123 | AQ7: 9000719.5 | AR7: 9156479.5 | AS7: 9310216.5 | AT7: 9463023.5 | AU7: 9614116 | AV7: 9764202.5 | AW7: 9917108 | AX7: 10073422 | AY7: 10231756 | AZ7: 10388293 | BA7: 10544436 | BB7: 10701277 | BC7: 10859218
A8: ='Population Definitions'!$A$8 -> 18-64_males | C8: Number | E8: 7485396.6 | F8: 7706212.1 | G8: 7902768.6 | H8: 8104957.6 | I8: 8311534.1 | J8: 8524475.7 | K8: 8747026.2 | L8: 8978258.7 | M8: 9199139.2 | N8: 9369762.7 | O8: 9565245.2 | P8: 9845210.5 | Q8: 10151484 | R8: 10502987 | S8: 10884849 | T8: 11345737 | U8: 11870689 | V8: 12390503 | W8: 12866615 | X8: 13306637 | Y8: 13776947 | Z8: 14278893 | AA8: 14797127 | AB8: 15329976 | AC8: 16096652 | AD8: 16670365 | AE8: 17252569 | AF8: 17841130 | AG8: 18438272 | AH8: 19045458 | AI8: 19666397 | AJ8: 20310252 | AK8: 20977110 | AL8: 21654336 | AM8: 22348074 | AN8: 23064825 | AO8: 23799414 | AP8: 24547341 | AQ8: 25305385 | AR8: 26074469 | AS8: 26854018 | AT8: 27645631 | AU8: 28450956 | AV8: 29266388 | AW8: 30090718 | AX8: 30927160 | AY8: 31771583 | AZ8: 32622381 | BA8: 33481487 | BB8: 34346870 | BC8: 35217788
A9: ='Population Definitions'!$A$9 -> 18-64_females | C9: Number | E9: 7918725.8 | F9: 8157705.8 | G9: 8389100.8 | H9: 8627130.8 | I9: 8871318.3 | J9: 9122809.2 | K9: 9383622.7 | L9: 9653159.2 | M9: 9919916.7 | N9: 10163332 | O9: 10421422 | P9: 10720472 | Q9: 11040878 | R9: 11392326 | S9: 11769863 | T9: 12193387 | U9: 12657089 | V9: 13125993 | W9: 13580832 | X9: 14026369 | Y9: 14495799 | Z9: 14991064 | AA9: 15503631 | AB9: 16033678 | AC9: 16606026 | AD9: 17168663 | AE9: 17741952 | AF9: 18324464 | AG9: 18918425 | AH9: 19525282 | AI9: 20148378 | AJ9: 20796338 | AK9: 21468829 | AL9: 22152527 | AM9: 22852583 | AN9: 23574670 | AO9: 24313421 | AP9: 25064101 | AQ9: 25822992 | AR9: 26590020 | AS9: 27364622 | AT9: 28148463 | AU9: 28943300 | AV9: 29746184 | AW9: 30556661 | AX9: 31379140 | AY9: 32209740 | AZ9: 33047011 | BA9: 33893223 | BB9: 34746475 | BC9: 35606249
A10: ='Population Definitions'!$A$10 -> 65+_males | C10: Number | E10: 428881 | F10: 438506 | G10: 448965.5 | H10: 460354 | I10: 472617 | J10: 485876.5 | K10: 500430 | L10: 516484 | M10: 534153 | N10: 553393 | O10: 574138.5 | P10: 596344.5 | Q10: 619665.5 | R10: 642575 | S10: 663772.5 | T10: 683667.5 | U10: 702968.5 | V10: 721861 | W10: 740031.5 | X10: 757174 | Y10: 772868.5 | Z10: 786933.5 | AA10: 801639 | AB10: 817298 | AC10: 832241 | AD10: 847347 | AE10: 863485 | AF10: 881373 | AG10: 902051.5 | AH10: 926535.5 | AI10: 955690.5 | AJ10: 990447.5 | AK10: 1031277 | AL10: 1077823 | AM10: 1130219 | AN10: 1188254.5 | AO10: 1251592.5 | AP10: 1319593.5 | AQ10: 1391370.5 | AR10: 1466616.5 | AS10: 1544471.5 | AT10: 1623572 | AU10: 1704009.5 | AV10: 1786126.5 | AW10: 1869977.5 | AX10: 1956217.5 | AY10: 2044787.5 | AZ10: 2136208 | BA10: 2231259.5 | BB10: 2329278.5 | BC10: 2430002
A11: ='Population Definitions'!$A$11 -> 65+_females | C11: Number | E11: 527848 | F11: 537693.5 | G11: 548100 | H11: 559204.5 | I11: 571088.5 | J11: 584024.5 | K11: 598622 | L11: 615427 | M11: 634818 | N11: 657180 | O11: 682944.5 | P11: 712320.5 | Q11: 745254 | R11: 779968 | S11: 814414.5 | T11: 849735 | U11: 887836 | V11: 929056.5 | W11: 973117.5 | X11: 1019458 | Y11: 1067894.5 | Z11: 1115439 | AA11: 1162397 | AB11: 1210009 | AC11: 1255416.5 | AD11: 1298491.5 | AE11: 1339479.5 | AF11: 1378689 | AG11: 1417033 | AH11: 1455693 | AI11: 1495861.5 | AJ11: 1538831 | AK11: 1585682.5 | AL11: 1636785 | AM11: 1693055 | AN11: 1755072.5 | AO11: 1823141 | AP11: 1897284.5 | AQ11: 1977438 | AR11: 2064435.5 | AS11: 2157385.5 | AT11: 2255103.5 | AU11: 2357917 | AV11: 2465840.5 | AW11: 2578347.5 | AX11: 2695037 | AY11: 2815595 | AZ11: 2940394 | BA11: 3070217.5 | BB11: 3204255.5 | BC11: 3341788
A12: ='Population Definitions'!$A$12 -> Prisoners_males | C12: Number | E12: 11026.459 | J12: 11221.068 | P12: 9262.2495 | T12: 8308.566 | Y12: 7833.777 | AA12: 7890.0465
A13: ='Population Definitions'!$A$13 -> Prisoners_females | C13: Number | E13: 376.29075 | J13: 382.932 | P13: 326.0005 | T13: 292.434 | Y13: 275.723 | AA13: 277.7035
A14: ='Population Definitions'!$A$14 -> Prisoners_PWID_males | C14: Number | E14: 33079.378 | J14: 33663.204 | P14: 27786.749 | T14: 24925.698 | Y14: 23501.331 | AA14: 23670.14
A15: ='Population Definitions'!$A$15 -> Prisoners_PWID_females | C15: Number | E15: 1128.8723 | J15: 1148.796 | P15: 978.0015 | T15: 877.302 | Y15: 827.169 | AA15: 833.1105
A17: Number of live births | B17: Provenance | C17: Units | D17: Uncertainty | E17: Constant | G17: 2000 | H17: 2001 | I17: 2002 | J17: 2003 | K17: 2004 | L17: 2005 | M17: 2006 | N17: 2007 | O17: 2008 | P17: 2009 | Q17: 2010 | R17: 2011 | S17: 2012 | T17: 2013 | U17: 2014 | V17: 2015 | W17: 2016 | X17: 2017 | Y17: 2018 | Z17: 2019 | AA17: 2020 | AB17: 2021 | AC17: 2022 | AD17: 2023 | AE17: 2024 | AF17: 2025 | AG17: 2026 | AH17: 2027 | AI17: 2028 | AJ17: 2029 | AK17: 2030 | AL17: 2031 | AM17: 2032 | AN17: 2033 | AO17: 2034 | AP17: 2035 | AQ17: 2036 | AR17: 2037 | AS17: 2038 | AT17: 2039 | AU17: 2040 | AV17: 2041 | AW17: 2042 | AX17: 2043 | AY17: 2044 | AZ17: 2045 | BA17: 2046 | BB17: 2047 | BC17: 2048 | BD17: 2049 | BE17: 2050
A18: ='Population Definitions'!$A$2 -> PWID_males | C18: Number (per year) | E18: 0 | F18: OR
A19: ='Population Definitions'!$A$3 -> PWID_females | C19: Number (per year) | E19: 0 | F19: OR
A20: ='Population Definitions'!$A$4 -> 0-9_males | C20: Number (per year) | F20: OR | G20: 719808.76 | H20: 736844.19 | I20: 752034.46 | J20: 775262.57 | K20: 799902.01 | L20: 821585.31 | M20: 834896.44 | N20: 842062.92 | O20: 852853.65 | P20: 864952.7 | Q20: 878457.55 | R20: 888290.64 | S20: 914553.38 | T20: 950104.2 | U20: 978935.81 | V20: 992076.77 | W20: 1027223 | X20: 1061537 | Y20: 1087540.9 | Z20: 1107397.7 | AA20: 1127246.7 | AB20: 1148133.9 | AC20: 1170093.7 | AD20: 1191102.5 | AE20: 1211201.1 | AF20: 1228099.2 | AG20: 1248539.5 | AH20: 1266290.9 | AI20: 1283770.6 | AJ20: 1303302.8 | AK20: 1322353.7 | AL20: 1343751.9 | AM20: 1358786.9 | AN20: 1379193.9 | AO20: 1402625.1 | AP20: 1423019.1 | AQ20: 1441669 | AR20: 1457158.8 | AS20: 1480885.5 | AT20: 1500196.4 | AU20: 1519434.1 | AV20: 1534620.1 | AW20: 1557342.3 | AX20: 1576488.2 | AY20: 1596655 | AZ20: 1607747.8 | BA20: 1635037.1 | BB20: 1653776.3 | BC20: 1666334.1 | BD20: 1674945.5 | BE20: 1695039.1
A21: ='Population Definitions'!$A$5 -> 0-9_females | C21: Number (per year) | F21: OR | G21: 702938.24 | H21: 720277.81 | I21: 735126.54 | J21: 757832.43 | K21: 782682.99 | L21: 803113.69 | M21: 816125.56 | N21: 822327.08 | O21: 832052.35 | P21: 843856.3 | Q21: 856196.45 | R21: 865780.36 | S21: 890509.62 | T21: 925125.8 | U21: 952272.19 | V21: 965055.23 | W21: 998273.04 | X21: 1031620 | Y21: 1056891.1 | Z21: 1075143.3 | AA21: 1094414.3 | AB21: 1114693.1 | AC21: 1136013.3 | AD21: 1155288.5 | AE21: 1174782.9 | AF21: 1191172.8 | AG21: 1210998.5 | AH21: 1228216.1 | AI21: 1245170.4 | AJ21: 1264115.2 | AK21: 1282593.3 | AL21: 1303348.1 | AM21: 1317931.1 | AN21: 1336428.1 | AO21: 1359132.9 | AP21: 1380231.9 | AQ21: 1398321 | AR21: 1413345.2 | AS21: 1434966.5 | AT21: 1455088.6 | AU21: 1473747.9 | AV21: 1487034.9 | AW21: 1509052.7 | AX21: 1527604.8 | AY21: 1548647 | AZ21: 1559406.2 | BA21: 1585874.9 | BB21: 1604050.7 | BC21: 1616230.9 | BD21: 1624583.5 | BE21: 1644072.9
A22: ='Population Definitions'!$A$6 -> 10-17_males | C22: Number (per year) | E22: 0 | F22: OR
A23: ='Population Definitions'!$A$7 -> 10-17_females | C23: Number (per year) | E23: 0 | F23: OR
A24: ='Population Definitions'!$A$8 -> 18-64_males | C24: Number (per year) | E24: 0 | F24: OR
A25: ='Population Definitions'!$A$9 -> 18-64_females | C25: Number (per year) | E25: 0 | F25: OR
A26: ='Population Definitions'!$A$10 -> 65+_males | C26: Number (per year) | E26: 0 | F26: OR
A27: ='Population Definitions'!$A$11 -> 65+_females | C27: Number (per year) | E27: 0 | F27: OR
A28: ='Population Definitions'!$A$12 -> Prisoners_males | C28: Number (per year) | E28: 0 | F28: OR
A29: ='Population Definitions'!$A$13 -> Prisoners_females | C29: Number (per year) | E29: 0 | F29: OR
A30: ='Population Definitions'!$A$14 -> Prisoners_PWID_males | C30: Number (per year) | E30: 0 | F30: OR
A31: ='Population Definitions'!$A$15 -> Prisoners_PWID_females | C31: Number (per year) | E31: 0 | F31: OR
A33: Net migration rate | B33: Provenance | C33: Units | D33: Uncertainty | E33: Constant | G33: 2000 | H33: 2001 | I33: 2002 | J33: 2003 | K33: 2004 | L33: 2005 | M33: 2006 | N33: 2007 | O33: 2008 | P33: 2009 | Q33: 2010 | R33: 2011 | S33: 2012 | T33: 2013 | U33: 2014 | V33: 2015 | W33: 2016 | X33: 2017 | Y33: 2018 | Z33: 2019 | AA33: 2020 | AB33: 2021 | AC33: 2022 | AD33: 2023 | AE33: 2024 | AF33: 2025 | AG33: 2026 | AH33: 2027 | AI33: 2028 | AJ33: 2029 | AK33: 2030 | AL33: 2031 | AM33: 2032 | AN33: 2033 | AO33: 2034 | AP33: 2035 | AQ33: 2036 | AR33: 2037 | AS33: 2038 | AT33: 2039 | AU33: 2040 | AV33: 2041 | AW33: 2042 | AX33: 2043 | AY33: 2044 | AZ33: 2045 | BA33: 2046 | BB33: 2047 | BC33: 2048 | BD33: 2049 | BE33: 2050
A34: ='Population Definitions'!$A$2 -> PWID_males | C34: Rate (per year) | E34: 0 | F34: OR
A35: ='Population Definitions'!$A$3 -> PWID_females | C35: Rate (per year) | E35: 0 | F35: OR
A36: ='Population Definitions'!$A$4 -> 0-9_males | C36: Rate (per year) | F36: OR | G36: 0.0015999899 | H36: 0.0011225315 | I36: 0.0017217299 | J36: 0.0017540858 | K36: 0.0014652201 | L36: 0.00077473735 | M36: 0.00033585819 | N36: 0.00042355986 | O36: 4.8723104e-05 | P36: 0.00026519565 | Q36: 0.00047592681 | R36: 0.0016471748 | S36: 0.0023373428 | T36: 0.0018799466 | U36: 0.0012635222 | V36: 0.0028469303 | W36: 0.0025928688 | X36: 0.0017363245 | Y36: 0.0010296688 | Z36: 0.0010104302 | AA36: 0.0011331537 | AB36: 0.0011522741 | AC36: 0.0010223988 | AD36: 0.00082389446 | AE36: 0.00065687118 | AF36: 0.00082962541 | AG36: 0.00064146261 | AH36: 0.00061147973 | AI36: 0.00076389125 | AJ36: 0.00077439116 | AK36: 0.00087406637 | AL36: 0.0006309813 | AM36: 0.00078742459 | AN36: 0.00092434698 | AO36: 0.00080683573 | AP36: 0.00073017659 | AQ36: 0.00060263561 | AR36: 0.00087004163 | AS36: 0.00068343174 | AT36: 0.00064836055 | AU36: 0.00045421475 | AV36: 0.00070900349 | AW36: 0.00057799848 | AX36: 0.00061437036 | AY36: 0.0003685356 | AZ36: 0.00089959594 | BA36: 0.0005883043 | BB36: 0.00038390187 | BC36: 0.00021610029 | BD36: 0.00056231553 | BE36: 0.00041934664
A37: ='Population Definitions'!$A$5 -> 0-9_females | C37: Rate (per year) | F37: OR | G37: 0.0016304168 | H37: 0.0011038876 | I37: 0.0017637019 | J37: 0.001794751 | K37: 0.0013663924 | L37: 0.00073518902 | M37: 0.00018409734 | N37: 0.00030714816 | O37: 6.6979024e-06 | P37: 0.00015131898 | Q37: 0.00043733907 | R37: 0.0015432635 | S37: 0.0022921394 | T37: 0.0018180646 | U37: 0.0012830762 | V37: 0.0028000492 | W37: 0.0025713114 | X37: 0.0016524078 | Y37: 0.0009025129 | Z37: 0.0010140559 | AA37: 0.0011592275 | AB37: 0.0010740351 | AC37: 0.00095389466 | AD37: 0.00085837607 | AE37: 0.0006824635 | AF37: 0.00084149245 | AG37: 0.00063814306 | AH37: 0.00059493962 | AI37: 0.00072931674 | AJ37: 0.00074933709 | AK37: 0.00085588853 | AL37: 0.00059699771 | AM37: 0.00074140852 | AN37: 0.00097519395 | AO37: 0.00087056086 | AP37: 0.00069164311 | AQ37: 0.00057195672 | AR37: 0.00081977351 | AS37: 0.0007389482 | AT37: 0.00060513852 | AU37: 0.00039091687 | AV37: 0.00074714034 | AW37: 0.00061990366 | AX37: 0.00066160393 | AY37: 0.00032529335 | AZ37: 0.00086286925 | BA37: 0.00054562019 | BB37: 0.00034714422 | BC37: 0.00017671516 | BD37: 0.00051483137 | BE37: 0.00037725565
A38: ='Population Definitions'!$A$6 -> 10-17_males | C38: Rate (per year) | F38: OR | G38: -0.00087435698 | H38: -0.0015832073 | I38: -0.001548529 | J38: -0.0015763355 | K38: -0.0015514904 | L38: -0.0015292884 | M38: -0.0014710721 | N38: -0.0017698966 | O38: -0.0028444527 | P38: -0.002411443 | Q38: -0.0010672608 | R38: -0.00066433275 | S38: -0.00021036591 | T38: -6.3519408e-05 | U38: 0.0008666347 | V38: 0.0016404877 | W38: 0.0012240833 | X38: 0.00031302585 | Y38: -0.00044817901 | Z38: -0.00029695971 | AA38: -7.02998e-05 | AB38: -0.0001432402 | AC38: -0.00024240334 | AD38: -0.00023249003 | AE38: -0.00016557108 | AF38: -0.00015277414 | AG38: -0.00019323702 | AH38: -0.00020598429 | AI38: -0.00016216505 | AJ38: -0.0001262882 | AK38: -0.00010863364 | AL38: -9.2586021e-05 | AM38: -0.00010968309 | AN38: -7.6759945e-05 | AO38: -7.6120688e-05 | AP38: -8.7990765e-05 | AQ38: -8.2601438e-05 | AR38: -9.0445073e-05 | AS38: -9.6297335e-05 | AT38: -0.00012307066 | AU38: -0.00013869096 | AV38: -0.00012405528 | AW38: -0.00012099674 | AX38: -0.00012866545 | AY38: -9.8767376e-05 | AZ38: -9.8214578e-05 | BA38: -0.00011315645 | BB38: -0.00010708164 | BC38: -0.00013015068 | BD38: -0.00014252035 | BE38: -0.00014595621
A39: ='Population Definitions'!$A$7 -> 10-17_females | C39: Rate (per year) | F39: OR | G39: -0.00049439899 | H39: -0.00093453291 | I39: -0.00091158857 | J39: -0.00093531022 | K39: -0.00092467251 | L39: -0.00091151829 | M39: -0.00088643554 | N39: -0.0010727866 | O39: -0.001726468 | P39: -0.0014701015 | Q39: -0.00064663272 | R39: -0.00039084339 | S39: -0.00011976769 | T39: -2.5300416e-05 | U39: 0.00054651747 | V39: 0.0010110704 | W39: 0.00075808115 | X39: 0.00018632181 | Y39: -0.00027785583 | Z39: -0.00018009347 | AA39: -3.646721e-05 | AB39: -0.00010222009 | AC39: -0.00015503867 | AD39: -0.0001941002 | AE39: -0.0001825333 | AF39: -0.00016823271 | AG39: -0.00020861909 | AH39: -0.00022157681 | AI39: -0.00017629153 | AJ39: -0.00013958089 | AK39: -0.00012197798 | AL39: -0.00010649258 | AM39: -0.00012371031 | AN39: -9.0315811e-05 | AO39: -9.0029063e-05 | AP39: -0.00010339913 | AQ39: -9.6967391e-05 | AR39: -0.00010612767 | AS39: -0.00011176884 | AT39: -0.00013919105 | AU39: -0.000155904 | AV39: -0.00014038853 | AW39: -0.00013750614 | AX39: -0.00014496832 | AY39: -0.00011525537 | AZ39: -0.00011411217 | BA39: -0.00012998746 | BB39: -0.00012360067 | BC39: -0.00014675986 | BD39: -0.00015970057 | BE39: -0.0001631333
A40: ='Population Definitions'!$A$8 -> 18-64_males | C40: Rate (per year) | F40: OR | G40: -0.0050202126 | H40: -0.0087715396 | I40: -0.0085616912 | J40: -0.0086554445 | K40: -0.0084938715 | L40: -0.0083583035 | M40: -0.0081053713 | N40: -0.009684229 | O40: -0.015428818 | P40: -0.013276561 | Q40: -0.0060144634 | R40: -0.0037554829 | S40: -0.0013025634 | T40: -0.00053437383 | U40: 0.0047116905 | V40: 0.0087832887 | W40: 0.0064522093 | X40: 0.001444874 | Y40: -0.0026020504 | Z40: -0.0016184772 | AA40: -0.00081438965 | AB40: -0.0007867138 | AC40: -0.0015601089 | AD40: -0.0010982963 | AE40: -0.00048795981 | AF40: -0.00042145378 | AG40: -0.00056200613 | AH40: -0.00060239877 | AI40: -0.00042394006 | AJ40: -0.00027831288 | AK40: -0.000210684 | AL40: -0.00015174421 | AM40: -0.00020574935 | AN40: -7.6449643e-05 | AO40: -7.3408883e-05 | AP40: -0.00011690486 | AQ40: -8.6586022e-05 | AR40: -0.00011290414 | AS40: -0.00012490137 | AT40: -0.00021481877 | AU40: -0.00026476323 | AV40: -0.0002079702 | AW40: -0.00018976346 | AX40: -0.00020986249 | AY40: -0.00010472379 | AZ40: -9.6531078e-05 | BA40: -0.00014005516 | BB40: -0.00011424552 | BC40: -0.00017941936 | BD40: -0.00021179123 | BE40: -0.00021393475
A41: ='Population Definitions'!$A$9 -> 18-64_females | C41: Rate (per year) | F41: OR | G41: -0.0023832932 | H41: -0.0042593806 | I41: -0.004077506 | J41: -0.0041232588 | K41: -0.0040483705 | L41: -0.0039100846 | M41: -0.0038156339 | N41: -0.004575626 | O41: -0.0073413069 | P41: -0.0061694175 | Q41: -0.0027966513 | R41: -0.0016414107 | S41: -0.00055862969 | T41: -9.5282238e-05 | U41: 0.002298528 | V41: 0.0042385883 | W41: 0.0031994343 | X41: 0.00079978769 | Y41: -0.0011365775 | Z41: -0.00063326285 | AA41: -0.00046157621 | AB41: -0.00042374618 | AC41: -0.00073468336 | AD41: -0.00065931432 | AE41: -0.00042390319 | AF41: -0.00036324556 | AG41: -0.00050593199 | AH41: -0.00055020178 | AI41: -0.00038081466 | AJ41: -0.00024486831 | AK41: -0.00018354914 | AL41: -0.00012890738 | AM41: -0.00018618684 | AN41: -6.1455985e-05 | AO41: -6.0623636e-05 | AP41: -0.00010372745 | AQ41: -7.5570758e-05 | AR41: -9.9538649e-05 | AS41: -0.00011117336 | AT41: -0.00019707381 | AU41: -0.00024546738 | AV41: -0.00018827707 | AW41: -0.00016944298 | AX41: -0.00018809843 | AY41: -8.595074e-05 | AZ41: -7.8806452e-05 | BA41: -0.00012292278 | BB41: -9.8491459e-05 | BC41: -0.00016391913 | BD41: -0.00019772353 | BE41: -0.0002013464
A42: ='Population Definitions'!$A$10 -> 65+_males | C42: Rate (per year) | F42: OR | G42: -0.002963526 | H42: -0.0031185434 | I42: -0.0030770739 | J42: -0.0031236831 | K42: -0.0031579482 | L42: -0.0032374482 | M42: -0.0032601962 | N42: -0.0033534437 | O42: -0.0036468952 | P42: -0.003715262 | Q42: -0.0033180147 | R42: -0.0032112311 | S42: -0.0030379293 | T42: -0.0027420924 | U42: -0.0022394721 | V42: -0.0025502163 | W42: -0.0024126259 | X42: -0.0025766733 | Y42: -0.0025816469 | Z42: -0.003079213 | AA42: -0.0028814734 | AB42: -0.00043777524 | AC42: -0.0025572608 | AD42: -0.0025657716 | AE42: -0.0025497422 | AF42: -0.0024535403 | AG42: -0.0026375675 | AH42: -0.0027173512 | AI42: -0.0026672535 | AJ42: -0.0026145787 | AK42: -0.0026603801 | AL42: -0.0027633974 | AM42: -0.0029090147 | AN42: -0.0028882293 | AO42: -0.0029374838 | AP42: -0.0030540595 | AQ42: -0.0030157579 | AR42: -0.0030952714 | AS42: -0.0030444802 | AT42: -0.0031248796 | AU42: -0.0031133627 | AV42: -0.0029983271 | AW42: -0.0029272137 | AX42: -0.0029292438 | AY42: -0.0028067183 | AZ42: -0.0027617072 | BA42: -0.00279051 | BB42: -0.0027600309 | BC42: -0.0027717529 | BD42: -0.0027568623 | BE42: -0.0026611089
...

Sheet Infectiousness
A1: Force of Infection constant | B1: Provenance | C1: Units | D1: Uncertainty | E1: Constant | G1: 2000 | H1: 2001 | I1: 2002 | J1: 2003 | K1: 2004 | L1: 2005 | M1: 2006 | N1: 2007 | O1: 2008 | P1: 2009 | Q1: 2010 | R1: 2011 | S1: 2012 | T1: 2013 | U1: 2014 | V1: 2015 | W1: 2016 | X1: 2017 | Y1: 2018 | Z1: 2019 | AA1: 2020 | AB1: 2021 | AC1: 2022 | AD1: 2023 | AE1: 2024 | AF1: 2025 | AG1: 2026 | AH1: 2027 | AI1: 2028 | AJ1: 2029 | AK1: 2030 | AL1: 2031 | AM1: 2032 | AN1: 2033 | AO1: 2034 | AP1: 2035 | AQ1: 2036 | AR1: 2037 | AS1: 2038 | AT1: 2039 | AU1: 2040 | AV1: 2041 | AW1: 2042 | AX1: 2043 | AY1: 2044 | AZ1: 2045 | BA1: 2046 | BB1: 2047 | BC1: 2048 | BD1: 2049 | BE1: 2050
A2: ='Population Definitions'!$A$2 -> PWID_males | C2: N.A. | E2: 0.1 | F2: OR
A3: ='Population Definitions'!$A$3 -> PWID_females | C3: N.A. | E3: 0.1 | F3: OR
A4: ='Population Definitions'!$A$4 -> 0-9_males | C4: N.A. | E4: 0 | F4: OR
A5: ='Population Definitions'!$A$5 -> 0-9_females | C5: N.A. | E5: 0 | F5: OR
A6: ='Population Definitions'!$A$6 -> 10-17_males | C6: N.A. | E6: 0 | F6: OR
A7: ='Population Definitions'!$A$7 -> 10-17_females | C7: N.A. | E7: 0 | F7: OR
A8: ='Population Definitions'!$A$8 -> 18-64_males | C8: N.A. | E8: 0 | F8: OR
A9: ='Population Definitions'!$A$9 -> 18-64_females | C9: N.A. | E9: 0 | F9: OR
A10: ='Population Definitions'!$A$10 -> 65+_males | C10: N.A. | E10: 0 | F10: OR
A11: ='Population Definitions'!$A$11 -> 65+_females | C11: N.A. | E11: 0 | F11: OR
A12: ='Population Definitions'!$A$12 -> Prisoners_males | C12: N.A. | E12: 0 | F12: OR
A13: ='Population Definitions'!$A$13 -> Prisoners_females | C13: N.A. | E13: 0 | F13: OR
A14: ='Population Definitions'!$A$14 -> Prisoners_PWID_males | C14: N.A. | E14: 0.1 | F14: OR
A15: ='Population Definitions'!$A$15 -> Prisoners_PWID_females | C15: N.A. | E15: 0.1 | F15: OR
A17: Infectivity among the general population | B17: Provenance | C17: Units | D17: Uncertainty | E17: Constant | G17: 2000 | H17: 2001 | I17: 2002 | J17: 2003 | K17: 2004 | L17: 2005 | M17: 2006 | N17: 2007 | O17: 2008 | P17: 2009 | Q17: 2010 | R17: 2011 | S17: 2012 | T17: 2013 | U17: 2014 | V17: 2015 | W17: 2016 | X17: 2017 | Y17: 2018 | Z17: 2019 | AA17: 2020 | AB17: 2021 | AC17: 2022 | AD17: 2023 | AE17: 2024 | AF17: 2025 | AG17: 2026 | AH17: 2027 | AI17: 2028 | AJ17: 2029 | AK17: 2030 | AL17: 2031 | AM17: 2032 | AN17: 2033 | AO17: 2034 | AP17: 2035 | AQ17: 2036 | AR17: 2037 | AS17: 2038 | AT17: 2039 | AU17: 2040 | AV17: 2041 | AW17: 2042 | AX17: 2043 | AY17: 2044 | AZ17: 2045 | BA17: 2046 | BB17: 2047 | BC17: 2048 | BD17: 2049 | BE17: 2050
A18: ='Population Definitions'!$A$2 -> PWID_males | C18: N.A. | E18: 0 | F18: OR
A19: ='Population Definitions'!$A$3 -> PWID_females | C19: N.A. | E19: 0 | F19: OR
A20: ='Population Definitions'!$A$4 -> 0-9_males | C20: N.A. | E20: 0 | F20: OR
A21: ='Population Definitions'!$A$5 -> 0-9_females | C21: N.A. | E21: 0 | F21: OR
A22: ='Population Definitions'!$A$6 -> 10-17_males | C22: N.A. | E22: 0 | F22: OR
A23: ='Population Definitions'!$A$7 -> 10-17_females | C23: N.A. | E23: 0 | F23: OR
A24: ='Population Definitions'!$A$8 -> 18-64_males | C24: N.A. | E24: 0.1 | F24: OR
A25: ='Population Definitions'!$A$9 -> 18-64_females | C25: N.A. | E25: 0.1 | F25: OR
A26: ='Population Definitions'!$A$10 -> 65+_males | C26: N.A. | E26: 0.1 | F26: OR
A27: ='Population Definitions'!$A$11 -> 65+_females | C27: N.A. | E27: 0.1 | F27: OR
A28: ='Population Definitions'!$A$12 -> Prisoners_males | C28: N.A. | E28: 0 | F28: OR
A29: ='Population Definitions'!$A$13 -> Prisoners_females | C29: N.A. | E29: 0 | F29: OR
A30: ='Population Definitions'!$A$14 -> Prisoners_PWID_males | C30: N.A. | E30: 0 | F30: OR
A31: ='Population Definitions'!$A$15 -> Prisoners_PWID_females | C31: N.A. | E31: 0 | F31: OR

Sheet Disease Progression
A1: Proportion of HCV infections spontaneously clearing | B1: Provenance | C1: Units | D1: Uncertainty | E1: Constant | G1: 2000 | H1: 2001 | I1: 2002 | J1: 2003 | K1: 2004 | L1: 2005 | M1: 2006 | N1: 2007 | O1: 2008 | P1: 2009 | Q1: 2010 | R1: 2011 | S1: 2012 | T1: 2013 | U1: 2014 | V1: 2015 | W1: 2016 | X1: 2017 | Y1: 2018 | Z1: 2019 | AA1: 2020 | AB1: 2021 | AC1: 2022 | AD1: 2023 | AE1: 2024 | AF1: 2025 | AG1: 2026 | AH1: 2027 | AI1: 2028 | AJ1: 2029 | AK1: 2030 | AL1: 2031 | AM1: 2032 | AN1: 2033 | AO1: 2034 | AP1: 2035 | AQ1: 2036 | AR1: 2037 | AS1: 2038 | AT1: 2039 | AU1: 2040 | AV1: 2041 | AW1: 2042 | AX1: 2043 | AY1: 2044 | AZ1: 2045 | BA1: 2046 | BB1: 2047 | BC1: 2048 | BD1: 2049 | BE1: 2050
A2: ='Population Definitions'!$A$2 -> PWID_males | C2: Proportion | D2: 0.028061224 | E2: 0.19889503 | F2: OR
A3: ='Population Definitions'!$A$3 -> PWID_females | C3: Proportion | D3: 0.033163265 | E3: 0.42105263 | F3: OR
A4: ='Population Definitions'!$A$4 -> 0-9_males | C4: Proportion | D4: 0.028061224 | E4: 0.19889503 | F4: OR
A5: ='Population Definitions'!$A$5 -> 0-9_females | C5: Proportion | D5: 0.033163265 | E5: 0.42105263 | F5: OR
A6: ='Population Definitions'!$A$6 -> 10-17_males | C6: Proportion | D6: 0.028061224 | E6: 0.19889503 | F6: OR
A7: ='Population Definitions'!$A$7 -> 10-17_females | C7: Proportion | D7: 0.033163265 | E7: 0.42105263 | F7: OR
A8: ='Population Definitions'!$A$8 -> 18-64_males | C8: Proportion | D8: 0.028061224 | E8: 0.19889503 | F8: OR
A9: ='Population Definitions'!$A$9 -> 18-64_females | C9: Proportion | D9: 0.033163265 | E9: 0.42105263 | F9: OR
A10: ='Population Definitions'!$A$10 -> 65+_males | C10: Proportion | D10: 0.028061224 | E10: 0.19889503 | F10: OR
A11: ='Population Definitions'!$A$11 -> 65+_females | C11: Proportion | D11: 0.033163265 | E11: 0.42105263 | F11: OR
A12: ='Population Definitions'!$A$12 -> Prisoners_males | C12: Proportion | D12: 0.028061224 | E12: 0.19889503 | F12: OR
A13: ='Population Definitions'!$A$13 -> Prisoners_females | C13: Proportion | D13: 0.033163265 | E13: 0.42105263 | F13: OR
A14: ='Population Definitions'!$A$14 -> Prisoners_PWID_males | C14: Proportion | D14: 0.028061224 | E14: 0.19889503 | F14: OR
A15: ='Population Definitions'!$A$15 -> Prisoners_PWID_females | C15: Proportion | D15: 0.033163265 | E15: 0.42105263 | F15: OR
A17: Average duration for spontaneous viral clearance | B17: Provenance | C17: Units | D17: Uncertainty | E17: Constant | G17: 2000 | H17: 2001 | I17: 2002 | J17: 2003 | K17: 2004 | L17: 2005 | M17: 2006 | N17: 2007 | O17: 2008 | P17: 2009 | Q17: 2010 | R17: 2011 | S17: 2012 | T17: 2013 | U17: 2014 | V17: 2015 | W17: 2016 | X17: 2017 | Y17: 2018 | Z17: 2019 | AA17: 2020 | AB17: 2021 | AC17: 2022 | AD17: 2023 | AE17: 2024 | AF17: 2025 | AG17: 2026 | AH17: 2027 | AI17: 2028 | AJ17: 2029 | AK17: 2030 | AL17: 2031 | AM17: 2032 | AN17: 2033 | AO17: 2034 | AP17: 2035 | AQ17: 2036 | AR17: 2037 | AS17: 2038 | AT17: 2039 | AU17: 2040 | AV17: 2041 | AW17: 2042 | AX17: 2043 | AY17: 2044 | AZ17: 2045 | BA17: 2046 | BB17: 2047 | BC17: 2048 | BD17: 2049 | BE17: 2050
A18: ='Population Definitions'!$A$2 -> PWID_males | B18: Framework-supplied default | C18: Duration (years) | E18: 1 | F18: OR
A19: ='Population Definitions'!$A$3 -> PWID_females | B19: Framework-supplied default | C19: Duration (years) | E19: 1 | F19: OR
A20: ='Population Definitions'!$A$4 -> 0-9_males | B20: Framework-supplied default | C20: Duration (years) | E20: 1 | F20: OR
A21: ='Population Definitions'!$A$5 -> 0-9_females | B21: Framework-supplied default | C21: Duration (years) | E21: 1 | F21: OR
A22: ='Population Definitions'!$A$6 -> 10-17_males | B22: Framework-supplied default | C22: Duration (years) | E22: 1 | F22: OR
A23: ='Population Definitions'!$A$7 -> 10-17_females | B23: Framework-supplied default | C23: Duration (years) | E23: 1 | F23: OR
A24: ='Population Definitions'!$A$8 -> 18-64_males | B24: Framework-supplied default | C24: Duration (years) | E24: 1 | F24: OR
A25: ='Population Definitions'!$A$9 -> 18-64_females | B25: Framework-supplied default | C25: Duration (years) | E25: 1 | F25: OR
A26: ='Population Definitions'!$A$10 -> 65+_males | B26: Framework-supplied default | C26: Duration (years) | E26: 1 | F26: OR
A27: ='Population Definitions'!$A$11 -> 65+_females | B27: Framework-supplied default | C27: Duration (years) | E27: 1 | F27: OR
A28: ='Population Definitions'!$A$12 -> Prisoners_males | B28: Framework-supplied default | C28: Duration (years) | E28: 1 | F28: OR
A29: ='Population Definitions'!$A$13 -> Prisoners_females | B29: Framework-supplied default | C29: Duration (years) | E29: 1 | F29: OR
A30: ='Population Definitions'!$A$14 -> Prisoners_PWID_males | B30: Framework-supplied default | C30: Duration (years) | E30: 1 | F30: OR
A31: ='Population Definitions'!$A$15 -> Prisoners_PWID_females | B31: Framework-supplied default | C31: Duration (years) | E31: 1 | F31: OR
A33: F0 to F1 progression rate (intermediate step) | B33: Provenance | C33: Units | D33: Uncertainty | E33: Constant | G33: 2000 | H33: 2001 | I33: 2002 | J33: 2003 | K33: 2004 | L33: 2005 | M33: 2006 | N33: 2007 | O33: 2008 | P33: 2009 | Q33: 2010 | R33: 2011 | S33: 2012 | T33: 2013 | U33: 2014 | V33: 2015 | W33: 2016 | X33: 2017 | Y33: 2018 | Z33: 2019 | AA33: 2020 | AB33: 2021 | AC33: 2022 | AD33: 2023 | AE33: 2024 | AF33: 2025 | AG33: 2026 | AH33: 2027 | AI33: 2028 | AJ33: 2029 | AK33: 2030 | AL33: 2031 | AM33: 2032 | AN33: 2033 | AO33: 2034 | AP33: 2035 | AQ33: 2036 | AR33: 2037 | AS33: 2038 | AT33: 2039 | AU33: 2040 | AV33: 2041 | AW33: 2042 | AX33: 2043 | AY33: 2044 | AZ33: 2045 | BA33: 2046 | BB33: 2047 | BC33: 2048 | BD33: 2049 | BE33: 2050
A34: ='Population Definitions'!$A$2 -> PWID_males | C34: Rate (per year) | D34: 0.094387755 | E34: 0.25 | F34: OR
A35: ='Population Definitions'!$A$3 -> PWID_females | C35: Rate (per year) | D35: 0.094387755 | E35: 0.25 | F35: OR
A36: ='Population Definitions'!$A$4 -> 0-9_males | C36: Rate (per year) | D36: 0.094387755 | E36: 0.25 | F36: OR
A37: ='Population Definitions'!$A$5 -> 0-9_females | C37: Rate (per year) | D37: 0.094387755 | E37: 0.25 | F37: OR
A38: ='Population Definitions'!$A$6 -> 10-17_males | C38: Rate (per year) | D38: 0.094387755 | E38: 0.25 | F38: OR
A39: ='Population Definitions'!$A$7 -> 10-17_females | C39: Rate (per year) | D39: 0.094387755 | E39: 0.25 | F39: OR
A40: ='Population Definitions'!$A$8 -> 18-64_males | C40: Rate (per year) | D40: 0.094387755 | E40: 0.25 | F40: OR
A41: ='Population Definitions'!$A$9 -> 18-64_females | C41: Rate (per year) | D41: 0.094387755 | E41: 0.25 | F41: OR
A42: ='Population Definitions'!$A$10 -> 65+_males | C42: Rate (per year) | D42: 0.094387755 | E42: 0.25 | F42: OR
...

Sheet Diagnosis
A1: Antibody testing rate in F0-F2, undiagnosed, in care (intermediate step) | B1: Provenance | C1: Units | D1: Uncertainty | E1: Constant | G1: 2000 | H1: 2001 | I1: 2002 | J1: 2003 | K1: 2004 | L1: 2005 | M1: 2006 | N1: 2007 | O1: 2008 | P1: 2009 | Q1: 2010 | R1: 2011 | S1: 2012 | T1: 2013 | U1: 2014 | V1: 2015 | W1: 2016 | X1: 2017 | Y1: 2018 | Z1: 2019 | AA1: 2020 | AB1: 2021 | AC1: 2022 | AD1: 2023 | AE1: 2024 | AF1: 2025 | AG1: 2026 | AH1: 2027 | AI1: 2028 | AJ1: 2029 | AK1: 2030 | AL1: 2031 | AM1: 2032 | AN1: 2033 | AO1: 2034 | AP1: 2035 | AQ1: 2036 | AR1: 2037 | AS1: 2038 | AT1: 2039 | AU1: 2040 | AV1: 2041 | AW1: 2042 | AX1: 2043 | AY1: 2044 | AZ1: 2045 | BA1: 2046 | BB1: 2047 | BC1: 2048 | BD1: 2049 | BE1: 2050
A2: ='Population Definitions'!$A$2 -> PWID_males | C2: Rate (per year) | D2: 0.025765306 | F2: OR | G2: 0.00475 | R2: 0.0095
A3: ='Population Definitions'!$A$3 -> PWID_females | C3: Rate (per year) | D3: 0.025765306 | F3: OR | G3: 0.00475 | R3: 0.0095
A4: ='Population Definitions'!$A$4 -> 0-9_males | C4: Rate (per year) | E4: 0.01 | F4: OR
A5: ='Population Definitions'!$A$5 -> 0-9_females | C5: Rate (per year) | E5: 0.01 | F5: OR
A6: ='Population Definitions'!$A$6 -> 10-17_males | C6: Rate (per year) | E6: 0.01 | F6: OR
A7: ='Population Definitions'!$A$7 -> 10-17_females | C7: Rate (per year) | E7: 0.01 | F7: OR
A8: ='Population Definitions'!$A$8 -> 18-64_males | C8: Rate (per year) | E8: 0.05 | F8: OR
A9: ='Population Definitions'!$A$9 -> 18-64_females | C9: Rate (per year) | E9: 0.05 | F9: OR
A10: ='Population Definitions'!$A$10 -> 65+_males | C10: Rate (per year) | E10: 0.05 | F10: OR
A11: ='Population Definitions'!$A$11 -> 65+_females | C11: Rate (per year) | E11: 0.05 | F11: OR
A12: ='Population Definitions'!$A$12 -> Prisoners_males | C12: Rate (per year) | F12: OR | G12: 0.00475 | R12: 0.0095
A13: ='Population Definitions'!$A$13 -> Prisoners_females | C13: Rate (per year) | F13: OR | G13: 0.00475 | R13: 0.0095
A14: ='Population Definitions'!$A$14 -> Prisoners_PWID_males | C14: Rate (per year) | F14: OR | G14: 0.00475 | R14: 0.0095
A15: ='Population Definitions'!$A$15 -> Prisoners_PWID_females | C15: Rate (per year) | F15: OR | G15: 0.00475 | R15: 0.0095
A17: Antibody testing rate in F3+, undiagnosed, in care (intermediate step) | B17: Provenance | C17: Units | D17: Uncertainty | E17: Constant | G17: 2000 | H17: 2001 | I17: 2002 | J17: 2003 | K17: 2004 | L17: 2005 | M17: 2006 | N17: 2007 | O17: 2008 | P17: 2009 | Q17: 2010 | R17: 2011 | S17: 2012 | T17: 2013 | U17: 2014 | V17: 2015 | W17: 2016 | X17: 2017 | Y17: 2018 | Z17: 2019 | AA17: 2020 | AB17: 2021 | AC17: 2022 | AD17: 2023 | AE17: 2024 | AF17: 2025 | AG17: 2026 | AH17: 2027 | AI17: 2028 | AJ17: 2029 | AK17: 2030 | AL17: 2031 | AM17: 2032 | AN17: 2033 | AO17: 2034 | AP17: 2035 | AQ17: 2036 | AR17: 2037 | AS17: 2038 | AT17: 2039 | AU17: 2040 | AV17: 2041 | AW17: 2042 | AX17: 2043 | AY17: 2044 | AZ17: 2045 | BA17: 2046 | BB17: 2047 | BC17: 2048 | BD17: 2049 | BE17: 2050
A18: ='Population Definitions'!$A$2 -> PWID_males | C18: Rate (per year) | D18: 0.025765306 | F18: OR | G18: 0.00475 | R18: 0.0095
A19: ='Population Definitions'!$A$3 -> PWID_females | C19: Rate (per year) | D19: 0.025765306 | F19: OR | G19: 0.00475 | R19: 0.0095
A20: ='Population Definitions'!$A$4 -> 0-9_males | C20: Rate (per year) | E20: 0.01 | F20: OR
A21: ='Population Definitions'!$A$5 -> 0-9_females | C21: Rate (per year) | E21: 0.01 | F21: OR
A22: ='Population Definitions'!$A$6 -> 10-17_males | C22: Rate (per year) | E22: 0.01 | F22: OR
A23: ='Population Definitions'!$A$7 -> 10-17_females | C23: Rate (per year) | E23: 0.01 | F23: OR
A24: ='Population Definitions'!$A$8 -> 18-64_males | C24: Rate (per year) | E24: 0.05 | F24: OR
A25: ='Population Definitions'!$A$9 -> 18-64_females | C25: Rate (per year) | E25: 0.05 | F25: OR
A26: ='Population Definitions'!$A$10 -> 65+_males | C26: Rate (per year) | E26: 0.05 | F26: OR
A27: ='Population Definitions'!$A$11 -> 65+_females | C27: Rate (per year) | E27: 0.05 | F27: OR
A28: ='Population Definitions'!$A$12 -> Prisoners_males | C28: Rate (per year) | F28: OR | G28: 0.00475 | R28: 0.0095
A29: ='Population Definitions'!$A$13 -> Prisoners_females | C29: Rate (per year) | F29: OR | G29: 0.00475 | R29: 0.0095
A30: ='Population Definitions'!$A$14 -> Prisoners_PWID_males | C30: Rate (per year) | F30: OR | G30: 0.00475 | R30: 0.0095
A31: ='Population Definitions'!$A$15 -> Prisoners_PWID_females | C31: Rate (per year) | F31: OR | G31: 0.00475 | R31: 0.0095
A33: RNA testing rate in F0-F2, Ab diagnosed, in care (intermediate step) | B33: Provenance | C33: Units | D33: Uncertainty | E33: Constant | G33: 2000 | H33: 2001 | I33: 2002 | J33: 2003 | K33: 2004 | L33: 2005 | M33: 2006 | N33: 2007 | O33: 2008 | P33: 2009 | Q33: 2010 | R33: 2011 | S33: 2012 | T33: 2013 | U33: 2014 | V33: 2015 | W33: 2016 | X33: 2017 | Y33: 2018 | Z33: 2019 | AA33: 2020 | AB33: 2021 | AC33: 2022 | AD33: 2023 | AE33: 2024 | AF33: 2025 | AG33: 2026 | AH33: 2027 | AI33: 2028 | AJ33: 2029 | AK33: 2030 | AL33: 2031 | AM33: 2032 | AN33: 2033 | AO33: 2034 | AP33: 2035 | AQ33: 2036 | AR33: 2037 | AS33: 2038 | AT33: 2039 | AU33: 2040 | AV33: 2041 | AW33: 2042 | AX33: 2043 | AY33: 2044 | AZ33: 2045 | BA33: 2046 | BB33: 2047 | BC33: 2048 | BD33: 2049 | BE33: 2050
A34: ='Population Definitions'!$A$2 -> PWID_males | C34: Rate (per year) | E34: 0.4 | F34: OR
A35: ='Population Definitions'!$A$3 -> PWID_females | C35: Rate (per year) | E35: 0.4 | F35: OR
A36: ='Population Definitions'!$A$4 -> 0-9_males | C36: Rate (per year) | E36: 0.4 | F36: OR
A37: ='Population Definitions'!$A$5 -> 0-9_females | C37: Rate (per year) | E37: 0.4 | F37: OR
A38: ='Population Definitions'!$A$6 -> 10-17_males | C38: Rate (per year) | E38: 0.4 | F38: OR
A39: ='Population Definitions'!$A$7 -> 10-17_females | C39: Rate (per year) | E39: 0.4 | F39: OR
A40: ='Population Definitions'!$A$8 -> 18-64_males | C40: Rate (per year) | E40: 0.4 | F40: OR
A41: ='Population Definitions'!$A$9 -> 18-64_females | C41: Rate (per year) | E41: 0.4 | F41: OR
A42: ='Population Definitions'!$A$10 -> 65+_males | C42: Rate (per year) | E42: 0.4 | F42: OR
...

Sheet Loss to follow-up
A1: Loss to follow-up rate on antibody test in F0-F2 | B1: Provenance | C1: Units | D1: Uncertainty | E1: Constant | G1: 2000 | H1: 2001 | I1: 2002 | J1: 2003 | K1: 2004 | L1: 2005 | M1: 2006 | N1: 2007 | O1: 2008 | P1: 2009 | Q1: 2010 | R1: 2011 | S1: 2012 | T1: 2013 | U1: 2014 | V1: 2015 | W1: 2016 | X1: 2017 | Y1: 2018 | Z1: 2019 | AA1: 2020 | AB1: 2021 | AC1: 2022 | AD1: 2023 | AE1: 2024 | AF1: 2025 | AG1: 2026 | AH1: 2027 | AI1: 2028 | AJ1: 2029 | AK1: 2030 | AL1: 2031 | AM1: 2032 | AN1: 2033 | AO1: 2034 | AP1: 2035 | AQ1: 2036 | AR1: 2037 | AS1: 2038 | AT1: 2039 | AU1: 2040 | AV1: 2041 | AW1: 2042 | AX1: 2043 | AY1: 2044 | AZ1: 2045 | BA1: 2046 | BB1: 2047 | BC1: 2048 | BD1: 2049 | BE1: 2050
A2: ='Population Definitions'!$A$2 -> PWID_males | B2: Framework-supplied default | C2: Proportion | E2: 0 | F2: OR
A3: ='Population Definitions'!$A$3 -> PWID_females | B3: Framework-supplied default | C3: Proportion | E3: 0 | F3: OR
A4: ='Population Definitions'!$A$4 -> 0-9_males | B4: Framework-supplied default | C4: Proportion | E4: 0 | F4: OR
A5: ='Population Definitions'!$A$5 -> 0-9_females | B5: Framework-supplied default | C5: Proportion | E5: 0 | F5: OR
A6: ='Population Definitions'!$A$6 -> 10-17_males | B6: Framework-supplied default | C6: Proportion | E6: 0 | F6: OR
A7: ='Population Definitions'!$A$7 -> 10-17_females | B7: Framework-supplied default | C7: Proportion | E7: 0 | F7: OR
A8: ='Population Definitions'!$A$8 -> 18-64_males | B8: Framework-supplied default | C8: Proportion | E8: 0 | F8: OR
A9: ='Population Definitions'!$A$9 -> 18-64_females | B9: Framework-supplied default | C9: Proportion | E9: 0 | F9: OR
A10: ='Population Definitions'!$A$10 -> 65+_males | B10: Framework-supplied default | C10: Proportion | E10: 0 | F10: OR
A11: ='Population Definitions'!$A$11 -> 65+_females | B11: Framework-supplied default | C11: Proportion | E11: 0 | F11: OR
A12: ='Population Definitions'!$A$12 -> Prisoners_males | B12: Framework-supplied default | C12: Proportion | E12: 0 | F12: OR
A13: ='Population Definitions'!$A$13 -> Prisoners_females | B13: Framework-supplied default | C13: Proportion | E13: 0 | F13: OR
A14: ='Population Definitions'!$A$14 -> Prisoners_PWID_males | B14: Framework-supplied default | C14: Proportion | E14: 0 | F14: OR
A15: ='Population Definitions'!$A$15 -> Prisoners_PWID_females | B15: Framework-supplied default | C15: Proportion | E15: 0 | F15: OR
A17: Loss to follow-up rate on antibody test in F3+ | B17: Provenance | C17: Units | D17: Uncertainty | E17: Constant | G17: 2000 | H17: 2001 | I17: 2002 | J17: 2003 | K17: 2004 | L17: 2005 | M17: 2006 | N17: 2007 | O17: 2008 | P17: 2009 | Q17: 2010 | R17: 2011 | S17: 2012 | T17: 2013 | U17: 2014 | V17: 2015 | W17: 2016 | X17: 2017 | Y17: 2018 | Z17: 2019 | AA17: 2020 | AB17: 2021 | AC17: 2022 | AD17: 2023 | AE17: 2024 | AF17: 2025 | AG17: 2026 | AH17: 2027 | AI17: 2028 | AJ17: 2029 | AK17: 2030 | AL17: 2031 | AM17: 2032 | AN17: 2033 | AO17: 2034 | AP17: 2035 | AQ17: 2036 | AR17: 2037 | AS17: 2038 | AT17: 2039 | AU17: 2040 | AV17: 2041 | AW17: 2042 | AX17: 2043 | AY17: 2044 | AZ17: 2045 | BA17: 2046 | BB17: 2047 | BC17: 2048 | BD17: 2049 | BE17: 2050
A18: ='Population Definitions'!$A$2 -> PWID_males | B18: Framework-supplied default | C18: Proportion | E18: 0 | F18: OR
A19: ='Population Definitions'!$A$3 -> PWID_females | B19: Framework-supplied default | C19: Proportion | E19: 0 | F19: OR
A20: ='Population Definitions'!$A$4 -> 0-9_males | B20: Framework-supplied default | C20: Proportion | E20: 0 | F20: OR
A21: ='Population Definitions'!$A$5 -> 0-9_females | B21: Framework-supplied default | C21: Proportion | E21: 0 | F21: OR
A22: ='Population Definitions'!$A$6 -> 10-17_males | B22: Framework-supplied default | C22: Proportion | E22: 0 | F22: OR
A23: ='Population Definitions'!$A$7 -> 10-17_females | B23: Framework-supplied default | C23: Proportion | E23: 0 | F23: OR
A24: ='Population Definitions'!$A$8 -> 18-64_males | B24: Framework-supplied default | C24: Proportion | E24: 0 | F24: OR
A25: ='Population Definitions'!$A$9 -> 18-64_females | B25: Framework-supplied default | C25: Proportion | E25: 0 | F25: OR
A26: ='Population Definitions'!$A$10 -> 65+_males | B26: Framework-supplied default | C26: Proportion | E26: 0 | F26: OR
A27: ='Population Definitions'!$A$11 -> 65+_females | B27: Framework-supplied default | C27: Proportion | E27: 0 | F27: OR
A28: ='Population Definitions'!$A$12 -> Prisoners_males | B28: Framework-supplied default | C28: Proportion | E28: 0 | F28: OR
A29: ='Population Definitions'!$A$13 -> Prisoners_females | B29: Framework-supplied default | C29: Proportion | E29: 0 | F29: OR
A30: ='Population Definitions'!$A$14 -> Prisoners_PWID_males | B30: Framework-supplied default | C30: Proportion | E30: 0 | F30: OR
A31: ='Population Definitions'!$A$15 -> Prisoners_PWID_females | B31: Framework-supplied default | C31: Proportion | E31: 0 | F31: OR
A33: Loss to follow-up rate on PCR test in F0-F2 | B33: Provenance | C33: Units | D33: Uncertainty | E33: Constant | G33: 2000 | H33: 2001 | I33: 2002 | J33: 2003 | K33: 2004 | L33: 2005 | M33: 2006 | N33: 2007 | O33: 2008 | P33: 2009 | Q33: 2010 | R33: 2011 | S33: 2012 | T33: 2013 | U33: 2014 | V33: 2015 | W33: 2016 | X33: 2017 | Y33: 2018 | Z33: 2019 | AA33: 2020 | AB33: 2021 | AC33: 2022 | AD33: 2023 | AE33: 2024 | AF33: 2025 | AG33: 2026 | AH33: 2027 | AI33: 2028 | AJ33: 2029 | AK33: 2030 | AL33: 2031 | AM33: 2032 | AN33: 2033 | AO33: 2034 | AP33: 2035 | AQ33: 2036 | AR33: 2037 | AS33: 2038 | AT33: 2039 | AU33: 2040 | AV33: 2041 | AW33: 2042 | AX33: 2043 | AY33: 2044 | AZ33: 2045 | BA33: 2046 | BB33: 2047 | BC33: 2048 | BD33: 2049 | BE33: 2050
A34: ='Population Definitions'!$A$2 -> PWID_males | B34: Framework-supplied default | C34: Proportion | E34: 0 | F34: OR
A35: ='Population Definitions'!$A$3 -> PWID_females | B35: Framework-supplied default | C35: Proportion | E35: 0 | F35: OR
A36: ='Population Definitions'!$A$4 -> 0-9_males | B36: Framework-supplied default | C36: Proportion | E36: 0 | F36: OR
A37: ='Population Definitions'!$A$5 -> 0-9_females | B37: Framework-supplied default | C37: Proportion | E37: 0 | F37: OR
A38: ='Population Definitions'!$A$6 -> 10-17_males | B38: Framework-supplied default | C38: Proportion | E38: 0 | F38: OR
A39: ='Population Definitions'!$A$7 -> 10-17_females | B39: Framework-supplied default | C39: Proportion | E39: 0 | F39: OR
A40: ='Population Definitions'!$A$8 -> 18-64_males | B40: Framework-supplied default | C40: Proportion | E40: 0 | F40: OR
A41: ='Population Definitions'!$A$9 -> 18-64_females | B41: Framework-supplied default | C41: Proportion | E41: 0 | F41: OR
A42: ='Population Definitions'!$A$10 -> 65+_males | B42: Framework-supplied default | C42: Proportion | E42: 0 | F42: OR
...

Sheet Re-engagement
A1: Antibody re-engagement in care, F0-F2, lost to follow-up after Ab test | B1: Provenance | C1: Units | D1: Uncertainty | E1: Constant | G1: 2000 | H1: 2001 | I1: 2002 | J1: 2003 | K1: 2004 | L1: 2005 | M1: 2006 | N1: 2007 | O1: 2008 | P1: 2009 | Q1: 2010 | R1: 2011 | S1: 2012 | T1: 2013 | U1: 2014 | V1: 2015 | W1: 2016 | X1: 2017 | Y1: 2018 | Z1: 2019 | AA1: 2020 | AB1: 2021 | AC1: 2022 | AD1: 2023 | AE1: 2024 | AF1: 2025 | AG1: 2026 | AH1: 2027 | AI1: 2028 | AJ1: 2029 | AK1: 2030 | AL1: 2031 | AM1: 2032 | AN1: 2033 | AO1: 2034 | AP1: 2035 | AQ1: 2036 | AR1: 2037 | AS1: 2038 | AT1: 2039 | AU1: 2040 | AV1: 2041 | AW1: 2042 | AX1: 2043 | AY1: 2044 | AZ1: 2045 | BA1: 2046 | BB1: 2047 | BC1: 2048 | BD1: 2049 | BE1: 2050
A2: ='Population Definitions'!$A$2 -> PWID_males | B2: Framework-supplied default | C2: Rate (per year) | E2: 0 | F2: OR
A3: ='Population Definitions'!$A$3 -> PWID_females | B3: Framework-supplied default | C3: Rate (per year) | E3: 0 | F3: OR
A4: ='Population Definitions'!$A$4 -> 0-9_males | B4: Framework-supplied default | C4: Rate (per year) | E4: 0 | F4: OR
A5: ='Population Definitions'!$A$5 -> 0-9_females | B5: Framework-supplied default | C5: Rate (per year) | E5: 0 | F5: OR
A6: ='Population Definitions'!$A$6 -> 10-17_males | B6: Framework-supplied default | C6: Rate (per year) | E6: 0 | F6: OR
A7: ='Population Definitions'!$A$7 -> 10-17_females | B7: Framework-supplied default | C7: Rate (per year) | E7: 0 | F7: OR
A8: ='Population Definitions'!$A$8 -> 18-64_males | B8: Framework-supplied default | C8: Rate (per year) | E8: 0 | F8: OR
A9: ='Population Definitions'!$A$9 -> 18-64_females | B9: Framework-supplied default | C9: Rate (per year) | E9: 0 | F9: OR
A10: ='Population Definitions'!$A$10 -> 65+_males | B10: Framework-supplied default | C10: Rate (per year) | E10: 0 | F10: OR
A11: ='Population Definitions'!$A$11 -> 65+_females | B11: Framework-supplied default | C11: Rate (per year) | E11: 0 | F11: OR
A12: ='Population Definitions'!$A$12 -> Prisoners_males | B12: Framework-supplied default | C12: Rate (per year) | E12: 0 | F12: OR
A13: ='Population Definitions'!$A$13 -> Prisoners_females | B13: Framework-supplied default | C13: Rate (per year) | E13: 0 | F13: OR
A14: ='Population Definitions'!$A$14 -> Prisoners_PWID_males | B14: Framework-supplied default | C14: Rate (per year) | E14: 0 | F14: OR
A15: ='Population Definitions'!$A$15 -> Prisoners_PWID_females | B15: Framework-supplied default | C15: Rate (per year) | E15: 0 | F15: OR
A17: Antibody re-engagement in care, F3+, lost to follow-up after Ab test | B17: Provenance | C17: Units | D17: Uncertainty | E17: Constant | G17: 2000 | H17: 2001 | I17: 2002 | J17: 2003 | K17: 2004 | L17: 2005 | M17: 2006 | N17: 2007 | O17: 2008 | P17: 2009 | Q17: 2010 | R17: 2011 | S17: 2012 | T17: 2013 | U17: 2014 | V17: 2015 | W17: 2016 | X17: 2017 | Y17: 2018 | Z17: 2019 | AA17: 2020 | AB17: 2021 | AC17: 2022 | AD17: 2023 | AE17: 2024 | AF17: 2025 | AG17: 2026 | AH17: 2027 | AI17: 2028 | AJ17: 2029 | AK17: 2030 | AL17: 2031 | AM17: 2032 | AN17: 2033 | AO17: 2034 | AP17: 2035 | AQ17: 2036 | AR17: 2037 | AS17: 2038 | AT17: 2039 | AU17: 2040 | AV17: 2041 | AW17: 2042 | AX17: 2043 | AY17: 2044 | AZ17: 2045 | BA17: 2046 | BB17: 2047 | BC17: 2048 | BD17: 2049 | BE17: 2050
A18: ='Population Definitions'!$A$2 -> PWID_males | B18: Framework-supplied default | C18: Rate (per year) | E18: 0 | F18: OR
A19: ='Population Definitions'!$A$3 -> PWID_females | B19: Framework-supplied default | C19: Rate (per year) | E19: 0 | F19: OR
A20: ='Population Definitions'!$A$4 -> 0-9_males | B20: Framework-supplied default | C20: Rate (per year) | E20: 0 | F20: OR
A21: ='Population Definitions'!$A$5 -> 0-9_females | B21: Framework-supplied default | C21: Rate (per year) | E21: 0 | F21: OR
A22: ='Population Definitions'!$A$6 -> 10-17_males | B22: Framework-supplied default | C22: Rate (per year) | E22: 0 | F22: OR
A23: ='Population Definitions'!$A$7 -> 10-17_females | B23: Framework-supplied default | C23: Rate (per year) | E23: 0 | F23: OR
A24: ='Population Definitions'!$A$8 -> 18-64_males | B24: Framework-supplied default | C24: Rate (per year) | E24: 0 | F24: OR
A25: ='Population Definitions'!$A$9 -> 18-64_females | B25: Framework-supplied default | C25: Rate (per year) | E25: 0 | F25: OR
A26: ='Population Definitions'!$A$10 -> 65+_males | B26: Framework-supplied default | C26: Rate (per year) | E26: 0 | F26: OR
A27: ='Population Definitions'!$A$11 -> 65+_females | B27: Framework-supplied default | C27: Rate (per year) | E27: 0 | F27: OR
A28: ='Population Definitions'!$A$12 -> Prisoners_males | B28: Framework-supplied default | C28: Rate (per year) | E28: 0 | F28: OR
A29: ='Population Definitions'!$A$13 -> Prisoners_females | B29: Framework-supplied default | C29: Rate (per year) | E29: 0 | F29: OR
A30: ='Population Definitions'!$A$14 -> Prisoners_PWID_males | B30: Framework-supplied default | C30: Rate (per year) | E30: 0 | F30: OR
A31: ='Population Definitions'!$A$15 -> Prisoners_PWID_females | B31: Framework-supplied default | C31: Rate (per year) | E31: 0 | F31: OR
A33: RNA re-engagement in care, F0-F2, lost to follow up after RNA test | B33: Provenance | C33: Units | D33: Uncertainty | E33: Constant | G33: 2000 | H33: 2001 | I33: 2002 | J33: 2003 | K33: 2004 | L33: 2005 | M33: 2006 | N33: 2007 | O33: 2008 | P33: 2009 | Q33: 2010 | R33: 2011 | S33: 2012 | T33: 2013 | U33: 2014 | V33: 2015 | W33: 2016 | X33: 2017 | Y33: 2018 | Z33: 2019 | AA33: 2020 | AB33: 2021 | AC33: 2022 | AD33: 2023 | AE33: 2024 | AF33: 2025 | AG33: 2026 | AH33: 2027 | AI33: 2028 | AJ33: 2029 | AK33: 2030 | AL33: 2031 | AM33: 2032 | AN33: 2033 | AO33: 2034 | AP33: 2035 | AQ33: 2036 | AR33: 2037 | AS33: 2038 | AT33: 2039 | AU33: 2040 | AV33: 2041 | AW33: 2042 | AX33: 2043 | AY33: 2044 | AZ33: 2045 | BA33: 2046 | BB33: 2047 | BC33: 2048 | BD33: 2049 | BE33: 2050
A34: ='Population Definitions'!$A$2 -> PWID_males | B34: Framework-supplied default | C34: Rate (per year) | E34: 0 | F34: OR
A35: ='Population Definitions'!$A$3 -> PWID_females | B35: Framework-supplied default | C35: Rate (per year) | E35: 0 | F35: OR
A36: ='Population Definitions'!$A$4 -> 0-9_males | B36: Framework-supplied default | C36: Rate (per year) | E36: 0 | F36: OR
A37: ='Population Definitions'!$A$5 -> 0-9_females | B37: Framework-supplied default | C37: Rate (per year) | E37: 0 | F37: OR
A38: ='Population Definitions'!$A$6 -> 10-17_males | B38: Framework-supplied default | C38: Rate (per year) | E38: 0 | F38: OR
A39: ='Population Definitions'!$A$7 -> 10-17_females | B39: Framework-supplied default | C39: Rate (per year) | E39: 0 | F39: OR
A40: ='Population Definitions'!$A$8 -> 18-64_males | B40: Framework-supplied default | C40: Rate (per year) | E40: 0 | F40: OR
A41: ='Population Definitions'!$A$9 -> 18-64_females | B41: Framework-supplied default | C41: Rate (per year) | E41: 0 | F41: OR
A42: ='Population Definitions'!$A$10 -> 65+_males | B42: Framework-supplied default | C42: Rate (per year) | E42: 0 | F42: OR
...

Sheet Treatment
A1: Proportion of treatments allocated to each population pre-DAA | B1: Provenance | C1: Units | D1: Uncertainty | E1: Constant | G1: 2000 | H1: 2001 | I1: 2002 | J1: 2003 | K1: 2004 | L1: 2005 | M1: 2006 | N1: 2007 | O1: 2008 | P1: 2009 | Q1: 2010 | R1: 2011 | S1: 2012 | T1: 2013 | U1: 2014 | V1: 2015 | W1: 2016 | X1: 2017 | Y1: 2018 | Z1: 2019 | AA1: 2020 | AB1: 2021 | AC1: 2022 | AD1: 2023 | AE1: 2024 | AF1: 2025 | AG1: 2026 | AH1: 2027 | AI1: 2028 | AJ1: 2029 | AK1: 2030 | AL1: 2031 | AM1: 2032 | AN1: 2033 | AO1: 2034 | AP1: 2035 | AQ1: 2036 | AR1: 2037 | AS1: 2038 | AT1: 2039 | AU1: 2040 | AV1: 2041 | AW1: 2042 | AX1: 2043 | AY1: 2044 | AZ1: 2045 | BA1: 2046 | BB1: 2047 | BC1: 2048 | BD1: 2049 | BE1: 2050
A2: ='Population Definitions'!$A$2 -> PWID_males | C2: N.A. | E2: 0 | F2: OR
A3: ='Population Definitions'!$A$3 -> PWID_females | C3: N.A. | E3: 0 | F3: OR
A4: ='Population Definitions'!$A$4 -> 0-9_males | C4: N.A. | F4: OR | G4: 0 | U4: 0 | V4: 0
A5: ='Population Definitions'!$A$5 -> 0-9_females | C5: N.A. | F5: OR | G5: 0 | U5: 0 | V5: 0
A6: ='Population Definitions'!$A$6 -> 10-17_males | C6: N.A. | F6: OR | G6: 0 | U6: 0 | V6: 0
A7: ='Population Definitions'!$A$7 -> 10-17_females | C7: N.A. | F7: OR | G7: 0 | U7: 0 | V7: 0
A8: ='Population Definitions'!$A$8 -> 18-64_males | C8: N.A. | F8: OR | G8: 0.21382081 | U8: 0.21382081 | V8: 0
