Workbook

Sheet Population Definitions
A1: Abbreviation | B1: Full Name | C1: Population type
A2: PWID_males | B2: People Who Inject Drugs (males) | C2: human
A3: PWID_females | B3: People Who Inject Drugs (females) | C3: human
A4: 0-9_males | B4: General Population 0-9 males | C4: human
A5: 0-9_females | B5: General Population 0-9 females | C5: human
A6: 10-17_males | B6: General Population 10-17 males | C6: human
A7: 10-17_females | B7: General Population 10-17 females | C7: human
A8: 18-64_males | B8: General Population 18-64 males | C8: human
A9: 18-64_females | B9: General Population 18-64 females | C9: human
A10: 65+_males | B10: General Population 65+ males | C10: human
A11: 65+_females | B11: General Population 65+ females | C11: human
A12: Prisoners_males | B12: Prisoners (males) | C12: human
... A15: Prisoners_PWID_females | B15: Prisoners (females) | C15: human

Sheet Disease Burden
A1: Population living with chronic HCV | B1: Provenance | C1: Units | D1: Uncertainty | E1: 2000 | F1: 2001 | G1: 2002 | H1: 2003 | I1: 2004 | J1: 2005 | K1: 2006 | L1: 2007 | M1: 2008 | N1: 2009 | O1: 2010 | P1: 2011 | Q1: 2012 | R1: 2013 | S1: 2014 | T1: 2015 | U1: 2016 | V1: 2017 | W1: 2018 | X1: 2019 | Y1: 2020 | Z1: 2021 | AA1: 2022 | AB1: 2023 | AC1: 2024 | AD1: 2025 | AE1: 2026 | AF1: 2027 | AG1: 2028 | AH1: 2029 | AI1: 2030 | AJ1: 2031 | AK1: 2032 | AL1: 2033 | AM1: 2034 | AN1: 2035 | AO1: 2036 | AP1: 2037 | AQ1: 2038 | AR1: 2039 | AS1: 2040 | AT1: 2041 | AU1: 2042 | AV1: 2043 | AW1: 2044 | AX1: 2045 | AY1: 2046 | AZ1: 2047 | BA1: 2048 | BB1: 2049 | BC1: 2050
A2: ='Population Definitions'!$A$2 -> PWID_males | C2: Number | E2: 9264.2462
A3: ='Population Definitions'!$A$3 -> PWID_females | C3: Number | E3: 434.60768
A4: ='Population Definitions'!$A$4 -> 0-9_males | C4: Number | E4: 0
A5: ='Population Definitions'!$A$5 -> 0-9_females | C5: Number | E5: 0
A6: ='Population Definitions'!$A$6 -> 10-17_males | C6: Number | E6: 0
A7: ='Population Definitions'!$A$7 -> 10-17_females | C7: Number | E7: 0
A8: ='Population Definitions'!$A$8 -> 18-64_males | C8: Number | E8: 1849362.2
A9: ='Population Definitions'!$A$9 -> 18-64_females | C9: Number | E9: 1795946.6
A10: ='Population Definitions'!$A$10 -> 65+_males | C10: Number | E10: 118193.9
A11: ='Population Definitions'!$A$11 -> 65+_females | C11: Number | E11: 163089
A12: ='Population Definitions'!$A$12 -> Prisoners_males | C12: Number | E12: 4871.1254
A13: ='Population Definitions'!$A$13 -> Prisoners_females | C13: Number | E13: 221.24577
A14: ='Population Definitions'!$A$14 -> Prisoners_PWID_males | C14: Number | E14: 1145.8635
A15: ='Population Definitions'!$A$15 -> Prisoners_PWID_females | C15: Number | E15: 86.139788
A17: HCV Prevalence | B17: Provenance | C17: Units | D17: Uncertainty | E17: 2000 | F17: 2001 | G17: 2002 | H17: 2003 | I17: 2004 | J17: 2005 | K17: 2006 | L17: 2007 | M17: 2008 | N17: 2009 | O17: 2010 | P17: 2011 | Q17: 2012 | R17: 2013 | S17: 2014 | T17: 2015 | U17: 2016 | V17: 2017 | W17: 2018 | X17: 2019 | Y17: 2020 | Z17: 2021 | AA17: 2022 | AB17: 2023 | AC17: 2024 | AD17: 2025 | AE17: 2026 | AF17: 2027 | AG17: 2028 | AH17: 2029 | AI17: 2030 | AJ17: 2031 | AK17: 2032 | AL17: 2033 | AM17: 2034 | AN17: 2035 | AO17: 2036 | AP17: 2037 | AQ17: 2038 | AR17: 2039 | AS17: 2040 | AT17: 2041 | AU17: 2042 | AV17: 2043 | AW17: 2044 | AX17: 2045 | AY17: 2046 | AZ17: 2047 | BA17: 2048 | BB17: 2049 | BC17: 2050
A18: ='Population Definitions'!$A$2 -> PWID_males | C18: Fraction | E18: 0.3267 | O18: 0.3267 | T18: 0.371
A19: ='Population Definitions'!$A$3 -> PWID_females | C19: Fraction | E19: 0.3267 | O19: 0.3267 | T19: 0.371
A20: ='Population Definitions'!$A$4 -> 0-9_males | C20: Fraction | E20: 0 | O20: 0
A21: ='Population Definitions'!$A$5 -> 0-9_females | C21: Fraction | E21: 0 | O21: 0
A22: ='Population Definitions'!$A$6 -> 10-17_males | C22: Fraction | E22: 0 | O22: 0
A23: ='Population Definitions'!$A$7 -> 10-17_females | C23: Fraction | E23: 0 | O23: 0
A24: ='Population Definitions'!$A$8 -> 18-64_males | C24: Fraction | E24: 0.095602233 | O24: 0
A25: ='Population Definitions'!$A$9 -> 18-64_females | C25: Fraction | E25: 0.095602233 | O25: 0
A26: ='Population Definitions'!$A$10 -> 65+_males | C26: Fraction | E26: 0.095602233 | O26: 0
A27: ='Population Definitions'!$A$11 -> 65+_females | C27: Fraction | E27: 0.095602233 | O27: 0
A28: ='Population Definitions'!$A$12 -> Prisoners_males | C28: Fraction | E28: 0.095602233 | O28: 0
A29: ='Population Definitions'!$A$13 -> Prisoners_females | C29: Fraction | E29: 0.095602233 | O29: 0
A30: ='Population Definitions'!$A$14 -> Prisoners_PWID_males | C30: Fraction | E30: 0.371 | O30: 0.371
A31: ='Population Definitions'!$A$15 -> Prisoners_PWID_females | C31: Fraction | E31: 0.371 | O31: 0.371
A33: Proportion who have F0-F2 | B33: Provenance | C33: Units | D33: Uncertainty | E33: Constant | G33: 2000 | H33: 2001 | I33: 2002 | J33: 2003 | K33: 2004 | L33: 2005 | M33: 2006 | N33: 2007 | O33: 2008 | P33: 2009 | Q33: 2010 | R33: 2011 | S33: 2012 | T33: 2013 | U33: 2014 | V33: 2015 | W33: 2016 | X33: 2017 | Y33: 2018 | Z33: 2019 | AA33: 2020 | AB33: 2021 | AC33: 2022 | AD33: 2023 | AE33: 2024 | AF33: 2025 | AG33: 2026 | AH33: 2027 | AI33: 2028 | AJ33: 2029 | AK33: 2030 | AL33: 2031 | AM33: 2032 | AN33: 2033 | AO33: 2034 | AP33: 2035 | AQ33: 2036 | AR33: 2037 | AS33: 2038 | AT33: 2039 | AU33: 2040 | AV33: 2041 | AW33: 2042 | AX33: 2043 | AY33: 2044 | AZ33: 2045 | BA33: 2046 | BB33: 2047 | BC33: 2048 | BD33: 2049 | BE33: 2050
A34: ='Population Definitions'!$A$2 -> PWID_males | C34: Fraction | E34: 0.945 | F34: OR
A35: ='Population Definitions'!$A$3 -> PWID_females | C35: Fraction | E35: 0.945 | F35: OR
A36: ='Population Definitions'!$A$4 -> 0-9_males | C36: Fraction | E36: 0.945 | F36: OR
A37: ='Population Definitions'!$A$5 -> 0-9_females | C37: Fraction | E37: 0.945 | F37: OR
A38: ='Population Definitions'!$A$6 -> 10-17_males | C38: Fraction | E38: 0.945 | F38: OR
A39: ='Population Definitions'!$A$7 -> 10-17_females | C39: Fraction | E39: 0.945 | F39: OR
A40: ='Population Definitions'!$A$8 -> 18-64_males | C40: Fraction | E40: 0.945 | F40: OR
A41: ='Population Definitions'!$A$9 -> 18-64_females | C41: Fraction | E41: 0.945 | F41: OR
A42: ='Population Definitions'!$A$10 -> 65+_males | C42: Fraction | E42: 0.945 | F42: OR
...

Sheet Demographics
A1: Population size | B1: Provenance | C1: Units | D1: Uncertainty | E1: 2000 | F1: 2001 | G1: 2002 | H1: 2003 | I1: 2004 | J1: 2005 | K1: 2006 | L1: 2007 | M1: 2008 | N1: 2009 | O1: 2010 | P1: 2011 | Q1: 2012 | R1: 2013 | S1: 2014 | T1: 2015 | U1: 2016 | V1: 2017 | W1: 2018 | X1: 2019 | Y1: 2020 | Z1: 2021 | AA1: 2022 | AB1: 2023 | AC1: 2024 | AD1: 2025 | AE1: 2026 | AF1: 2027 | AG1: 2028 | AH1: 2029 | AI1: 2030 | AJ1: 2031 | AK1: 2032 | AL1: 2033 | AM1: 2034 | AN1: 2035 | AO1: 2036 | AP1: 2037 | AQ1: 2038 | AR1: 2039 | AS1: 2040 | AT1: 2041 | AU1: 2042 | AV1: 2043 | AW1: 2044 | AX1: 2045 | AY1: 2046 | AZ1: 2047 | BA1: 2048 | BB1: 2049 | BC1: 2050
A2: ='Population Definitions'!$A$2 -> PWID_males | C2: Number | E2: 28357.044 | O2: 28357.044 | T2: 28357.044
A3: ='Population Definitions'!$A$3 -> PWID_females | C3: Number | E3: 1330.2959 | O3: 1330.2959 | T3: 1330.2959
A4: ='Population Definitions'!$A$4 -> 0-9_males | C4: Number | E4: 9341226 | F4: 9403426 | G4: 9487595.5 | H4: 9592943 | I4: 9715335 | J4: 9856078.5 | K4: 10013874 | L4: 10184206 | M4: 10361880 | N4: 10553564 | O4: 10773334 | P4: 11018581 | Q4: 11293283 | R4: 11610476 | S4: 11952666 | T4: 12293054 | U4: 12596785 | V4: 12848124 | W4: 13014834 | X4: 13074055 | Y4: 13076501 | Z4: 13036584 | AA4: 12948348 | AB4: 12826847 | AC4: 12689926 | AD4: 12534820 | AE4: 12390304 | AF4: 12276886 | AG4: 12224991 | AH4: 12258186 | AI4: 12322388 | AJ4: 12409497 | AK4: 12516908 | AL4: 12623038 | AM4: 12727948 | AN4: 12836270 | AO4: 12952156 | AP4: 13074165 | AQ4: 13199738 | AR4: 13326044 | AS4: 13448266 | AT4: 13560837 | AU4: 13658183 | AV4: 13735208 | AW4: 13788056 | AX4: 13813846 | AY4: 13813127 | AZ4: 13789549 | BA4: 13745089 | BB4: 13681268 | BC4: 13602722
A5: ='Population Definitions'!$A$5 -> 0-9_females | C5: Number | E5: 8792800 | F5: 8860499 | G5: 8954786.5 | H5: 9075199 | I5: 9213740 | J5: 9367219 | K5: 9532463 | L5: 9704242.5 | M5: 9879201.5 | N5: 10064684 | O5: 10276000 | P5: 10511930 | Q5: 10774722 | R5: 11075320 | S5: 11397504 | T5: 11718578 | U5: 12007220 | V5: 12248024 | W5: 12409486 | X5: 12469570 | Y5: 12474892 | Z5: 12437452 | AA5: 12351056 | AB5: 12230677 | AC5: 12093577 | AD5: 11938420 | AE5: 11794212 | AF5: 11680078 | AG5: 11625430 | AH5: 11653005 | AI5: 11710904 | AJ5: 11790968 | AK5: 11890768 | AL5: 11989655 | AM5: 12087768 | AN5: 12189463 | AO5: 12298262 | AP5: 12412868 | AQ5: 12530881 | AR5: 12649475 | AS5: 12764290 | AT5: 12870110 | AU5: 12961453 | AV5: 13033621 | AW5: 13083064 | AX5: 13106858 | AY5: 13105460 | AZ5: 13082154 | BA5: 13039030 | BB5: 12977821 | BC5: 12902468
A6: ='Population Definitions'!$A$6 -> 10-17_males | C6: Number | E6: 7085058.5 | F6: 7183759.5 | G6: 7250159 | H6: 7291015 | I6: 7311170.5 | J6: 7314503 | K6: 7303454.5 | L6: 7296125 | M6: 7313713 | N6: 7354264.5 | O6: 7409280.5 | P6: 7489379 | Q6: 7592989 | R6: 7709073 | S6: 7827804 | T6: 7940878.5 | U6: 8055604.5 | V6: 8186381 | W6: 8344588.5 | X6: 8525223 | Y6: 8725156 | Z6: 8942552.5 | AA6: 9189679 | AB6: 9480415 | AC6: 9785850 | AD6: 10074704 | AE6: 10315956 | AF6: 10503069 | AG6: 10602802 | AH6: 10595362 | AI6: 10525858 | AJ6: 10390669 | AK6: 10211200 | AL6: 10026254 | AM6: 9869843.5 | AN6: 9746938.5 | AO6: 9682110.5 | AP6: 9699358 | AQ6: 9744155.5 | AR6: 9808614 | AS6: 9890557 | AT6: 9969182.5 | AU6: 10045574 | AV6: 10125918 | AW6: 10215001 | AX6: 10311526 | AY6: 10413717 | AZ6: 10519066 | BA6: 10624688 | BB6: 10727842 | BC6: 10824435
A7: ='Population Definitions'!$A$7 -> 10-17_females | C7: Number | E7: 6709353 | F7: 6799702.5 | G7: 6856951.5 | H7: 6885860.5 | I7: 6892824.5 | J7: 6886507.5 | K7: 6872131 | L7: 6866847.5 | M7: 6888451.5 | N7: 6934370.5 | O7: 6996407 | P7: 7083879 | Q7: 7195179.5 | R7: 7321801 | S7: 7452891 | T7: 7576750.5 | U7: 7697825 | V7: 7828580.5 | W7: 7982131.5 | X7: 8154052.5 | Y7: 8340919 | Z7: 8541832.5 | AA7: 8770802 | AB7: 9044674.5 | AC7: 9335025.5 | AD7: 9611925 | AE7: 9846502.5 | AF7: 10030791 | AG7: 10130663 | AH7: 10125450 | AI7: 10057998 | AJ7: 9925278.5 | AK7: 9749215.5 | AL7: 9567105.5 | AM7: 9411434 | AN7: 9288112 | AO7: 9221376 | AP7: 9234043 | AQ7: 9273686 | AR7: 9332602 | AS7: 9408569.5 | AT7: 9481503 | AU7: 9552730.5 | AV7: 9627898 | AW7: 9711281 | AX7: 9801889 | AY7: 9897957.5 | AZ7: 9996985.5 | BA7: 10096182 | BB7: 10193089 | BC7: 10283806
A8: ='Population Definitions'!$A$8 -> 18-64_males | C8: Number | E8: 19344342 | F8: 19954372 | G8: 20580447 | H8: 21224352 | I8: 21878988 | J8: 22532586 | K8: 23156484 | L8: 23749805 | M8: 24309114 | N8: 24850178 | O8: 25368685 | P8: 25938126 | Q8: 26545088 | R8: 27142367 | S8: 27715027 | T8: 28217421 | U8: 28702459 | V8: 29271345 | W8: 29861438 | X8: 30470258 | Y8: 31074146 | Z8: 31656756 | AA8: 32257869 | AB8: 32937556 | AC8: 33769028 | AD8: 34428483 | AE8: 35071394 | AF8: 35739015 | AG8: 36435771 | AH8: 37153331 | AI8: 37902427 | AJ8: 38696304 | AK8: 39515512 | AL8: 40342112 | AM8: 41144203 | AN8: 41910182 | AO8: 42610775 | AP8: 43224031 | AQ8: 43804415 | AR8: 44360722 | AS8: 44892303 | AT8: 45419798 | AU8: 45944840 | AV8: 46459999 | AW8: 46961906 | AX8: 47452913 | AY8: 47935012 | AZ8: 48409066 | BA8: 48870838 | BB8: 49323136 | BC8: 49772374
A9: ='Population Definitions'!$A$9 -> 18-64_females | C9: Number | E9: 18785614 | F9: 19358102 | G9: 19951920 | H9: 20567840 | I9: 21199480 | J9: 21836750 | K9: 22468031 | L9: 23079263 | M9: 23666545 | N9: 24233973 | O9: 24776619 | P9: 25344276 | Q9: 25920000 | R9: 26490204 | S9: 27054404 | T9: 27574199 | U9: 28105269 | V9: 28653430 | W9: 29211158 | X9: 29787430 | Y9: 30363255 | Z9: 30935373 | AA9: 31516750 | AB9: 32177452 | AC9: 32874267 | AD9: 33510197 | AE9: 34134429 | AF9: 34781080 | AG9: 35456233 | AH9: 36154715 | AI9: 36887866 | AJ9: 37667683 | AK9: 38473773 | AL9: 39288983 | AM9: 40082169 | AN9: 40840960 | AO9: 41536208 | AP9: 42145935 | AQ9: 42722325 | AR9: 43273601 | AS9: 43798903 | AT9: 44317780 | AU9: 44831574 | AV9: 45333030 | AW9: 45818402 | AX9: 46290318 | AY9: 46751159 | AZ9: 47201272 | BA9: 47636195 | BB9: 48058970 | BC9: 48474738
A10: ='Population Definitions'!$A$10 -> 65+_males | C10: Number | E10: 1236309 | F10: 1263717 | G10: 1289759.5 | H10: 1312963.5 | I10: 1332008 | J10: 1347663.5 | K10: 1362652.5 | L10: 1379598 | M10: 1400752 | N10: 1428722.5 | O10: 1465956.5 | P10: 1514147.5 | Q10: 1573271 | R10: 1639274 | S10: 1706639 | T10: 1773921.5 | U10: 1845624 | V10: 1925499.5 | W10: 2013506 | X10: 2108916.5 | Y10: 2190919 | Z10: 2249931.5 | AA10: 2330990.5 | AB10: 2445456 | AC10: 2568738 | AD10: 2695885.5 | AE10: 2825018 | AF10: 2957937.5 | AG10: 3094698.5 | AH10: 3233934.5 | AI10: 3372714.5 | AJ10: 3512262 | AK10: 3654948.5 | AL10: 3800253 | AM10: 3948234.5 | AN10: 4098454 | AO10: 4251264 | AP10: 4407657.5 | AQ10: 4566267 | AR10: 4728340 | AS10: 4897651 | AT10: 5075687.5 | AU10: 5261593.5 | AV10: 5455058.5 | AW10: 5656715 | AX10: 5866142 | AY10: 6081020.5 | AZ10: 6304097.5 | BA10: 6541937.5 | BB10: 6791132.5 | BC10: 7046565.5
A11: ='Population Definitions'!$A$11 -> 65+_females | C11: Number | E11: 1705912 | F11: 1745781 | G11: 1784848.5 | H11: 1820705 | I11: 1851227.5 | J11: 1877026.5 | K11: 1900853 | L11: 1925677 | M11: 1954671.5 | N11: 1991417.5 | O11: 2039329.5 | P11: 2100657.5 | Q11: 2174385.5 | R11: 2252955.5 | S11: 2329636.5 | T11: 2410456 | U11: 2501720 | V11: 2602590 | W11: 2712869 | X11: 2831569 | Y11: 2937252 | Z11: 3010442.5 | AA11: 3106673 | AB11: 3246611.5 | AC11: 3393703.5 | AD11: 3543417 | AE11: 3695217.5 | AF11: 3850617.5 | AG11: 4009725.5 | AH11: 4170923.5 | AI11: 4331023.5 | AJ11: 4491448.5 | AK11: 4654611.5 | AL11: 4820061.5 | AM11: 4988097.5 | AN11: 5158695.5 | AO11: 5332969.5 | AP11: 5512496 | AQ11: 5696221 | AR11: 5885723.5 | AS11: 6084973 | AT11: 6295516.5 | AU11: 6516691.5 | AV11: 6748783 | AW11: 6992767 | AX11: 7247555 | AY11: 7510352 | AZ11: 7784074 | BA11: 8075288 | BB11: 8380213 | BC11: 8694943
A12: ='Population Definitions'!$A$12 -> Prisoners_males | C12: Number | E12: 50952.004 | F12: 50952.004 | K12: 58452.757 | P12: 59925.47 | U12: 96243.937 | Z12: 108955.4
A13: ='Population Definitions'!$A$13 -> Prisoners_females | C13: Number | E13: 2314.2323 | F13: 2314.2323 | K13: 2164.796 | P13: 2219.3379 | U13: 3564.3911 | Z13: 4035.1598
A14: ='Population Definitions'!$A$14 -> Prisoners_PWID_males | C14: Number | E14: 3088.5809 | F14: 3088.5809 | K14: 3543.2575 | P14: 3632.5296 | U14: 5834.0628 | Z14: 6604.5993
A15: ='Population Definitions'!$A$15 -> Prisoners_PWID_females | C15: Number | E15: 232.18272 | F15: 232.18272 | K15: 217.19004 | P15: 222.66213 | U15: 357.60888 | Z15: 404.84024
A17: Number of live births | B17: Provenance | C17: Units | D17: Uncertainty | E17: Constant | G17: 2000 | H17: 2001 | I17: 2002 | J17: 2003 | K17: 2004 | L17: 2005 | M17: 2006 | N17: 2007 | O17: 2008 | P17: 2009 | Q17: 2010 | R17: 2011 | S17: 2012 | T17: 2013 | U17: 2014 | V17: 2015 | W17: 2016 | X17: 2017 | Y17: 2018 | Z17: 2019 | AA17: 2020 | AB17: 2021 | AC17: 2022 | AD17: 2023 | AE17: 2024 | AF17: 2025 | AG17: 2026 | AH17: 2027 | AI17: 2028 | AJ17: 2029 | AK17: 2030 | AL17: 2031 | AM17: 2032 | AN17: 2033 | AO17: 2034 | AP17: 2035 | AQ17: 2036 | AR17: 2037 | AS17: 2038 | AT17: 2039 | AU17: 2040 | AV17: 2041 | AW17: 2042 | AX17: 2043 | AY17: 2044 | AZ17: 2045 | BA17: 2046 | BB17: 2047 | BC17: 2048 | BD17: 2049 | BE17: 2050
A18: ='Population Definitions'!$A$2 -> PWID_males | C18: Number (per year) | E18: 0 | F18: OR
A19: ='Population Definitions'!$A$3 -> PWID_females | C19: Number (per year) | E19: 0 | F19: OR
A20: ='Population Definitions'!$A$4 -> 0-9_males | C20: Number (per year) | F20: OR | G20: 1030086.9 | H20: 1045414.6 | I20: 1058266.9 | J20: 1069307.5 | K20: 1079538.5 | L20: 1102509.3 | M20: 1125643 | N20: 1160590.6 | O20: 1189156 | P20: 1223387.8 | Q20: 1258852.2 | R20: 1284338.5 | S20: 1342284.8 | T20: 1396081.5 | U20: 1418336.9 | V20: 1437774.2 | W20: 1388981 | X20: 1386862.9 | Y20: 1278202.6 | Z20: 1228383.7 | AA20: 1233752.3 | AB20: 1204470 | AC20: 1218825.3 | AD20: 1235051.8 | AE20: 1251322.4 | AF20: 1257799.7 | AG20: 1263151.1 | AH20: 1269142 | AI20: 1276486.2 | AJ20: 1286447.3 | AK20: 1298259.6 | AL20: 1310680 | AM20: 1324739.1 | AN20: 1339054.6 | AO20: 1352941.5 | AP20: 1366294.5 | AQ20: 1378744.7 | AR20: 1390017.7 | AS20: 1400300.4 | AT20: 1409003.1 | AU20: 1413822 | AV20: 1413709.5 | AW20: 1409696.8 | AX20: 1402339.4 | AY20: 1389640.5 | AZ20: 1374763.9 | BA20: 1362306 | BB20: 1351660.5 | BC20: 1340986.1 | BD20: 1332102.1 | BE20: 1324844.4
A21: ='Population Definitions'!$A$5 -> 0-9_females | C21: Number (per year) | F21: OR | G21: 971780.1 | H21: 989039.38 | I21: 1005957.1 | J21: 1022282.5 | K21: 1032063.5 | L21: 1052012.7 | M21: 1071021 | N21: 1102175.4 | O21: 1127162 | P21: 1157415.2 | Q21: 1193224.8 | R21: 1218537.5 | S21: 1277150.2 | T21: 1329601.5 | U21: 1350797.1 | V21: 1369308.8 | W21: 1322839 | X21: 1319565.1 | Y21: 1215021.4 | Z21: 1166556.3 | AA21: 1171654.7 | AB21: 1142761 | AC21: 1156380.7 | AD21: 1170665.2 | AE21: 1186087.6 | AF21: 1192227.3 | AG21: 1196165.9 | AH21: 1201839 | AI21: 1208793.8 | AJ21: 1218226.7 | AK21: 1228249.4 | AL21: 1240000 | AM21: 1253300.9 | AN21: 1266844.4 | AO21: 1279982.5 | AP21: 1292615.5 | AQ21: 1304394.3 | AR21: 1315059.3 | AS21: 1324787.6 | AT21: 1333020.9 | AU21: 1337580 | AV21: 1337473.5 | AW21: 1333677.2 | AX21: 1326716.6 | AY21: 1314702.5 | AZ21: 1300628.1 | BA21: 1288842 | BB21: 1278770.5 | BC21: 1268671.9 | BD21: 1260266.9 | BE21: 1253400.6
A22: ='Population Definitions'!$A$6 -> 10-17_males | C22: Number (per year) | E22: 0 | F22: OR
A23: ='Population Definitions'!$A$7 -> 10-17_females | C23: Number (per year) | E23: 0 | F23: OR
A24: ='Population Definitions'!$A$8 -> 18-64_males | C24: Number (per year) | E24: 0 | F24: OR
A25: ='Population Definitions'!$A$9 -> 18-64_females | C25: Number (per year) | E25: 0 | F25: OR
A26: ='Population Definitions'!$A$10 -> 65+_males | C26: Number (per year) | E26: 0 | F26: OR
A27: ='Population Definitions'!$A$11 -> 65+_females | C27: Number (per year) | E27: 0 | F27: OR
A28: ='Population Definitions'!$A$12 -> Prisoners_males | C28: Number (per year) | E28: 0 | F28: OR
A29: ='Population Definitions'!$A$13 -> Prisoners_females | C29: Number (per year) | E29: 0 | F29: OR
A30: ='Population Definitions'!$A$14 -> Prisoners_PWID_males | C30: Number (per year) | E30: 0 | F30: OR
A31: ='Population Definitions'!$A$15 -> Prisoners_PWID_females | C31: Number (per year) | E31: 0 | F31: OR
A33: Net migration rate | B33: Provenance | C33: Units | D33: Uncertainty | E33: Constant | G33: 2000 | H33: 2001 | I33: 2002 | J33: 2003 | K33: 2004 | L33: 2005 | M33: 2006 | N33: 2007 | O33: 2008 | P33: 2009 | Q33: 2010 | R33: 2011 | S33: 2012 | T33: 2013 | U33: 2014 | V33: 2015 | W33: 2016 | X33: 2017 | Y33: 2018 | Z33: 2019 | AA33: 2020 | AB33: 2021 | AC33: 2022 | AD33: 2023 | AE33: 2024 | AF33: 2025 | AG33: 2026 | AH33: 2027 | AI33: 2028 | AJ33: 2029 | AK33: 2030 | AL33: 2031 | AM33: 2032 | AN33: 2033 | AO33: 2034 | AP33: 2035 | AQ33: 2036 | AR33: 2037 | AS33: 2038 | AT33: 2039 | AU33: 2040 | AV33: 2041 | AW33: 2042 | AX33: 2043 | AY33: 2044 | AZ33: 2045 | BA33: 2046 | BB33: 2047 | BC33: 2048 | BD33: 2049 | BE33: 2050
A34: ='Population Definitions'!$A$2 -> PWID_males | C34: Rate (per year) | E34: 0 | F34: OR
A35: ='Population Definitions'!$A$3 -> PWID_females | C35: Rate (per year) | E35: 0 | F35: OR
A36: ='Population Definitions'!$A$4 -> 0-9_males | C36: Rate (per year) | F36: OR | G36: 0.00099029796 | H36: 0.00081851846 | I36: 0.0007502022 | J36: 0.00066387369 | K36: 0.0011869934 | L36: 0.00099478665 | M36: 0.0013594605 | N36: 0.00093555184 | O36: 0.0011819808 | P36: 0.0012129237 | Q36: 0.0012265301 | R36: 0.0029127605 | S36: 0.0026686368 | T36: 0.0011654098 | U36: 0.00050181888 | V36: -0.0022171235 | W36: -0.00024962525 | X36: -0.00420944 | Y36: -0.0017854671 | Z36: 0.00030359817 | AA36: -0.0010286657 | AB36: 0.00062469999 | AC36: 0.0011882382 | AD36: 0.0017115435 | AE36: 0.00056265823 | AF36: -0.00014250299 | AG36: -1.9986916e-05 | AH36: 0.00017219413 | AI36: 0.00030570774 | AJ36: 0.00034516964 | AK36: 0.00036412523 | AL36: 0.00044115406 | AM36: 0.0004362438 | AN36: 0.00043400277 | AO36: 0.00040018224 | AP36: 0.00036353701 | AQ36: 0.00035397687 | AR36: 0.0003141164 | AS36: 0.00026053963 | AT36: 9.9272089e-05 | AU36: -8.6741979e-05 | AV36: -0.00022741921 | AW36: -0.00038905616 | AX36: -0.0005897561 | AY36: -0.00065879635 | AZ36: -0.00057796367 | BA36: -0.00048399592 | BB36: -0.00045617593 | BC36: -0.00040390046 | BD36: -0.00034745365 | BE36: -0.00029835328
A37: ='Population Definitions'!$A$5 -> 0-9_females | C37: Rate (per year) | F37: OR | G37: 0.0011925556 | H37: 0.0011283927 | I37: 0.0010703644 | J37: 0.00065282288 | K37: 0.001113116 | L37: 0.00085519562 | M37: 0.0012231398 | N37: 0.00074638972 | O37: 0.00099511648 | P37: 0.0012398632 | Q37: 0.001248558 | R37: 0.0030655181 | S37: 0.0026796355 | T37: 0.0011116642 | U37: 0.00046000658 | V37: -0.0022382221 | W37: -0.00031343846 | X37: -0.0042524078 | Y37: -0.001806557 | Z37: 0.00031418411 | AA37: -0.0010747308 | AB37: 0.0006148 | AC37: 0.0011625548 | AD37: 0.001665917 | AE37: 0.00050914703 | AF37: -0.00014040808 | AG37: 3.3799966e-05 | AH37: 0.00018377378 | AI37: 0.00029553535 | AJ37: 0.00031853125 | AK37: 0.0004073219 | AL37: 0.00047218347 | AM37: 0.00045363567 | AN37: 0.00044034348 | AO37: 0.00040942224 | AP37: 0.0003647856 | AQ37: 0.00034535258 | AR37: 0.0002911648 | AS37: 0.00022527908 | AT37: 6.906182e-05 | AU37: -0.00012146941 | AV37: -0.00026355681 | AW37: -0.00041844844 | AX37: -0.00060843242 | AY37: -0.00066719687 | AZ37: -0.00059034735 | BA37: -0.00051303065 | BB37: -0.00048887514 | BC37: -0.00042252775 | BD37: -0.00037335956 | BE37: -0.00033137717
A38: ='Population Definitions'!$A$6 -> 10-17_males | C38: Rate (per year) | F38: OR | G38: 0.00012364048 | H38: 6.4381331e-05 | I38: 8.8825638e-05 | J38: 5.3010452e-05 | K38: -8.7263729e-05 | L38: -0.00045649035 | M38: -0.00089724664 | N38: -0.0011393719 | O38: -0.0011444255 | P38: -0.0011460697 | Q38: -0.00026500549 | R38: 0.000342485 | S38: 0.000342487 | T38: 7.2317385e-05 | U38: -0.00082328326 | V38: -0.0007401574 | W38: -0.00035695645 | X38: -9.9677745e-05 | Y38: 9.6289949e-05 | Z38: 5.7065956e-05 | AA38: 3.2778784e-05 | AB38: 8.6943856e-05 | AC38: 0.00068060049 | AD38: 0.00085877042 | AE38: 6.8977146e-05 | AF38: -0.00028685705 | AG38: -0.00021825412 | AH38: -0.00014819478 | AI38: -0.00013548305 | AJ38: -0.00014190171 | AK38: -0.00013642593 | AL38: -0.00013199343 | AM38: -0.00014410648 | AN38: -0.00014102973 | AO38: -0.00015187677 | AP38: -0.0001588704 | AQ38: -0.00014712701 | AR38: -0.00015336067 | AS38: -0.00015434893 | AT38: -0.00016271412 | AU38: -0.00016626971 | AV38: -0.00016626238 | AW38: -0.00018988462 | AX38: -0.00019321706 | AY38: -0.00018536464 | AZ38: -0.00019075741 | BA38: -0.00017731421 | BB38: -0.00015980506 | BC38: -0.00016113414 | BD38: -0.00016317354 | BE38: -0.00017506687
A39: ='Population Definitions'!$A$7 -> 10-17_females | C39: Rate (per year) | F39: OR | G39: 8.1677026e-05 | H39: 5.7796646e-05 | I39: 8.5096125e-05 | J39: 4.2768801e-05 | K39: -6.1803401e-05 | L39: -0.00029870003 | M39: -0.00058598999 | N39: -0.00074408235 | O39: -0.00074712002 | P39: -0.00074844573 | Q39: -1.3149607e-05 | R39: 0.00037168901 | S39: 0.00037434785 | T39: 0.00019728753 | U39: -0.00054072977 | V39: -0.00048899591 | W39: -0.00033775774 | X39: -0.00014632282 | Y39: 8.2120922e-05 | Z39: 4.0348036e-05 | AA39: 2.7634845e-05 | AB39: 7.0125468e-05 | AC39: 0.00076127588 | AD39: 0.00091739067 | AE39: 4.2902936e-05 | AF39: -0.00026415104 | AG39: -0.00020519977 | AH39: -0.00014550198 | AI39: -0.00013543043 | AJ39: -0.00014182085 | AK39: -0.00013889444 | AL39: -0.0001365201 | AM39: -0.00014831963 | AN39: -0.00014617796 | AO39: -0.00015528983 | AP39: -0.00016052778 | AQ39: -0.00014824252 | AR39: -0.00015296658 | AS39: -0.00015333709 | AT39: -0.0001600304 | AU39: -0.00016341485 | AV39: -0.00016321252 | AW39: -0.00018350774 | AX39: -0.00018633351 | AY39: -0.00017963645 | AZ39: -0.00018384211 | BA39: -0.00017210621 | BB39: -0.00015654719 | BC39: -0.00015783195 | BD39: -0.00015937269 | BE39: -0.00016968427
A40: ='Population Definitions'!$A$8 -> 18-64_males | C40: Rate (per year) | F40: OR | G40: 0.00043165019 | H40: 0.00012965999 | I40: 0.00020891378 | J40: 5.4076523e-05 | K40: -0.00052646486 | L40: -0.0019864335 | M40: -0.00361744 | N40: -0.0044115019 | O40: -0.0043167771 | P40: -0.0042249993 | Q40: -0.0011106077 | R40: 0.0010787685 | S40: 0.001075886 | T40: 0.0001284397 | U40: -0.00286908 | V40: -0.0025607181 | W40: -0.0011701121 | X40: -0.00029816476 | Y40: 0.00030770366 | Z40: -5.6835472e-05 | AA40: 7.3988068e-05 | AB40: 0.00040335479 | AC40: 0.0022852671 | AD40: 0.002701353 | AE40: 0.00051764088 | AF40: -0.00049507932 | AG40: -0.00029816517 | AH40: -0.00010328355 | AI40: -7.0415054e-05 | AJ40: -9.2886126e-05 | AK40: -7.8066854e-05 | AL40: -6.1255732e-05 | AM40: -8.3278299e-05 | AN40: -5.8114311e-05 | AO40: -6.7766467e-05 | AP40: -6.3488416e-05 | AQ40: -1.1926156e-05 | AR40: -1.7155818e-05 | AS40: -9.7077372e-06 | AT40: -2.110963e-05 | AU40: -2.3163966e-05 | AV40: -1.6800011e-05 | AW40: -6.2136402e-05 | AX40: -6.3351588e-05 | AY40: -4.0935541e-05 | AZ40: -4.8336635e-05 | BA40: -1.598153e-05 | BB40: 2.8945611e-05 | BC40: 3.1024119e-05 | BD40: 2.9017378e-05 | BE40: 4.9398606e-06
A41: ='Population Definitions'!$A$9 -> 18-64_females | C41: Rate (per year) | F41: OR | G41: 0.00026182189 | H41: 0.00016077902 | I41: 0.00024058173 | J41: 8.0134293e-05 | K41: -0.00027196165 | L41: -0.0010145771 | M41: -0.0018564648 | N41: -0.0022605622 | O41: -0.0022025109 | P41: -0.0021468428 | Q41: -7.8287895e-06 | R41: 0.0010890187 | S41: 0.0010995892 | T41: 0.00059866439 | U41: -0.0014444987 | V41: -0.0012966146 | W41: -0.00087383653 | X41: -0.000343334 | Y41: 0.00028150275 | Z41: -1.6614818e-05 | AA41: -7.4748489e-06 | AB41: 0.00046762978 | AC41: 0.002271281 | AD41: 0.0026613557 | AE41: 0.0004214041 | AF41: -0.00043757803 | AG41: -0.00027304044 | AH41: -0.00010985372 | AI41: -8.4494872e-05 | AJ41: -0.00010342609 | AK41: -9.269599e-05 | AL41: -8.0636121e-05 | AM41: -9.8998545e-05 | AN41: -8.0413793e-05 | AO41: -8.8913928e-05 | AP41: -8.5597112e-05 | AQ41: -4.4188722e-05 | AR41: -4.9469156e-05 | AS41: -4.385137e-05 | AT41: -5.4442342e-05 | AU41: -5.7362434e-05 | AV41: -5.2866335e-05 | AW41: -9.1929819e-05 | AX41: -9.3515832e-05 | AY41: -7.6069498e-05 | AZ41: -8.3675623e-05 | BA41: -5.656358e-05 | BB41: -2.0708512e-05 | BC41: -2.0897299e-05 | BD41: -2.2575707e-05 | BE41: -4.2969471e-05
A42: ='Population Definitions'!$A$10 -> 65+_males | C42: Rate (per year) | F42: OR | G42: -0.0026781331 | H42: -0.0027367678 | I42: -0.002575674 | J42: -0.0024612261 | K42: -0.0025622969 | L42: -0.0024983982 | M42: -0.0023817518 | N42: -0.0025163127 | O42: -0.0027049756 | P42: -0.0029351396 | Q42: -0.0031811994 | R42: -0.0032985558 | S42: -0.0033748159 | T42: -0.0031556653 | U42: -0.003029346 | V42: -0.0029200841 | W42: -0.0029632254 | X42: -0.0029841607 | Y42: -0.0030193603 | Z42: -0.012218122 | AA42: -0.007053661 | AB42: 0.0084613687 | AC42: -0.0018256188 | AD42: -0.0024653889 | AE42: -0.0030592844 | AF42: -0.0036195899 | AG42: -0.0033320142 | AH42: -0.0031469563 | AI42: -0.0030059471 | AJ42: -0.00295074 | AK42: -0.0028066414 | AL42: -0.002720469 | AM42: -0.0026893676 | AN42: -0.0025853542 | AO42: -0.0025425288 | AP42: -0.0024875233 | AQ42: -0.0023687073 | AR42: -0.0023290149 | AS42: -0.002241437 | AT42: -0.0022413786 | AU42: -0.0022192271 | AV42: -0.0021644359 | AW42: -0.0021425068 | AX42: -0.0021206005 | AY42: -0.0020713435 | AZ42: -0.0020188737 | BA42: -0.0019846998 | BB42: -0.0019465911 | BC42: -0.0019096025 | BD42: -0.001872589 | BE42: -0.0018318144
...

Sheet Infectiousness
A1: Force of Infection constant | B1: Provenance | C1: Units | D1: Uncertainty | E1: Constant | G1: 2000 | H1: 2001 | I1: 2002 | J1: 2003 | K1: 2004 | L1: 2005 | M1: 2006 | N1: 2007 | O1: 2008 | P1: 2009 | Q1: 2010 | R1: 2011 | S1: 2012 | T1: 2013 | U1: 2014 | V1: 2015 | W1: 2016 | X1: 2017 | Y1: 2018 | Z1: 2019 | AA1: 2020 | AB1: 2021 | AC1: 2022 | AD1: 2023 | AE1: 2024 | AF1: 2025 | AG1: 2026 | AH1: 2027 | AI1: 2028 | AJ1: 2029 | AK1: 2030 | AL1: 2031 | AM1: 2032 | AN1: 2033 | AO1: 2034 | AP1: 2035 | AQ1: 2036 | AR1: 2037 | AS1: 2038 | AT1: 2039 | AU1: 2040 | AV1: 2041 | AW1: 2042 | AX1: 2043 | AY1: 2044 | AZ1: 2045 | BA1: 2046 | BB1: 2047 | BC1: 2048 | BD1: 2049 | BE1: 2050
A2: ='Population Definitions'!$A$2 -> PWID_males | C2: N.A. | E2: 0.1 | F2: OR
A3: ='Population Definitions'!$A$3 -> PWID_females | C3: N.A. | E3: 0.1 | F3: OR
A4: ='Population Definitions'!$A$4 -> 0-9_males | C4: N.A. | E4: 0 | F4: OR
A5: ='Population Definitions'!$A$5 -> 0-9_females | C5: N.A. | E5: 0 | F5: OR
A6: ='Population Definitions'!$A$6 -> 10-17_males | C6: N.A. | E6: 0 | F6: OR
A7: ='Population Definitions'!$A$7 -> 10-17_females | C7: N.A. | E7: 0 | F7: OR
A8: ='Population Definitions'!$A$8 -> 18-64_males | C8: N.A. | E8: 0 | F8: OR
A9: ='Population Definitions'!$A$9 -> 18-64_females | C9: N.A. | E9: 0 | F9: OR
A10: ='Population Definitions'!$A$10 -> 65+_males | C10: N.A. | E10: 0 | F10: OR
A11: ='Population Definitions'!$A$11 -> 65+_females | C11: N.A. | E11: 0 | F11: OR
A12: ='Population Definitions'!$A$12 -> Prisoners_males | C12: N.A. | E12: 0 | F12: OR
A13: ='Population Definitions'!$A$13 -> Prisoners_females | C13: N.A. | E13: 0 | F13: OR
A14: ='Population Definitions'!$A$14 -> Prisoners_PWID_males | C14: N.A. | E14: 0.1 | F14: OR
A15: ='Population Definitions'!$A$15 -> Prisoners_PWID_females | C15: N.A. | E15: 0.1 | F15: OR
A17: Infectivity among the general population | B17: Provenance | C17: Units | D17: Uncertainty | E17: Constant | G17: 2000 | H17: 2001 | I17: 2002 | J17: 2003 | K17: 2004 | L17: 2005 | M17: 2006 | N17: 2007 | O17: 2008 | P17: 2009 | Q17: 2010 | R17: 2011 | S17: 2012 | T17: 2013 | U17: 2014 | V17: 2015 | W17: 2016 | X17: 2017 | Y17: 2018 | Z17: 2019 | AA17: 2020 | AB17: 2021 | AC17: 2022 | AD17: 2023 | AE17: 2024 | AF17: 2025 | AG17: 2026 | AH17: 2027 | AI17: 2028 | AJ17: 2029 | AK17: 2030 | AL17: 2031 | AM17: 2032 | AN17: 2033 | AO17: 2034 | AP17: 2035 | AQ17: 2036 | AR17: 2037 | AS17: 2038 | AT17: 2039 | AU17: 2040 | AV17: 2041 | AW17: 2042 | AX17: 2043 | AY17: 2044 | AZ17: 2045 | BA17: 2046 | BB17: 2047 | BC17: 2048 | BD17: 2049 | BE17: 2050
A18: ='Population Definitions'!$A$2 -> PWID_males | C18: N.A. | E18: 0 | F18: OR
A19: ='Population Definitions'!$A$3 -> PWID_females | C19: N.A. | E19: 0 | F19: OR
A20: ='Population Definitions'!$A$4 -> 0-9_males | C20: N.A. | E20: 0 | F20: OR
A21: ='Population Definitions'!$A$5 -> 0-9_females | C21: N.A. | E21: 0 | F21: OR
A22: ='Population Definitions'!$A$6 -> 10-17_males | C22: N.A. | E22: 0 | F22: OR
A23: ='Population Definitions'!$A$7 -> 10-17_females | C23: N.A. | E23: 0 | F23: OR
A24: ='Population Definitions'!$A$8 -> 18-64_males | C24: N.A. | E24: 0.1 | F24: OR
A25: ='Population Definitions'!$A$9 -> 18-64_females | C25: N.A. | E25: 0.1 | F25: OR
A26: ='Population Definitions'!$A$10 -> 65+_males | C26: N.A. | E26: 0.1 | F26: OR
A27: ='Population Definitions'!$A$11 -> 65+_females | C27: N.A. | E27: 0.1 | F27: OR
A28: ='Population Definitions'!$A$12 -> Prisoners_males | C28: N.A. | E28: 0 | F28: OR
A29: ='Population Definitions'!$A$13 -> Prisoners_females | C29: N.A. | E29: 0 | F29: OR
A30: ='Population Definitions'!$A$14 -> Prisoners_PWID_males | C30: N.A. | E30: 0 | F30: OR
A31: ='Population Definitions'!$A$15 -> Prisoners_PWID_females | C31: N.A. | E31: 0 | F31: OR

Sheet Disease Progression
A1: Proportion of HCV infections spontaneously clearing | B1: Provenance | C1: Units | D1: Uncertainty | E1: Constant | G1: 2000 | H1: 2001 | I1: 2002 | J1: 2003 | K1: 2004 | L1: 2005 | M1: 2006 | N1: 2007 | O1: 2008 | P1: 2009 | Q1: 2010 | R1: 2011 | S1: 2012 | T1: 2013 | U1: 2014 | V1: 2015 | W1: 2016 | X1: 2017 | Y1: 2018 | Z1: 2019 | AA1: 2020 | AB1: 2021 | AC1: 2022 | AD1: 2023 | AE1: 2024 | AF1: 2025 | AG1: 2026 | AH1: 2027 | AI1: 2028 | AJ1: 2029 | AK1: 2030 | AL1: 2031 | AM1: 2032 | AN1: 2033 | AO1: 2034 | AP1: 2035 | AQ1: 2036 | AR1: 2037 | AS1: 2038 | AT1: 2039 | AU1: 2040 | AV1: 2041 | AW1: 2042 | AX1: 2043 | AY1: 2044 | AZ1: 2045 | BA1: 2046 | BB1: 2047 | BC1: 2048 | BD1: 2049 | BE1: 2050
A2: ='Population Definitions'!$A$2 -> PWID_males | C2: Proportion | D2: 0.028061224 | E2: 0.19889503 | F2: OR
A3: ='Population Definitions'!$A$3 -> PWID_females | C3: Proportion | D3: 0.033163265 | E3: 0.42105263 | F3: OR
A4: ='Population Definitions'!$A$4 -> 0-9_males | C4: Proportion | D4: 0.028061224 | E4: 0.19889503 | F4: OR
A5: ='Population Definitions'!$A$5 -> 0-9_females | C5: Proportion | D5: 0.033163265 | E5: 0.42105263 | F5: OR
A6: ='Population Definitions'!$A$6 -> 10-17_males | C6: Proportion | D6: 0.028061224 | E6: 0.19889503 | F6: OR
A7: ='Population Definitions'!$A$7 -> 10-17_females | C7: Proportion | D7: 0.033163265 | E7: 0.42105263 | F7: OR
A8: ='Population Definitions'!$A$8 -> 18-64_males | C8: Proportion | D8: 0.028061224 | E8: 0.19889503 | F8: OR
A9: ='Population Definitions'!$A$9 -> 18-64_females | C9: Proportion | D9: 0.033163265 | E9: 0.42105263 | F9: OR
A10: ='Population Definitions'!$A$10 -> 65+_males | C10: Proportion | D10: 0.028061224 | E10: 0.19889503 | F10: OR
A11: ='Population Definitions'!$A$11 -> 65+_females | C11: Proportion | D11: 0.033163265 | E11: 0.42105263 | F11: OR
A12: ='Population Definitions'!$A$12 -> Prisoners_males | C12: Proportion | D12: 0.028061224 | E12: 0.19889503 | F12: OR
A13: ='Population Definitions'!$A$13 -> Prisoners_females | C13: Proportion | D13: 0.033163265 | E13: 0.42105263 | F13: OR
A14: ='Population Definitions'!$A$14 -> Prisoners_PWID_males | C14: Proportion | D14: 0.028061224 | E14: 0.19889503 | F14: OR
A15: ='Population Definitions'!$A$15 -> Prisoners_PWID_females | C15: Proportion | D15: 0.033163265 | E15: 0.42105263 | F15: OR
A17: Average duration for spontaneous viral clearance | B17: Provenance | C17: Units | D17: Uncertainty | E17: Constant | G17: 2000 | H17: 2001 | I17: 2002 | J17: 2003 | K17: 2004 | L17: 2005 | M17: 2006 | N17: 2007 | O17: 2008 | P17: 2009 | Q17: 2010 | R17: 2011 | S17: 2012 | T17: 2013 | U17: 2014 | V17: 2015 | W17: 2016 | X17: 2017 | Y17: 2018 | Z17: 2019 | AA17: 2020 | AB17: 2021 | AC17: 2022 | AD17: 2023 | AE17: 2024 | AF17: 2025 | AG17: 2026 | AH17: 2027 | AI17: 2028 | AJ17: 2029 | AK17: 2030 | AL17: 2031 | AM17: 2032 | AN17: 2033 | AO17: 2034 | AP17: 2035 | AQ17: 2036 | AR17: 2037 | AS17: 2038 | AT17: 2039 | AU17: 2040 | AV17: 2041 | AW17: 2042 | AX17: 2043 | AY17: 2044 | AZ17: 2045 | BA17: 2046 | BB17: 2047 | BC17: 2048 | BD17: 2049 | BE17: 2050
A18: ='Population Definitions'!$A$2 -> PWID_males | B18: Framework-supplied default | C18: Duration (years) | E18: 1 | F18: OR
A19: ='Population Definitions'!$A$3 -> PWID_females | B19: Framework-supplied default | C19: Duration (years) | E19: 1 | F19: OR
A20: ='Population Definitions'!$A$4 -> 0-9_males | B20: Framework-supplied default | C20: Duration (years) | E20: 1 | F20: OR
A21: ='Population Definitions'!$A$5 -> 0-9_females | B21: Framework-supplied default | C21: Duration (years) | E21: 1 | F21: OR
A22: ='Population Definitions'!$A$6 -> 10-17_males | B22: Framework-supplied default | C22: Duration (years) | E22: 1 | F22: OR
A23: ='Population Definitions'!$A$7 -> 10-17_females | B23: Framework-supplied default | C23: Duration (years) | E23: 1 | F23: OR
A24: ='Population Definitions'!$A$8 -> 18-64_males | B24: Framework-supplied default | C24: Duration (years) | E24: 1 | F24: OR
A25: ='Population Definitions'!$A$9 -> 18-64_females | B25: Framework-supplied default | C25: Duration (years) | E25: 1 | F25: OR
A26: ='Population Definitions'!$A$10 -> 65+_males | B26: Framework-supplied default | C26: Duration (years) | E26: 1 | F26: OR
A27: ='Population Definitions'!$A$11 -> 65+_females | B27: Framework-supplied default | C27: Duration (years) | E27: 1 | F27: OR
A28: ='Population Definitions'!$A$12 -> Prisoners_males | B28: Framework-supplied default | C28: Duration (years) | E28: 1 | F28: OR
A29: ='Population Definitions'!$A$13 -> Prisoners_females | B29: Framework-supplied default | C29: Duration (years) | E29: 1 | F29: OR
A30: ='Population Definitions'!$A$14 -> Prisoners_PWID_males | B30: Framework-supplied default | C30: Duration (years) | E30: 1 | F30: OR
A31: ='Population Definitions'!$A$15 -> Prisoners_PWID_females | B31: Framework-supplied default | C31: Duration (years) | E31: 1 | F31: OR
A33: F0 to F1 progression rate (intermediate step) | B33: Provenance | C33: Units | D33: Uncertainty | E33: Constant | G33: 2000 | H33: 2001 | I33: 2002 | J33: 2003 | K33: 2004 | L33: 2005 | M33: 2006 | N33: 2007 | O33: 2008 | P33: 2009 | Q33: 2010 | R33: 2011 | S33: 2012 | T33: 2013 | U33: 2014 | V33: 2015 | W33: 2016 | X33: 2017 | Y33: 2018 | Z33: 2019 | AA33: 2020 | AB33: 2021 | AC33: 2022 | AD33: 2023 | AE33: 2024 | AF33: 2025 | AG33: 2026 | AH33: 2027 | AI33: 2028 | AJ33: 2029 | AK33: 2030 | AL33: 2031 | AM33: 2032 | AN33: 2033 | AO33: 2034 | AP33: 2035 | AQ33: 2036 | AR33: 2037 | AS33: 2038 | AT33: 2039 | AU33: 2040 | AV33: 2041 | AW33: 2042 | AX33: 2043 | AY33: 2044 | AZ33: 2045 | BA33: 2046 | BB33: 2047 | BC33: 2048 | BD33: 2049 | BE33: 2050
A34: ='Population Definitions'!$A$2 -> PWID_males | C34: Rate (per year) | D34: 0.094387755 | E34: 0.25 | F34: OR
A35: ='Population Definitions'!$A$3 -> PWID_females | C35: Rate (per year) | D35: 0.094387755 | E35: 0.25 | F35: OR
A36: ='Population Definitions'!$A$4 -> 0-9_males | C36: Rate (per year) | D36: 0.094387755 | E36: 0.25 | F36: OR
A37: ='Population Definitions'!$A$5 -> 0-9_females | C37: Rate (per year) | D37: 0.094387755 | E37: 0.25 | F37: OR
A38: ='Population Definitions'!$A$6 -> 10-17_males | C38: Rate (per year) | D38: 0.094387755 | E38: 0.25 | F38: OR
A39: ='Population Definitions'!$A$7 -> 10-17_females | C39: Rate (per year) | D39: 0.094387755 | E39: 0.25 | F39: OR
A40: ='Population Definitions'!$A$8 -> 18-64_males | C40: Rate (per year) | D40: 0.094387755 | E40: 0.25 | F40: OR
A41: ='Population Definitions'!$A$9 -> 18-64_females | C41: Rate (per year) | D41: 0.094387755 | E41: 0.25 | F41: OR
A42: ='Population Definitions'!$A$10 -> 65+_males | C42: Rate (per year) | D42: 0.094387755 | E42: 0.25 | F42: OR
...

Sheet Diagnosis
A1: Antibody testing rate in F0-F2, undiagnosed, in care (intermediate step) | B1: Provenance | C1: Units | D1: Uncertainty | E1: Constant | G1: 2000 | H1: 2001 | I1: 2002 | J1: 2003 | K1: 2004 | L1: 2005 | M1: 2006 | N1: 2007 | O1: 2008 | P1: 2009 | Q1: 2010 | R1: 2011 | S1: 2012 | T1: 2013 | U1: 2014 | V1: 2015 | W1: 2016 | X1: 2017 | Y1: 2018 | Z1: 2019 | AA1: 2020 | AB1: 2021 | AC1: 2022 | AD1: 2023 | AE1: 2024 | AF1: 2025 | AG1: 2026 | AH1: 2027 | AI1: 2028 | AJ1: 2029 | AK1: 2030 | AL1: 2031 | AM1: 2032 | AN1: 2033 | AO1: 2034 | AP1: 2035 | AQ1: 2036 | AR1: 2037 | AS1: 2038 | AT1: 2039 | AU1: 2040 | AV1: 2041 | AW1: 2042 | AX1: 2043 | AY1: 2044 | AZ1: 2045 | BA1: 2046 | BB1: 2047 | BC1: 2048 | BD1: 2049 | BE1: 2050
A2: ='Population Definitions'!$A$2 -> PWID_males | C2: Rate (per year) | D2: 0.025765306 | F2: OR | G2: 0.05175 | V2: 0.1035 | AA2: 1
A3: ='Population Definitions'!$A$3 -> PWID_females | C3: Rate (per year) | D3: 0.025765306 | F3: OR | G3: 0.05175 | V3: 0.1035 | AA3: 1
A4: ='Population Definitions'!$A$4 -> 0-9_males | C4: Rate (per year) | F4: OR | G4: 0.01 | V4: 0.8 | AA4: 1
A5: ='Population Definitions'!$A$5 -> 0-9_females | C5: Rate (per year) | F5: OR | G5: 0.01 | V5: 0.8 | AA5: 1
A6: ='Population Definitions'!$A$6 -> 10-17_males | C6: Rate (per year) | F6: OR | G6: 0.01 | V6: 0.8 | AA6: 1
A7: ='Population Definitions'!$A$7 -> 10-17_females | C7: Rate (per year) | F7: OR | G7: 0.01 | V7: 0.8 | AA7: 1
A8: ='Population Definitions'!$A$8 -> 18-64_males | C8: Rate (per year) | F8: OR | G8: 0.05 | V8: 0.8 | AA8: 1
A9: ='Population Definitions'!$A$9 -> 18-64_females | C9: Rate (per year) | F9: OR | G9: 0.05 | V9: 0.8 | AA9: 1
A10: ='Population Definitions'!$A$10 -> 65+_males | C10: Rate (per year) | F10: OR | G10: 0.05 | V10: 0.8 | AA10: 1
A11: ='Population Definitions'!$A$11 -> 65+_females | C11: Rate (per year) | F11: OR | G11: 0.05 | V11: 0.8 | AA11: 1
A12: ='Population Definitions'!$A$12 -> Prisoners_males | C12: Rate (per year) | E12: 0 | F12: OR
A13: ='Population Definitions'!$A$13 -> Prisoners_females | C13: Rate (per year) | E13: 0 | F13: OR
A14: ='Population Definitions'!$A$14 -> Prisoners_PWID_males | C14: Rate (per year) | E14: 0 | F14: OR
A15: ='Population Definitions'!$A$15 -> Prisoners_PWID_females | C15: Rate (per year) | E15: 0 | F15: OR
A17: Antibody testing rate in F3+, undiagnosed, in care (intermediate step) | B17: Provenance | C17: Units | D17: Uncertainty | E17: Constant | G17: 2000 | H17: 2001 | I17: 2002 | J17: 2003 | K17: 2004 | L17: 2005 | M17: 2006 | N17: 2007 | O17: 2008 | P17: 2009 | Q17: 2010 | R17: 2011 | S17: 2012 | T17: 2013 | U17: 2014 | V17: 2015 | W17: 2016 | X17: 2017 | Y17: 2018 | Z17: 2019 | AA17: 2020 | AB17: 2021 | AC17: 2022 | AD17: 2023 | AE17: 2024 | AF17: 2025 | AG17: 2026 | AH17: 2027 | AI17: 2028 | AJ17: 2029 | AK17: 2030 | AL17: 2031 | AM17: 2032 | AN17: 2033 | AO17: 2034 | AP17: 2035 | AQ17: 2036 | AR17: 2037 | AS17: 2038 | AT17: 2039 | AU17: 2040 | AV17: 2041 | AW17: 2042 | AX17: 2043 | AY17: 2044 | AZ17: 2045 | BA17: 2046 | BB17: 2047 | BC17: 2048 | BD17: 2049 | BE17: 2050
A18: ='Population Definitions'!$A$2 -> PWID_males | C18: Rate (per year) | D18: 0.025765306 | F18: OR | G18: 0.05175 | V18: 0.1035 | AA18: 1
A19: ='Population Definitions'!$A$3 -> PWID_females | C19: Rate (per year) | D19: 0.025765306 | F19: OR | G19: 0.05175 | V19: 0.1035 | AA19: 1
A20: ='Population Definitions'!$A$4 -> 0-9_males | C20: Rate (per year) | F20: OR | G20: 0.01 | V20: 0.8 | AA20: 1
A21: ='Population Definitions'!$A$5 -> 0-9_females | C21: Rate (per year) | F21: OR | G21: 0.01 | V21: 0.8 | AA21: 1
A22: ='Population Definitions'!$A$6 -> 10-17_males | C22: Rate (per year) | F22: OR | G22: 0.01 | V22: 0.8 | AA22: 1
A23: ='Population Definitions'!$A$7 -> 10-17_females | C23: Rate (per year) | F23: OR | G23: 0.01 | V23: 0.8 | AA23: 1
A24: ='Population Definitions'!$A$8 -> 18-64_males | C24: Rate (per year) | F24: OR | G24: 0.05 | V24: 0.8 | AA24: 1
A25: ='Population Definitions'!$A$9 -> 18-64_females | C25: Rate (per year) | F25: OR | G25: 0.05 | V25: 0.8 | AA25: 1
A26: ='Population Definitions'!$A$10 -> 65+_males | C26: Rate (per year) | F26: OR | G26: 0.05 | V26: 0.8 | AA26: 1
A27: ='Population Definitions'!$A$11 -> 65+_females | C27: Rate (per year) | F27: OR | G27: 0.05 | V27: 0.8 | AA27: 1
A28: ='Population Definitions'!$A$12 -> Prisoners_males | C28: Rate (per year) | E28: 0 | F28: OR
A29: ='Population Definitions'!$A$13 -> Prisoners_females | C29: Rate (per year) | E29: 0 | F29: OR
A30: ='Population Definitions'!$A$14 -> Prisoners_PWID_males | C30: Rate (per year) | E30: 0 | F30: OR
A31: ='Population Definitions'!$A$15 -> Prisoners_PWID_females | C31: Rate (per year) | E31: 0 | F31: OR
A33: RNA testing rate in F0-F2, Ab diagnosed, in care (intermediate step) | B33: Provenance | C33: Units | D33: Uncertainty | E33: Constant | G33: 2000 | H33: 2001 | I33: 2002 | J33: 2003 | K33: 2004 | L33: 2005 | M33: 2006 | N33: 2007 | O33: 2008 | P33: 2009 | Q33: 2010 | R33: 2011 | S33: 2012 | T33: 2013 | U33: 2014 | V33: 2015 | W33: 2016 | X33: 2017 | Y33: 2018 | Z33: 2019 | AA33: 2020 | AB33: 2021 | AC33: 2022 | AD33: 2023 | AE33: 2024 | AF33: 2025 | AG33: 2026 | AH33: 2027 | AI33: 2028 | AJ33: 2029 | AK33: 2030 | AL33: 2031 | AM33: 2032 | AN33: 2033 | AO33: 2034 | AP33: 2035 | AQ33: 2036 | AR33: 2037 | AS33: 2038 | AT33: 2039 | AU33: 2040 | AV33: 2041 | AW33: 2042 | AX33: 2043 | AY33: 2044 | AZ33: 2045 | BA33: 2046 | BB33: 2047 | BC33: 2048 | BD33: 2049 | BE33: 2050
A34: ='Population Definitions'!$A$2 -> PWID_males | C34: Rate (per year) | F34: OR | G34: 0.4 | V34: 1
A35: ='Population Definitions'!$A$3 -> PWID_females | C35: Rate (per year) | F35: OR | G35: 0.4 | V35: 1
A36: ='Population Definitions'!$A$4 -> 0-9_males | C36: Rate (per year) | F36: OR | G36: 0.4 | V36: 1
A37: ='Population Definitions'!$A$5 -> 0-9_females | C37: Rate (per year) | F37: OR | G37: 0.4 | V37: 1
A38: ='Population Definitions'!$A$6 -> 10-17_males | C38: Rate (per year) | F38: OR | G38: 0.4 | V38: 1
A39: ='Population Definitions'!$A$7 -> 10-17_females | C39: Rate (per year) | F39: OR | G39: 0.4 | V39: 1
A40: ='Population Definitions'!$A$8 -> 18-64_males | C40: Rate (per year) | F40: OR | G40: 0.4 | V40: 1
A41: ='Population Definitions'!$A$9 -> 18-64_females | C41: Rate (per year) | F41: OR | G41: 0.4 | V41: 1
A42: ='Population Definitions'!$A$10 -> 65+_males | C42: Rate (per year) | F42: OR | G42: 0.4 | V42: 1
...

Sheet Loss to follow-up
A1: Loss to follow-up rate on antibody test in F0-F2 | B1: Provenance | C1: Units | D1: Uncertainty | E1: Constant | G1: 2000 | H1: 2001 | I1: 2002 | J1: 2003 | K1: 2004 | L1: 2005 | M1: 2006 | N1: 2007 | O1: 2008 | P1: 2009 | Q1: 2010 | R1: 2011 | S1: 2012 | T1: 2013 | U1: 2014 | V1: 2015 | W1: 2016 | X1: 2017 | Y1: 2018 | Z1: 2019 | AA1: 2020 | AB1: 2021 | AC1: 2022 | AD1: 2023 | AE1: 2024 | AF1: 2025 | AG1: 2026 | AH1: 2027 | AI1: 2028 | AJ1: 2029 | AK1: 2030 | AL1: 2031 | AM1: 2032 | AN1: 2033 | AO1: 2034 | AP1: 2035 | AQ1: 2036 | AR1: 2037 | AS1: 2038 | AT1: 2039 | AU1: 2040 | AV1: 2041 | AW1: 2042 | AX1: 2043 | AY1: 2044 | AZ1: 2045 | BA1: 2046 | BB1: 2047 | BC1: 2048 | BD1: 2049 | BE1: 2050
A2: ='Population Definitions'!$A$2 -> PWID_males | B2: Framework-supplied default | C2: Proportion | E2: 0 | F2: OR
A3: ='Population Definitions'!$A$3 -> PWID_females | B3: Framework-supplied default | C3: Proportion | E3: 0 | F3: OR
A4: ='Population Definitions'!$A$4 -> 0-9_males | B4: Framework-supplied default | C4: Proportion | E4: 0 | F4: OR
A5: ='Population Definitions'!$A$5 -> 0-9_females | B5: Framework-supplied default | C5: Proportion | E5: 0 | F5: OR
A6: ='Population Definitions'!$A$6 -> 10-17_males | B6: Framework-supplied default | C6: Proportion | E6: 0 | F6: OR
A7: ='Population Definitions'!$A$7 -> 10-17_females | B7: Framework-supplied default | C7: Proportion | E7: 0 | F7: OR
A8: ='Population Definitions'!$A$8 -> 18-64_males | B8: Framework-supplied default | C8: Proportion | E8: 0 | F8: OR
A9: ='Population Definitions'!$A$9 -> 18-64_females | B9: Framework-supplied default | C9: Proportion | E9: 0 | F9: OR
A10: ='Population Definitions'!$A$10 -> 65+_males | B10: Framework-supplied default | C10: Proportion | E10: 0 | F10: OR
A11: ='Population Definitions'!$A$11 -> 65+_females | B11: Framework-supplied default | C11: Proportion | E11: 0 | F11: OR
A12: ='Population Definitions'!$A$12 -> Prisoners_males | B12: Framework-supplied default | C12: Proportion | E12: 0 | F12: OR
A13: ='Population Definitions'!$A$13 -> Prisoners_females | B13: Framework-supplied default | C13: Proportion | E13: 0 | F13: OR
A14: ='Population Definitions'!$A$14 -> Prisoners_PWID_males | B14: Framework-supplied default | C14: Proportion | E14: 0 | F14: OR
A15: ='Population Definitions'!$A$15 -> Prisoners_PWID_females | B15: Framework-supplied default | C15: Proportion | E15: 0 | F15: OR
A17: Loss to follow-up rate on antibody test in F3+ | B17: Provenance | C17: Units | D17: Uncertainty | E17: Constant | G17: 2000 | H17: 2001 | I17: 2002 | J17: 2003 | K17: 2004 | L17: 2005 | M17: 2006 | N17: 2007 | O17: 2008 | P17: 2009 | Q17: 2010 | R17: 2011 | S17: 2012 | T17: 2013 | U17: 2014 | V17: 2015 | W17: 2016 | X17: 2017 | Y17: 2018 | Z17: 2019 | AA17: 2020 | AB17: 2021 | AC17: 2022 | AD17: 2023 | AE17: 2024 | AF17: 2025 | AG17: 2026 | AH17: 2027 | AI17: 2028 | AJ17: 2029 | AK17: 2030 | AL17: 2031 | AM17: 2032 | AN17: 2033 | AO17: 2034 | AP17: 2035 | AQ17: 2036 | AR17: 2037 | AS17: 2038 | AT17: 2039 | AU17: 2040 | AV17: 2041 | AW17: 2042 | AX17: 2043 | AY17: 2044 | AZ17: 2045 | BA17: 2046 | BB17: 2047 | BC17: 2048 | BD17: 2049 | BE17: 2050
A18: ='Population Definitions'!$A$2 -> PWID_males | B18: Framework-supplied default | C18: Proportion | E18: 0 | F18: OR
A19: ='Population Definitions'!$A$3 -> PWID_females | B19: Framework-supplied default | C19: Proportion | E19: 0 | F19: OR
A20: ='Population Definitions'!$A$4 -> 0-9_males | B20: Framework-supplied default | C20: Proportion | E20: 0 | F20: OR
A21: ='Population Definitions'!$A$5 -> 0-9_females | B21: Framework-supplied default | C21: Proportion | E21: 0 | F21: OR
A22: ='Population Definitions'!$A$6 -> 10-17_males | B22: Framework-supplied default | C22: Proportion | E22: 0 | F22: OR
A23: ='Population Definitions'!$A$7 -> 10-17_females | B23: Framework-supplied default | C23: Proportion | E23: 0 | F23: OR
A24: ='Population Definitions'!$A$8 -> 18-64_males | B24: Framework-supplied default | C24: Proportion | E24: 0 | F24: OR
A25: ='Population Definitions'!$A$9 -> 18-64_females | B25: Framework-supplied default | C25: Proportion | E25: 0 | F25: OR
A26: ='Population Definitions'!$A$10 -> 65+_males | B26: Framework-supplied default | C26: Proportion | E26: 0 | F26: OR
A27: ='Population Definitions'!$A$11 -> 65+_females | B27: Framework-supplied default | C27: Proportion | E27: 0 | F27: OR
A28: ='Population Definitions'!$A$12 -> Prisoners_males | B28: Framework-supplied default | C28: Proportion | E28: 0 | F28: OR
A29: ='Population Definitions'!$A$13 -> Prisoners_females | B29: Framework-supplied default | C29: Proportion | E29: 0 | F29: OR
A30: ='Population Definitions'!$A$14 -> Prisoners_PWID_males | B30: Framework-supplied default | C30: Proportion | E30: 0 | F30: OR
A31: ='Population Definitions'!$A$15 -> Prisoners_PWID_females | B31: Framework-supplied default | C31: Proportion | E31: 0 | F31: OR
A33: Loss to follow-up rate on PCR test in F0-F2 | B33: Provenance | C33: Units | D33: Uncertainty | E33: Constant | G33: 2000 | H33: 2001 | I33: 2002 | J33: 2003 | K33: 2004 | L33: 2005 | M33: 2006 | N33: 2007 | O33: 2008 | P33: 2009 | Q33: 2010 | R33: 2011 | S33: 2012 | T33: 2013 | U33: 2014 | V33: 2015 | W33: 2016 | X33: 2017 | Y33: 2018 | Z33: 2019 | AA33: 2020 | AB33: 2021 | AC33: 2022 | AD33: 2023 | AE33: 2024 | AF33: 2025 | AG33: 2026 | AH33: 2027 | AI33: 2028 | AJ33: 2029 | AK33: 2030 | AL33: 2031 | AM33: 2032 | AN33: 2033 | AO33: 2034 | AP33: 2035 | AQ33: 2036 | AR33: 2037 | AS33: 2038 | AT33: 2039 | AU33: 2040 | AV33: 2041 | AW33: 2042 | AX33: 2043 | AY33: 2044 | AZ33: 2045 | BA33: 2046 | BB33: 2047 | BC33: 2048 | BD33: 2049 | BE33: 2050
A34: ='Population Definitions'!$A$2 -> PWID_males | B34: Framework-supplied default | C34: Proportion | E34: 0 | F34: OR
A35: ='Population Definitions'!$A$3 -> PWID_females | B35: Framework-supplied default | C35: Proportion | E35: 0 | F35: OR
A36: ='Population Definitions'!$A$4 -> 0-9_males | B36: Framework-supplied default | C36: Proportion | E36: 0 | F36: OR
A37: ='Population Definitions'!$A$5 -> 0-9_females | B37: Framework-supplied default | C37: Proportion | E37: 0 | F37: OR
A38: ='Population Definitions'!$A$6 -> 10-17_males | B38: Framework-supplied default | C38: Proportion | E38: 0 | F38: OR
A39: ='Population Definitions'!$A$7 -> 10-17_females | B39: Framework-supplied default | C39: Proportion | E39: 0 | F39: OR
A40: ='Population Definitions'!$A$8 -> 18-64_males | B40: Framework-supplied default | C40: Proportion | E40: 0 | F40: OR
A41: ='Population Definitions'!$A$9 -> 18-64_females | B41: Framework-supplied default | C41: Proportion | E41: 0 | F41: OR
A42: ='Population Definitions'!$A$10 -> 65+_males | B42: Framework-supplied default | C42: Proportion | E42: 0 | F42: OR
...

Sheet Re-engagement
A1: Antibody re-engagement in care, F0-F2, lost to follow-up after Ab test | B1: Provenance | C1: Units | D1: Uncertainty | E1: Constant | G1: 2000 | H1: 2001 | I1: 2002 | J1: 2003 | K1: 2004 | L1: 2005 | M1: 2006 | N1: 2007 | O1: 2008 | P1: 2009 | Q1: 2010 | R1: 2011 | S1: 2012 | T1: 2013 | U1: 2014 | V1: 2015 | W1: 2016 | X1: 2017 | Y1: 2018 | Z1: 2019 | AA1: 2020 | AB1: 2021 | AC1: 2022 | AD1: 2023 | AE1: 2024 | AF1: 2025 | AG1: 2026 | AH1: 2027 | AI1: 2028 | AJ1: 2029 | AK1: 2030 | AL1: 2031 | AM1: 2032 | AN1: 2033 | AO1: 2034 | AP1: 2035 | AQ1: 2036 | AR1: 2037 | AS1: 2038 | AT1: 2039 | AU1: 2040 | AV1: 2041 | AW1: 2042 | AX1: 2043 | AY1: 2044 | AZ1: 2045 | BA1: 2046 | BB1: 2047 | BC1: 2048 | BD1: 2049 | BE1: 2050
A2: ='Population Definitions'!$A$2 -> PWID_males | B2: Framework-supplied default | C2: Rate (per year) | E2: 0 | F2: OR
A3: ='Population Definitions'!$A$3 -> PWID_females | B3: Framework-supplied default | C3: Rate (per year) | E3: 0 | F3: OR
A4: ='Population Definitions'!$A$4 -> 0-9_males | B4: Framework-supplied default | C4: Rate (per year) | E4: 0 | F4: OR
A5: ='Population Definitions'!$A$5 -> 0-9_females | B5: Framework-supplied default | C5: Rate (per year) | E5: 0 | F5: OR
A6: ='Population Definitions'!$A$6 -> 10-17_males | B6: Framework-supplied default | C6: Rate (per year) | E6: 0 | F6: OR
A7: ='Population Definitions'!$A$7 -> 10-17_females | B7: Framework-supplied default | C7: Rate (per year) | E7: 0 | F7: OR
A8: ='Population Definitions'!$A$8 -> 18-64_males | B8: Framework-supplied default | C8: Rate (per year) | E8: 0 | F8: OR
A9: ='Population Definitions'!$A$9 -> 18-64_females | B9: Framework-supplied default | C9: Rate (per year) | E9: 0 | F9: OR
A10: ='Population Definitions'!$A$10 -> 65+_males | B10: Framework-supplied default | C10: Rate (per year) | E10: 0 | F10: OR
A11: ='Population Definitions'!$A$11 -> 65+_females | B11: Framework-supplied default | C11: Rate (per year) | E11: 0 | F11: OR
A12: ='Population Definitions'!$A$12 -> Prisoners_males | B12: Framework-supplied default | C12: Rate (per year) | E12: 0 | F12: OR
A13: ='Population Definitions'!$A$13 -> Prisoners_females | B13: Framework-supplied default | C13: Rate (per year) | E13: 0 | F13: OR
A14: ='Population Definitions'!$A$14 -> Prisoners_PWID_males | B14: Framework-supplied default | C14: Rate (per year) | E14: 0 | F14: OR
A15: ='Population Definitions'!$A$15 -> Prisoners_PWID_females | B15: Framework-supplied default | C15: Rate (per year) | E15: 0 | F15: OR
A17: Antibody re-engagement in care, F3+, lost to follow-up after Ab test | B17: Provenance | C17: Units | D17: Uncertainty | E17: Constant | G17: 2000 | H17: 2001 | I17: 2002 | J17: 2003 | K17: 2004 | L17: 2005 | M17: 2006 | N17: 2007 | O17: 2008 | P17: 2009 | Q17: 2010 | R17: 2011 | S17: 2012 | T17: 2013 | U17: 2014 | V17: 2015 | W17: 2016 | X17: 2017 | Y17: 2018 | Z17: 2019 | AA17: 2020 | AB17: 2021 | AC17: 2022 | AD17: 2023 | AE17: 2024 | AF17: 2025 | AG17: 2026 | AH17: 2027 | AI17: 2028 | AJ17: 2029 | AK17: 2030 | AL17: 2031 | AM17: 2032 | AN17: 2033 | AO17: 2034 | AP17: 2035 | AQ17: 2036 | AR17: 2037 | AS17: 2038 | AT17: 2039 | AU17: 2040 | AV17: 2041 | AW17: 2042 | AX17: 2043 | AY17: 2044 | AZ17: 2045 | BA17: 2046 | BB17: 2047 | BC17: 2048 | BD17: 2049 | BE17: 2050
A18: ='Population Definitions'!$A$2 -> PWID_males | B18: Framework-supplied default | C18: Rate (per year) | E18: 0 | F18: OR
A19: ='Population Definitions'!$A$3 -> PWID_females | B19: Framework-supplied default | C19: Rate (per year) | E19: 0 | F19: OR
A20: ='Population Definitions'!$A$4 -> 0-9_males | B20: Framework-supplied default | C20: Rate (per year) | E20: 0 | F20: OR
A21: ='Population Definitions'!$A$5 -> 0-9_females | B21: Framework-supplied default | C21: Rate (per year) | E21: 0 | F21: OR
A22: ='Population Definitions'!$A$6 -> 10-17_males | B22: Framework-supplied default | C22: Rate (per year) | E22: 0 | F22: OR
A23: ='Population Definitions'!$A$7 -> 10-17_females | B23: Framework-supplied default | C23: Rate (per year) | E23: 0 | F23: OR
A24: ='Population Definitions'!$A$8 -> 18-64_males | B24: Framework-supplied default | C24: Rate (per year) | E24: 0 | F24: OR
A25: ='Population Definitions'!$A$9 -> 18-64_females | B25: Framework-supplied default | C25: Rate (per year) | E25: 0 | F25: OR
A26: ='Population Definitions'!$A$10 -> 65+_males | B26: Framework-supplied default | C26: Rate (per year) | E26: 0 | F26: OR
A27: ='Population Definitions'!$A$11 -> 65+_females | B27: Framework-supplied default | C27: Rate (per year) | E27: 0 | F27: OR
A28: ='Population Definitions'!$A$12 -> Prisoners_males | B28: Framework-supplied default | C28: Rate (per year) | E28: 0 | F28: OR
A29: ='Population Definitions'!$A$13 -> Prisoners_females | B29: Framework-supplied default | C29: Rate (per year) | E29: 0 | F29: OR
A30: ='Population Definitions'!$A$14 -> Prisoners_PWID_males | B30: Framework-supplied default | C30: Rate (per year) | E30: 0 | F30: OR
A31: ='Population Definitions'!$A$15 -> Prisoners_PWID_females | B31: Framework-supplied default | C31: Rate (per year) | E31: 0 | F31: OR
A33: RNA re-engagement in care, F0-F2, lost to follow up after RNA test | B33: Provenance | C33: Units | D33: Uncertainty | E33: Constant | G33: 2000 | H33: 2001 | I33: 2002 | J33: 2003 | K33: 2004 | L33: 2005 | M33: 2006 | N33: 2007 | O33: 2008 | P33: 2009 | Q33: 2010 | R33: 2011 | S33: 2012 | T33: 2013 | U33: 2014 | V33: 2015 | W33: 2016 | X33: 2017 | Y33: 2018 | Z33: 2019 | AA33: 2020 | AB33: 2021 | AC33: 2022 | AD33: 2023 | AE33: 2024 | AF33: 2025 | AG33: 2026 | AH33: 2027 | AI33: 2028 | AJ33: 2029 | AK33: 2030 | AL33: 2031 | AM33: 2032 | AN33: 2033 | AO33: 2034 | AP33: 2035 | AQ33: 2036 | AR33: 2037 | AS33: 2038 | AT33: 2039 | AU33: 2040 | AV33: 2041 | AW33: 2042 | AX33: 2043 | AY33: 2044 | AZ33: 2045 | BA33: 2046 | BB33: 2047 | BC33: 2048 | BD33: 2049 | BE33: 2050
A34: ='Population Definitions'!$A$2 -> PWID_males | B34: Framework-supplied default | C34: Rate (per year) | E34: 0 | F34: OR
A35: ='Population Definitions'!$A$3 -> PWID_females | B35: Framework-supplied default | C35: Rate (per year) | E35: 0 | F35: OR
A36: ='Population Definitions'!$A$4 -> 0-9_males | B36: Framework-supplied default | C36: Rate (per year) | E36: 0 | F36: OR
A37: ='Population Definitions'!$A$5 -> 0-9_females | B37: Framework-supplied default | C37: Rate (per year) | E37: 0 | F37: OR
A38: ='Population Definitions'!$A$6 -> 10-17_males | B38: Framework-supplied default | C38: Rate (per year) | E38: 0 | F38: OR
A39: ='Population Definitions'!$A$7 -> 10-17_females | B39: Framework-supplied default | C39: Rate (per year) | E39: 0 | F39: OR
A40: ='Population Definitions'!$A$8 -> 18-64_males | B40: Framework-supplied default | C40: Rate (per year) | E40: 0 | F40: OR
A41: ='Population Definitions'!$A$9 -> 18-64_females | B41: Framework-supplied default | C41: Rate (per year) | E41: 0 | F41: OR
A42: ='Population Definitions'!$A$10 -> 65+_males | B42: Framework-supplied default | C42: Rate (per year) | E42: 0 | F42: OR
...

Sheet Treatment
A1: Proportion of treatments allocated to each population pre-DAA | B1: Provenance | C1: Units | D1: Uncertainty | E1: Constant | G1: 2000 | H1: 2001 | I1: 2002 | J1: 2003 | K1: 2004 | L1: 2005 | M1: 2006 | N1: 2007 | O1: 2008 | P1: 2009 | Q1: 2010 | R1: 2011 | S1: 2012 | T1: 2013 | U1: 2014 | V1: 2015 | W1: 2016 | X1: 2017 | Y1: 2018 | Z1: 2019 | AA1: 2020 | AB1: 2021 | AC1: 2022 | AD1: 2023 | AE1: 2024 | AF1: 2025 | AG1: 2026 | AH1: 2027 | AI1: 2028 | AJ1: 2029 | AK1: 2030 | AL1: 2031 | AM1: 2032 | AN1: 2033 | AO1: 2034 | AP1: 2035 | AQ1: 2036 | AR1: 2037 | AS1: 2038 | AT1: 2039 | AU1: 2040 | AV1: 2041 | AW1: 2042 | AX1: 2043 | AY1: 2044 | AZ1: 2045 | BA1: 2046 | BB1: 2047 | BC1: 2048 | BD1: 2049 | BE1: 2050
A2: ='Population Definitions'!$A$2 -> PWID_males | C2: N.A. | E2: 0 | F2: OR
A3: ='Population Definitions'!$A$3 -> PWID_females | C3: N.A. | E3: 0 | F3: OR
A4: ='Population Definitions'!$A$4 -> 0-9_males | C4: N.A. | F4: OR | G4: 0 | U4: 0 | V4: 0
A5: ='Population Definitions'!$A$5 -> 0-9_females | C5: N.A. | F5: OR | G5: 0 | U5: 0 | V5: 0
