Workbook

Sheet Program targeting
C1: Targeted to (populations) | P1: Targeted to (compartments)
A2: Abbreviation | B2: Display name | C2: People Who Inject Drugs (males) | D2: People Who Inject Drugs (females) | E2: General Population 0-9 males | F2: General Population 0-9 females | G2: General Population 10-17 males | H2: General Population 10-17 females | I2: General Population 18-64 males | J2: General Population 18-64 females | K2: General Population 65+ males | L2: General Population 65+ females | M2: Prisoners (males) | N2: Prisoners (females) | P2: Susceptible: never infected | Q2: Liver Fibrosis F0: susceptible with antibodies (unaware) | R2: Liver Fibrosis F0: susceptible with antibodies (aware) | S2: Liver Fibrosis F0: acute, undiagnosed antibody positive | T2: Liver Fibrosis F0: acute, diagnosed antibody positive (first infection, aware) | U2: Liver Fibrosis F0: chronic, undiagnosed antibodies positive | V2: Liver Fibrosis F0: chronic, undiagnosed, lost to care | W2: Liver Fibrosis F0: chronic, diagnosed antibodies positive | X2: Liver Fibrosis F0: chronic, diagnosed antibodies positive, lost to follow-up | Y2: Liver Fibrosis F0: chronic, diagnosed positive-strand RNA (PCR test) | Z2: Liver Fibrosis F0: chronic, diagnosed positive-strand RNA, lost to follow-up | AA2: Liver Fibrosis F0: chronic, on treatment 1 | AB2: Liver Fibrosis F0: chronic, failed treatment 1 | AC2: Liver Fibrosis F0: chronic, failed treatment 1, lost to follow-up | AD2: Liver Fibrosis F0: susceptible with antibodies (aware and treated) | AE2: Liver Fibrosis F0: acute (re-infection) | AF2: Liver Fibrosis F0: chronic, on treatment 2 | AG2: Liver Fibrosis F0: chronic, failed treatment 2 | AH2: Liver Fibrosis F1: chronic, undiagnosed antibodies positive | AI2: Liver Fibrosis F1: chronic, undiagnosed, lost to care | AJ2: Liver Fibrosis F1: chronic, diagnosed antibodies positive | AK2: Liver Fibrosis F1: chronic, diagnosed antibodies positive, lost to follow-up | AL2: Liver Fibrosis F1: chronic, diagnosed positive-strand RNA (PCR test) | AM2: Liver Fibrosis F1: chronic, diagnosed positive-strand RNA, lost to follow-up | AN2: Liver Fibrosis F1: chronic, on treatment 1 | AO2: Liver Fibrosis F1: chronic, failed treatment 1 | AP2: Liver Fibrosis F1: chronic, failed treatment 1, lost to follow-up | AQ2: Liver Fibrosis F1: susceptible with antibodies (aware and treated) | AR2: Liver Fibrosis F1: acute (re-infection) | AS2: Liver Fibrosis F1: chronic, on treatment 2 | AT2: Liver Fibrosis F1: chronic, failed treatment 2 | AU2: Liver Fibrosis F2: chronic, undiagnosed antibodies positive | AV2: Liver Fibrosis F2: chronic, undiagnosed, lost to care | AW2: Liver Fibrosis F2: chronic, diagnosed antibodies positive | AX2: Liver Fibrosis F2: chronic, diagnosed antibodies positive, lost to follow-up | AY2: Liver Fibrosis F2: chronic, diagnosed positive-strand RNA (PCR test) | AZ2: Liver Fibrosis F2: chronic, diagnosed positive-strand RNA, lost to follow-up | BA2: Liver Fibrosis F2: chronic, on treatment 1 | BB2: Liver Fibrosis F2: chronic, failed treatment 1 | BC2: Liver Fibrosis F2: chronic, failed treatment 1, lost to follow-up | BD2: Liver Fibrosis F2: susceptible with antibodies (aware and treated) | BE2: Liver Fibrosis F2: acute (re-infection) | BF2: Liver Fibrosis F2: chronic, on treatment 2 | BG2: Liver Fibrosis F2: chronic, failed treatment 2 | BH2: Liver Fibrosis F3: chronic, undiagnosed antibodies positive | BI2: Liver Fibrosis F3: chronic, undiagnosed, lost to care | BJ2: Liver Fibrosis F3: chronic, diagnosed antibodies positive | BK2: Liver Fibrosis F3: chronic, diagnosed antibodies positive, lost to follow-up | BL2: Liver Fibrosis F3: chronic, diagnosed positive-strand RNA (PCR test) | BM2: Liver Fibrosis F3: chronic, diagnosed positive-strand RNA, lost to follow-up | BN2: Liver Fibrosis F3: chronic, on treatment 1 | BO2: Liver Fibrosis F3: chronic, failed treatment 1 | BP2: Liver Fibrosis F3: chronic, failed treatment 1, lost to follow-up | BQ2: Liver Fibrosis F3: susceptible with antibodies (aware and treated) | BR2: Liver Fibrosis F3: acute (re-infection) | BS2: Liver Fibrosis F3: chronic, on treatment 2 | BT2: Liver Fibrosis F3: chronic, failed treatment 2 | BU2: Liver Fibrosis F4: chronic, undiagnosed antibodies positive | BV2: Liver Fibrosis F4: chronic, undiagnosed, lost to care | BW2: Liver Fibrosis F4: chronic, diagnosed antibodies positive | BX2: Liver Fibrosis F4: chronic, diagnosed antibodies positive, lost to follow-up | BY2: Liver Fibrosis F4: chronic, diagnosed positive-strand RNA (PCR test) | BZ2: Liver Fibrosis F4: chronic, diagnosed positive-strand RNA, lost to follow-up | CA2: Liver Fibrosis F4: chronic, on treatment 1 | CB2: Liver Fibrosis F4: chronic, failed treatment 1 | CC2: Liver Fibrosis F4: chronic, failed treatment 1, lost to follow-up | CD2: Liver Fibrosis F4: susceptible with antibodies (aware and treated) | CE2: Liver Fibrosis F4: acute (re-infection) | CF2: Liver Fibrosis F4: chronic, on treatment 2 | CG2: Liver Fibrosis F4: chronic, failed treatment 2 | CH2: Decompensated Cirrhosis: chronic, undiagnosed antibodies positive | CI2: Decompensated Cirrhosis: chronic, undiagnosed, lost to care | CJ2: Decompensated Cirrhosis: chronic, diagnosed antibodies positive | CK2: Decompensated Cirrhosis: chronic, diagnosed antibodies positive, lost to follow-up | CL2: Decompensated Cirrhosis: chronic, diagnosed positive-strand RNA (PCR test) | CM2: Decompensated Cirrhosis: chronic, diagnosed positive-strand RNA, lost to follow-up | CN2: Decompensated Cirrhosis: chronic, on treatment 1 | CO2: Decompensated Cirrhosis: chronic, failed treatment 1 | CP2: Decompensated Cirrhosis: chronic, failed treatment 1, lost to follow-up | CQ2: Decompensated Cirrhosis: susceptible with antibodies (aware and treated) | CR2: Decompensated Cirrhosis: acute (re-infection) | CS2: Decompensated Cirrhosis: chronic, on treatment 2 | CT2: Decompensated Cirrhosis: chronic, failed treatment 2 | CU2: Decompensated Cirrhosis: liver transplant 1 year ago | CV2: Decompensated Cirrhosis: liver transplant 2+ years ago | CW2: Hepatocellular Carcinoma: chronic, undiagnosed antibodies positive | CX2: Hepatocellular Carcinoma: chronic, undiagnosed, lost to care | CY2: Hepatocellular Carcinoma: chronic, diagnosed antibodies positive | CZ2: Hepatocellular Carcinoma: chronic, diagnosed antibodies positive, lost to follow-up | DA2: Hepatocellular Carcinoma: chronic, diagnosed positive-strand RNA (PCR test) | DB2: Hepatocellular Carcinoma: chronic, diagnosed positive-strand RNA, lost to follow-up | DC2: Hepatocellular Carcinoma: chronic, on treatment 1 | DD2: Hepatocellular Carcinoma: chronic, failed treatment 1 | DE2: Hepatocellular Carcinoma: chronic, failed treatment 1, lost to follow-up | DF2: Hepatocellular Carcinoma: susceptible with antibodies (aware and treated) | DG2: Hepatocellular Carcinoma: acute (re-infection) | DH2: Hepatocellular Carcinoma: chronic, on treatment 2 | DI2: Hepatocellular Carcinoma: chronic, failed treatment 2 | DJ2: Hepatocellular Carcinoma: liver transplant 1 year ago | DK2: Hepatocellular Carcinoma: liver transplant 2+ years ago | DL2: Susceptible: never infected (vaccinated) | DM2: Liver Fibrosis F0: susceptible with antibodies (unaware) (vaccinated) | DN2: Liver Fibrosis F0: susceptible with antibodies (aware) (vaccinated) | DO2: Liver Fibrosis F0: acute, undiagnosed antibody positive (vaccinated) | DP2: Liver Fibrosis F0: acute, diagnosed antibody positive (first infection, aware) (vaccinated) | DQ2: Liver Fibrosis F0: chronic, undiagnosed antibodies positive (vaccinated) | DR2: Liver Fibrosis F0: chronic, undiagnosed, lost to care (vaccinated) | DS2: Liver Fibrosis F0: chronic, diagnosed antibodies positive (vaccinated) | DT2: Liver Fibrosis F0: chronic, diagnosed antibodies positive, lost to follow-up (vaccinated) | DU2: Liver Fibrosis F0: chronic, diagnosed positive-strand RNA (PCR test) (vaccinated) | DV2: Liver Fibrosis F0: chronic, diagnosed positive-strand RNA, lost to follow-up (vaccinated) | DW2: Liver Fibrosis F0: chronic, on treatment 1 (vaccinated) | DX2: Liver Fibrosis F0: chronic, failed treatment 1 (vaccinated) | DY2: Liver Fibrosis F0: chronic, failed treatment 1, lost to follow-up (vaccinated) | DZ2: Liver Fibrosis F0: susceptible with antibodies (aware and treated) (vaccinated) | EA2: Liver Fibrosis F0: acute (re-infection) (vaccinated) | EB2: Liver Fibrosis F0: chronic, on treatment 2 (vaccinated) | EC2: Liver Fibrosis F0: chronic, failed treatment 2 (vaccinated) | ED2: Liver Fibrosis F1: chronic, undiagnosed antibodies positive (vaccinated) | EE2: Liver Fibrosis F1: chronic, undiagnosed, lost to care (vaccinated) | EF2: Liver Fibrosis F1: chronic, diagnosed antibodies positive (vaccinated) | EG2: Liver Fibrosis F1: chronic, diagnosed antibodies positive, lost to follow-up (vaccinated) | EH2: Liver Fibrosis F1: chronic, diagnosed positive-strand RNA (PCR test) (vaccinated) | EI2: Liver Fibrosis F1: chronic, diagnosed positive-strand RNA, lost to follow-up (vaccinated) | EJ2: Liver Fibrosis F1: chronic, on treatment 1 (vaccinated) | EK2: Liver Fibrosis F1: chronic, failed treatment 1 (vaccinated) | EL2: Liver Fibrosis F1: chronic, failed treatment 1, lost to follow-up (vaccinated) | EM2: Liver Fibrosis F1: susceptible with antibodies (aware and treated) (vaccinated) | EN2: Liver Fibrosis F1: acute (re-infection) (vaccinated) | EO2: Liver Fibrosis F1: chronic, on treatment 2 (vaccinated) | EP2: Liver Fibrosis F1: chronic, failed treatment 2 (vaccinated) | EQ2: Liver Fibrosis F2: chronic, undiagnosed antibodies positive (vaccinated) | ER2: Liver Fibrosis F2: chronic, undiagnosed, lost to care (vaccinated) | ES2: Liver Fibrosis F2: chronic, diagnosed antibodies positive (vaccinated) | ET2: Liver Fibrosis F2: chronic, diagnosed antibodies positive, lost to follow-up (vaccinated) | EU2: Liver Fibrosis F2: chronic, diagnosed positive-strand RNA (PCR test) (vaccinated) | EV2: Liver Fibrosis F2: chronic, diagnosed positive-strand RNA, lost to follow-up (vaccinated) | EW2: Liver Fibrosis F2: chronic, on treatment 1 (vaccinated) | EX2: Liver Fibrosis F2: chronic, failed treatment 1 (vaccinated) | EY2: Liver Fibrosis F2: chronic, failed treatment 1, lost to follow-up (vaccinated) | EZ2: Liver Fibrosis F2: susceptible with antibodies (aware and treated) (vaccinated) | FA2: Liver Fibrosis F2: acute (re-infection) (vaccinated) | FB2: Liver Fibrosis F2: chronic, on treatment 2 (vaccinated) | FC2: Liver Fibrosis F2: chronic, failed treatment 2 (vaccinated) | FD2: Liver Fibrosis F3: chronic, undiagnosed antibodies positive (vaccinated) | FE2: Liver Fibrosis F3: chronic, undiagnosed, lost to care (vaccinated) | FF2: Liver Fibrosis F3: chronic, diagnosed antibodies positive (vaccinated) | FG2: Liver Fibrosis F3: chronic, diagnosed antibodies positive, lost to follow-up (vaccinated) | FH2: Liver Fibrosis F3: chronic, diagnosed positive-strand RNA (PCR test) (vaccinated) | FI2: Liver Fibrosis F3: chronic, diagnosed positive-strand RNA, lost to follow-up (vaccinated) | FJ2: Liver Fibrosis F3: chronic, on treatment 1 (vaccinated) | FK2: Liver Fibrosis F3: chronic, failed treatment 1 (vaccinated) | FL2: Liver Fibrosis F3: chronic, failed treatment 1, lost to follow-up (vaccinated) | FM2: Liver Fibrosis F3: susceptible with antibodies (aware and treated) (vaccinated) | FN2: Liver Fibrosis F3: acute (re-infection) (vaccinated) | FO2: Liver Fibrosis F3: chronic, on treatment 2 (vaccinated) | FP2: Liver Fibrosis F3: chronic, failed treatment 2 (vaccinated) | FQ2: Liver Fibrosis F4: chronic, undiagnosed antibodies positive (vaccinated) | FR2: Liver Fibrosis F4: chronic, undiagnosed, lost to care (vaccinated) | FS2: Liver Fibrosis F4: chronic, diagnosed antibodies positive (vaccinated) | FT2: Liver Fibrosis F4: chronic, diagnosed antibodies positive, lost to follow-up (vaccinated) | FU2: Liver Fibrosis F4: chronic, diagnosed positive-strand RNA (PCR test) (vaccinated) | FV2: Liver Fibrosis F4: chronic, diagnosed positive-strand RNA, lost to follow-up (vaccinated) | FW2: Liver Fibrosis F4: chronic, on treatment 1 (vaccinated) | FX2: Liver Fibrosis F4: chronic, failed treatment 1 (vaccinated) | FY2: Liver Fibrosis F4: chronic, failed treatment 1, lost to follow-up (vaccinated) | FZ2: Liver Fibrosis F4: susceptible with antibodies (aware and treated) (vaccinated) | GA2: Liver Fibrosis F4: acute (re-infection) (vaccinated) | GB2: Liver Fibrosis F4: chronic, on treatment 2 (vaccinated) | GC2: Liver Fibrosis F4: chronic, failed treatment 2 (vaccinated) | GD2: Decompensated Cirrhosis: chronic, undiagnosed antibodies positive (vaccinated) | GE2: Decompensated Cirrhosis: chronic, undiagnosed, lost to care (vaccinated) | GF2: Decompensated Cirrhosis: chronic, diagnosed antibodies positive (vaccinated) | GG2: Decompensated Cirrhosis: chronic, diagnosed antibodies positive, lost to follow-up (vaccinated) | GH2: Decompensated Cirrhosis: chronic, diagnosed positive-strand RNA (PCR test) (vaccinated) | GI2: Decompensated Cirrhosis: chronic, diagnosed positive-strand RNA, lost to follow-up (vaccinated) | GJ2: Decompensated Cirrhosis: chronic, on treatment 1 (vaccinated) | GK2: Decompensated Cirrhosis: chronic, failed treatment 1 (vaccinated) | GL2: Decompensated Cirrhosis: chronic, failed treatment 1, lost to follow-up (vaccinated) | GM2: Decompensated Cirrhosis: susceptible with antibodies (aware and treated) (vaccinated) | GN2: Decompensated Cirrhosis: acute (re-infection) (vaccinated) | GO2: Decompensated Cirrhosis: chronic, on treatment 2 (vaccinated) | GP2: Decompensated Cirrhosis: chronic, failed treatment 2 (vaccinated) | GQ2: Decompensated Cirrhosis: liver transplant 1 year ago (vaccinated) | GR2: Decompensated Cirrhosis: liver transplant 2+ years ago (vaccinated) | GS2: Hepatocellular Carcinoma: chronic, undiagnosed antibodies positive (vaccinated) | GT2: Hepatocellular Carcinoma: chronic, undiagnosed, lost to care (vaccinated) | GU2: Hepatocellular Carcinoma: chronic, diagnosed antibodies positive (vaccinated) | GV2: Hepatocellular Carcinoma: chronic, diagnosed antibodies positive, lost to follow-up (vaccinated) | GW2: Hepatocellular Carcinoma: chronic, diagnosed positive-strand RNA (PCR test) (vaccinated) | GX2: Hepatocellular Carcinoma: chronic, diagnosed positive-strand RNA, lost to follow-up (vaccinated) | GY2: Hepatocellular Carcinoma: chronic, on treatment 1 (vaccinated) | GZ2: Hepatocellular Carcinoma: chronic, failed treatment 1 (vaccinated) | HA2: Hepatocellular Carcinoma: chronic, failed treatment 1, lost to follow-up (vaccinated) | HB2: Hepatocellular Carcinoma: susceptible with antibodies (aware and treated) (vaccinated) | HC2: Hepatocellular Carcinoma: acute (re-infection) (vaccinated) | HD2: Hepatocellular Carcinoma: chronic, on treatment 2 (vaccinated) | HE2: Hepatocellular Carcinoma: chronic, failed treatment 2 (vaccinated) | HF2: Hepatocellular Carcinoma: liver transplant 1 year ago (vaccinated) | HG2: Hepatocellular Carcinoma: liver transplant 2+ years ago (vaccinated)
A3: pwid_vax | B3: PWID – Vaccine coverage matching existing testing | C3: Y | D3: Y | E3: N | F3: N | G3: N | H3: N | I3: N | J3: N | K3: N | L3: N | M3: N | N3: N | P3: Y | Q3: Y | R3: Y | S3: N | T3: N | U3: N | V3: N | W3: N | X3: N | Y3: N | Z3: N | AA3: N | AB3: N | AC3: N | AD3: Y | AE3: N | AF3: N | AG3: N | AH3: N | AI3: N | AJ3: N | AK3: N | AL3: N | AM3: N | AN3: N | AO3: N | AP3: N | AQ3: Y | AR3: N | AS3: N | AT3: N | AU3: N | AV3: N | AW3: N | AX3: N | AY3: N | AZ3: N | BA3: N | BB3: N | BC3: N | BD3: Y | BE3: N | BF3: N | BG3: N | BH3: N | BI3: N | BJ3: N | BK3: N | BL3: N | BM3: N | BN3: N | BO3: N | BP3: N | BQ3: Y | BR3: N | BS3: N | BT3: N | BU3: N | BV3: N | BW3: N | BX3: N | BY3: N | BZ3: N | CA3: N | CB3: N | CC3: N | CD3: Y | CE3: N | CF3: N | CG3: N | CH3: N | CI3: N | CJ3: N | CK3: N | CL3: N | CM3: N | CN3: N | CO3: N | CP3: N | CQ3: Y | CR3: N | CS3: N | CT3: N | CU3: N | CV3: N | CW3: N | CX3: N | CY3: N | CZ3: N | DA3: N | DB3: N | DC3: N | DD3: N | DE3: N | DF3: Y | DG3: N | DH3: N | DI3: N | DJ3: N | DK3: N | DL3: N | DM3: N | DN3: N | DO3: N | DP3: N | DQ3: N | DR3: N | DS3: N | DT3: N | DU3: N | DV3: N | DW3: N | DX3: N | DY3: N | DZ3: N | EA3: N | EB3: N | EC3: N | ED3: N | EE3: N | EF3: N | EG3: N | EH3: N | EI3: N | EJ3: N | EK3: N | EL3: N | EM3: N | EN3: N | EO3: N | EP3: N | EQ3: N | ER3: N | ES3: N | ET3: N | EU3: N | EV3: N | EW3: N | EX3: N | EY3: N | EZ3: N | FA3: N | FB3: N | FC3: N | FD3: N | FE3: N | FF3: N | FG3: N | FH3: N | FI3: N | FJ3: N | FK3: N | FL3: N | FM3: N | FN3: N | FO3: N | FP3: N | FQ3: N | FR3: N | FS3: N | FT3: N | FU3: N | FV3: N | FW3: N | FX3: N | FY3: N | FZ3: N | GA3: N | GB3: N | GC3: N | GD3: N | GE3: N | GF3: N | GG3: N | GH3: N | GI3: N | GJ3: N | GK3: N | GL3: N | GM3: N | GN3: N | GO3: N | GP3: N | GQ3: N | GR3: N | GS3: N | GT3: N | GU3: N | GV3: N | GW3: N | GX3: N | GY3: N | GZ3: N | HA3: N | HB3: N | HC3: N | HD3: N | HE3: N | HF3: N | HG3: N
A4: pwid_vax_campaign | B4: PWID – Vaccine + Test & Treat scale-up | C4: Y | D4: Y | E4: N | F4: N | G4: N | H4: N | I4: N | J4: N | K4: N | L4: N | M4: N | N4: N | P4: Y | Q4: Y | R4: Y | S4: Y | T4: N | U4: Y | V4: Y | W4: N | X4: N | Y4: N | Z4: N | AA4: N | AB4: N | AC4: N | AD4: Y | AE4: Y | AF4: N | AG4: N | AH4: Y | AI4: Y | AJ4: N | AK4: N | AL4: N | AM4: N | AN4: N | AO4: N | AP4: N | AQ4: Y | AR4: Y | AS4: N | AT4: N | AU4: Y | AV4: Y | AW4: N | AX4: N | AY4: N | AZ4: N | BA4: N | BB4: N | BC4: N | BD4: Y | BE4: Y | BF4: N | BG4: N | BH4: Y | BI4: Y | BJ4: N | BK4: N | BL4: N | BM4: N | BN4: N | BO4: N | BP4: N | BQ4: Y | BR4: Y | BS4: N | BT4: N | BU4: Y | BV4: Y | BW4: N | BX4: N | BY4: N | BZ4: N | CA4: N | CB4: N | CC4: N | CD4: Y | CE4: Y | CF4: N | CG4: N | CH4: Y | CI4: Y | CJ4: N | CK4: N | CL4: N | CM4: N | CN4: N | CO4: N | CP4: N | CQ4: Y | CR4: Y | CS4: N | CT4: N | CU4: N | CV4: N | CW4: Y | CX4: Y | CY4: N | CZ4: N | DA4: N | DB4: N | DC4: N | DD4: N | DE4: N | DF4: Y | DG4: Y | DH4: N | DI4: N | DJ4: N | DK4: N | DL4: N | DM4: N | DN4: N | DO4: N | DP4: N | DQ4: N | DR4: N | DS4: N | DT4: N | DU4: N | DV4: N | DW4: N | DX4: N | DY4: N | DZ4: N | EA4: N | EB4: N | EC4: N | ED4: N | EE4: N | EF4: N | EG4: N | EH4: N | EI4: N | EJ4: N | EK4: N | EL4: N | EM4: N | EN4: N | EO4: N | EP4: N | EQ4: N | ER4: N | ES4: N | ET4: N | EU4: N | EV4: N | EW4: N | EX4: N | EY4: N | EZ4: N | FA4: N | FB4: N | FC4: N | FD4: N | FE4: N | FF4: N | FG4: N | FH4: N | FI4: N | FJ4: N | FK4: N | FL4: N | FM4: N | FN4: N | FO4: N | FP4: N | FQ4: N | FR4: N | FS4: N | FT4: N | FU4: N | FV4: N | FW4: N | FX4: N | FY4: N | FZ4: N | GA4: N | GB4: N | GC4: N | GD4: N | GE4: N | GF4: N | GG4: N | GH4: N | GI4: N | GJ4: N | GK4: N | GL4: N | GM4: N | GN4: N | GO4: N | GP4: N | GQ4: N | GR4: N | GS4: N | GT4: N | GU4: N | GV4: N | GW4: N | GX4: N | GY4: N | GZ4: N | HA4: N | HB4: N | HC4: N | HD4: N | HE4: N | HF4: N | HG4: N
A5: prison_vax_campaign | B5: Prisoners – Vaccine + Test & Treat scale-up | C5: N | D5: N | E5: N | F5: N | G5: N | H5: N | I5: N | J5: N | K5: N | L5: N | M5: Y | N5: Y | P5: Y | Q5: Y | R5: Y | S5: Y | T5: N | U5: Y | V5: Y | W5: N | X5: N | Y5: N | Z5: N | AA5: N | AB5: N | AC5: N | AD5: Y | AE5: Y | AF5: N | AG5: N | AH5: Y | AI5: Y | AJ5: N | AK5: N | AL5: N | AM5: N | AN5: N | AO5: N | AP5: N | AQ5: Y | AR5: Y | AS5: N | AT5: N | AU5: Y | AV5: Y | AW5: N | AX5: N | AY5: N | AZ5: N | BA5: N | BB5: N | BC5: N | BD5: Y | BE5: Y | BF5: N | BG5: N | BH5: Y | BI5: Y | BJ5: N | BK5: N | BL5: N | BM5: N | BN5: N | BO5: N | BP5: N | BQ5: Y | BR5: Y | BS5: N | BT5: N | BU5: Y | BV5: Y | BW5: N | BX5: N | BY5: N | BZ5: N | CA5: N | CB5: N | CC5: N | CD5: Y | CE5: Y | CF5: N | CG5: N | CH5: Y | CI5: Y | CJ5: N | CK5: N | CL5: N | CM5: N | CN5: N | CO5: N | CP5: N | CQ5: Y | CR5: Y | CS5: N | CT5: N | CU5: N | CV5: N | CW5: Y | CX5: Y | CY5: N | CZ5: N | DA5: N | DB5: N | DC5: N | DD5: N | DE5: N | DF5: Y | DG5: Y | DH5: N | DI5: N | DJ5: N | DK5: N | DL5: N | DM5: N | DN5: N | DO5: N | DP5: N | DQ5: N | DR5: N | DS5: N | DT5: N | DU5: N | DV5: N | DW5: N | DX5: N | DY5: N | DZ5: N | EA5: N | EB5: N | EC5: N | ED5: N | EE5: N | EF5: N | EG5: N | EH5: N | EI5: N | EJ5: N | EK5: N | EL5: N | EM5: N | EN5: N | EO5: N | EP5: N | EQ5: N | ER5: N | ES5: N | ET5: N | EU5: N | EV5: N | EW5: N | EX5: N | EY5: N | EZ5: N | FA5: N | FB5: N | FC5: N | FD5: N | FE5: N | FF5: N | FG5: N | FH5: N | FI5: N | FJ5: N | FK5: N | FL5: N | FM5: N | FN5: N | FO5: N | FP5: N | FQ5: N | FR5: N | FS5: N | FT5: N | FU5: N | FV5: N | FW5: N | FX5: N | FY5: N | FZ5: N | GA5: N | GB5: N | GC5: N | GD5: N | GE5: N | GF5: N | GG5: N | GH5: N | GI5: N | GJ5: N | GK5: N | GL5: N | GM5: N | GN5: N | GO5: N | GP5: N | GQ5: N | GR5: N | GS5: N | GT5: N | GU5: N | GV5: N | GW5: N | GX5: N | GY5: N | GZ5: N | HA5: N | HB5: N | HC5: N | HD5: N | HE5: N | HF5: N | HG5: N
A6: teen_vax | B6: Adolescents – School-based vaccination | C6: N | D6: N | E6: N | F6: N | G6: Y | H6: Y | I6: N | J6: N | K6: N | L6: N | M6: N | N6: N | P6: Y | Q6: Y | R6: Y | S6: N | T6: N | U6: N | V6: N | W6: N | X6: N | Y6: N | Z6: N | AA6: N | AB6: N | AC6: N | AD6: Y | AE6: N | AF6: N | AG6: N | AH6: N | AI6: N | AJ6: N | AK6: N | AL6: N | AM6: N | AN6: N | AO6: N | AP6: N | AQ6: Y | AR6: N | AS6: N | AT6: N | AU6: N | AV6: N | AW6: N | AX6: N | AY6: N | AZ6: N | BA6: N | BB6: N | BC6: N | BD6: Y | BE6: N | BF6: N | BG6: N | BH6: N | BI6: N | BJ6: N | BK6: N | BL6: N | BM6: N | BN6: N | BO6: N | BP6: N | BQ6: Y | BR6: N | BS6: N | BT6: N | BU6: N | BV6: N | BW6: N | BX6: N | BY6: N | BZ6: N | CA6: N | CB6: N | CC6: N | CD6: Y | CE6: N | CF6: N | CG6: N | CH6: N | CI6: N | CJ6: N | CK6: N | CL6: N | CM6: N | CN6: N | CO6: N | CP6: N | CQ6: Y | CR6: N | CS6: N | CT6: N | CU6: N | CV6: N | CW6: N | CX6: N | CY6: N | CZ6: N | DA6: N | DB6: N | DC6: N | DD6: N | DE6: N | DF6: Y | DG6: N | DH6: N | DI6: N | DJ6: N | DK6: N | DL6: N | DM6: N | DN6: N | DO6: N | DP6: N | DQ6: N | DR6: N | DS6: N | DT6: N | DU6: N | DV6: N | DW6: N | DX6: N | DY6: N | DZ6: N | EA6: N | EB6: N | EC6: N | ED6: N | EE6: N | EF6: N | EG6: N | EH6: N | EI6: N | EJ6: N | EK6: N | EL6: N | EM6: N | EN6: N | EO6: N | EP6: N | EQ6: N | ER6: N | ES6: N | ET6: N | EU6: N | EV6: N | EW6: N | EX6: N | EY6: N | EZ6: N | FA6: N | FB6: N | FC6: N | FD6: N | FE6: N | FF6: N | FG6: N | FH6: N | FI6: N | FJ6: N | FK6: N | FL6: N | FM6: N | FN6: N | FO6: N | FP6: N | FQ6: N | FR6: N | FS6: N | FT6: N | FU6: N | FV6: N | FW6: N | FX6: N | FY6: N | FZ6: N | GA6: N | GB6: N | GC6: N | GD6: N | GE6: N | GF6: N | GG6: N | GH6: N | GI6: N | GJ6: N | GK6: N | GL6: N | GM6: N | GN6: N | GO6: N | GP6: N | GQ6: N | GR6: N | GS6: N | GT6: N | GU6: N | GV6: N | GW6: N | GX6: N | GY6: N | GZ6: N | HA6: N | HB6: N | HC6: N | HD6: N | HE6: N | HF6: N | HG6: N
A7: adults_vax | B7: Adults – Catch-up campaign | C7: N | D7: N | E7: N | F7: N | G7: N | H7: N | I7: Y | J7: Y | K7: N | L7: N | M7: N | N7: N | P7: Y | Q7: Y | R7: Y | S7: N | T7: N | U7: N | V7: N | W7: N | X7: N | Y7: N | Z7: N | AA7: N | AB7: N | AC7: N | AD7: Y | AE7: N | AF7: N | AG7: N | AH7: N | AI7: N | AJ7: N | AK7: N | AL7: N | AM7: N | AN7: N | AO7: N | AP7: N | AQ7: Y | AR7: N | AS7: N | AT7: N | AU7: N | AV7: N | AW7: N | AX7: N | AY7: N | AZ7: N | BA7: N | BB7: N | BC7: N | BD7: Y | BE7: N | BF7: N | BG7: N | BH7: N | BI7: N | BJ7: N | BK7: N | BL7: N | BM7: N | BN7: N | BO7: N | BP7: N | BQ7: Y | BR7: N | BS7: N | BT7: N | BU7: N | BV7: N | BW7: N | BX7: N | BY7: N | BZ7: N | CA7: N | CB7: N | CC7: N | CD7: Y | CE7: N | CF7: N | CG7: N | CH7: N | CI7: N | CJ7: N | CK7: N | CL7: N | CM7: N | CN7: N | CO7: N | CP7: N | CQ7: Y | CR7: N | CS7: N | CT7: N | CU7: N | CV7: N | CW7: N | CX7: N | CY7: N | CZ7: N | DA7: N | DB7: N | DC7: N | DD7: N | DE7: N | DF7: Y | DG7: N | DH7: N | DI7: N | DJ7: N | DK7: N | DL7: N | DM7: N | DN7: N | DO7: N | DP7: N | DQ7: N | DR7: N | DS7: N | DT7: N | DU7: N | DV7: N | DW7: N | DX7: N | DY7: N | DZ7: N | EA7: N | EB7: N | EC7: N | ED7: N | EE7: N | EF7: N | EG7: N | EH7: N | EI7: N | EJ7: N | EK7: N | EL7: N | EM7: N | EN7: N | EO7: N | EP7: N | EQ7: N | ER7: N | ES7: N | ET7: N | EU7: N | EV7: N | EW7: N | EX7: N | EY7: N | EZ7: N | FA7: N | FB7: N | FC7: N | FD7: N | FE7: N | FF7: N | FG7: N | FH7: N | FI7: N | FJ7: N | FK7: N | FL7: N | FM7: N | FN7: N | FO7: N | FP7: N | FQ7: N | FR7: N | FS7: N | FT7: N | FU7: N | FV7: N | FW7: N | FX7: N | FY7: N | FZ7: N | GA7: N | GB7: N | GC7: N | GD7: N | GE7: N | GF7: N | GG7: N | GH7: N | GI7: N | GJ7: N | GK7: N | GL7: N | GM7: N | GN7: N | GO7: N | GP7: N | GQ7: N | GR7: N | GS7: N | GT7: N | GU7: N | GV7: N | GW7: N | GX7: N | GY7: N | GZ7: N | HA7: N | HB7: N | HC7: N | HD7: N | HE7: N | HF7: N | HG7: N
A8: pwid_counter | B8: Counterfactual scenario for pwid test&treat scale-up | C8: Y | D8: Y | E8: N | F8: N | G8: N | H8: N | I8: N | J8: N | K8: N | L8: N | M8: N | N8: N | P8: Y | Q8: Y | R8: Y | S8: Y | T8: N | U8: Y | V8: Y | W8: N | X8: N | Y8: N | Z8: N | AA8: N | AB8: N | AC8: N | AD8: Y | AE8: Y | AF8: N | AG8: N | AH8: Y | AI8: Y | AJ8: N | AK8: N | AL8: N | AM8: N | AN8: N | AO8: N | AP8: N | AQ8: Y | AR8: Y | AS8: N | AT8: N | AU8: Y | AV8: Y | AW8: N | AX8: N | AY8: N | AZ8: N | BA8: N | BB8: N | BC8: N | BD8: Y | BE8: Y | BF8: N | BG8: N | BH8: Y | BI8: Y | BJ8: N | BK8: N | BL8: N | BM8: N | BN8: N | BO8: N | BP8: N | BQ8: Y | BR8: Y | BS8: N | BT8: N | BU8: Y | BV8: Y | BW8: N | BX8: N | BY8: N | BZ8: N | CA8: N | CB8: N | CC8: N | CD8: Y | CE8: Y | CF8: N | CG8: N | CH8: Y | CI8: Y | CJ8: N | CK8: N | CL8: N | CM8: N | CN8: N | CO8: N | CP8: N | CQ8: Y | CR8: Y | CS8: N | CT8: N | CU8: N | CV8: N | CW8: Y | CX8: Y | CY8: N | CZ8: N | DA8: N | DB8: N | DC8: N | DD8: N | DE8: N | DF8: Y | DG8: Y | DH8: N | DI8: N | DJ8: N | DK8: N | DL8: N | DM8: N | DN8: N | DO8: N | DP8: N | DQ8: N | DR8: N | DS8: N | DT8: N | DU8: N | DV8: N | DW8: N | DX8: N | DY8: N | DZ8: N | EA8: N | EB8: N | EC8: N | ED8: N | EE8: N | EF8: N | EG8: N | EH8: N | EI8: N | EJ8: N | EK8: N | EL8: N | EM8: N | EN8: N | EO8: N | EP8: N | EQ8: N | ER8: N | ES8: N | ET8: N | EU8: N | EV8: N | EW8: N | EX8: N | EY8: N | EZ8: N | FA8: N | FB8: N | FC8: N | FD8: N | FE8: N | FF8: N | FG8: N | FH8: N | FI8: N | FJ8: N | FK8: N | FL8: N | FM8: N | FN8: N | FO8: N | FP8: N | FQ8: N | FR8: N | FS8: N | FT8: N | FU8: N | FV8: N | FW8: N | FX8: N | FY8: N | FZ8: N | GA8: N | GB8: N | GC8: N | GD8: N | GE8: N | GF8: N | GG8: N | GH8: N | GI8: N | GJ8: N | GK8: N | GL8: N | GM8: N | GN8: N | GO8: N | GP8: N | GQ8: N | GR8: N | GS8: N | GT8: N | GU8: N | GV8: N | GW8: N | GX8: N | GY8: N | GZ8: N | HA8: N | HB8: N | HC8: N | HD8: N | HE8: N | HF8: N | HG8: N
A9: prison_counter | B9: Counterfactual scenario for prison test&treat scale-up | C9: N | D9: N | E9: N | F9: N | G9: N | H9: N | I9: N | J9: N | K9: N | L9: N | M9: Y | N9: Y | P9: Y | Q9: Y | R9: Y | S9: Y | T9: N | U9: Y | V9: Y | W9: N | X9: N | Y9: N | Z9: N | AA9: N | AB9: N | AC9: N | AD9: Y | AE9: Y | AF9: N | AG9: N | AH9: Y | AI9: Y | AJ9: N | AK9: N | AL9: N | AM9: N | AN9: N | AO9: N | AP9: N | AQ9: Y | AR9: Y | AS9: N | AT9: N | AU9: Y | AV9: Y | AW9: N | AX9: N | AY9: N | AZ9: N | BA9: N | BB9: N | BC9: N | BD9: Y | BE9: Y | BF9: N | BG9: N | BH9: Y | BI9: Y | BJ9: N | BK9: N | BL9: N | BM9: N | BN9: N | BO9: N | BP9: N | BQ9: Y | BR9: Y | BS9: N | BT9: N | BU9: Y | BV9: Y | BW9: N | BX9: N | BY9: N | BZ9: N | CA9: N | CB9: N | CC9: N | CD9: Y | CE9: Y | CF9: N | CG9: N | CH9: Y | CI9: Y | CJ9: N | CK9: N | CL9: N | CM9: N | CN9: N | CO9: N | CP9: N | CQ9: Y | CR9: Y | CS9: N | CT9: N | CU9: N | CV9: N | CW9: Y | CX9: Y | CY9: N | CZ9: N | DA9: N | DB9: N | DC9: N | DD9: N | DE9: N | DF9: Y | DG9: Y | DH9: N | DI9: N | DJ9: N | DK9: N | DL9: N | DM9: N | DN9: N | DO9: N | DP9: N | DQ9: N | DR9: N | DS9: N | DT9: N | DU9: N | DV9: N | DW9: N | DX9: N | DY9: N | DZ9: N | EA9: N | EB9: N | EC9: N | ED9: N | EE9: N | EF9: N | EG9: N | EH9: N | EI9: N | EJ9: N | EK9: N | EL9: N | EM9: N | EN9: N | EO9: N | EP9: N | EQ9: N | ER9: N | ES9: N | ET9: N | EU9: N | EV9: N | EW9: N | EX9: N | EY9: N | EZ9: N | FA9: N | FB9: N | FC9: N | FD9: N | FE9: N | FF9: N | FG9: N | FH9: N | FI9: N | FJ9: N | FK9: N | FL9: N | FM9: N | FN9: N | FO9: N | FP9: N | FQ9: N | FR9: N | FS9: N | FT9: N | FU9: N | FV9: N | FW9: N | FX9: N | FY9: N | FZ9: N | GA9: N | GB9: N | GC9: N | GD9: N | GE9: N | GF9: N | GG9: N | GH9: N | GI9: N | GJ9: N | GK9: N | GL9: N | GM9: N | GN9: N | GO9: N | GP9: N | GQ9: N | GR9: N | GS9: N | GT9: N | GU9: N | GV9: N | GW9: N | GX9: N | GY9: N | GZ9: N | HA9: N | HB9: N | HC9: N | HD9: N | HE9: N | HF9: N | HG9: N
A10: status_quo | B10: Status-quo | C10: Y | D10: Y | E10: Y | F10: Y | G10: Y | H10: Y | I10: Y | J10: Y | K10: Y | L10: Y | M10: Y | N10: Y | P10: Y | Q10: Y | R10: Y | S10: Y | T10: Y | U10: Y | V10: Y | W10: Y | X10: N | Y10: Y | Z10: N | AA10: Y | AB10: Y | AC10: N | AD10: Y | AE10: Y | AF10: Y | AG10: Y | AH10: Y | AI10: Y | AJ10: Y | AK10: N | AL10: Y | AM10: N | AN10: Y | AO10: Y | AP10: N | AQ10: Y | AR10: Y | AS10: Y | AT10: Y | AU10: Y | AV10: Y | AW10: Y | AX10: N | AY10: Y | AZ10: N | BA10: Y | BB10: Y | BC10: N | BD10: Y | BE10: Y | BF10: Y | BG10: Y | BH10: Y | BI10: Y | BJ10: Y | BK10: N | BL10: Y | BM10: N | BN10: Y | BO10: Y | BP10: N | BQ10: Y | BR10: Y | BS10: Y | BT10: Y | BU10: Y | BV10: Y | BW10: Y | BX10: N | BY10: Y | BZ10: N | CA10: Y | CB10: Y | CC10: N | CD10: Y | CE10: Y | CF10: Y | CG10: Y | CH10: Y | CI10: Y | CJ10: Y | CK10: N | CL10: Y | CM10: N | CN10: Y | CO10: Y | CP10: N | CQ10: Y | CR10: Y | CS10: Y | CT10: Y | CU10: N | CV10: N | CW10: Y | CX10: Y | CY10: Y | CZ10: N | DA10: Y | DB10: N | DC10: Y | DD10: Y | DE10: N | DF10: Y | DG10: Y | DH10: Y | DI10: Y | DJ10: N | DK10: N | DL10: N | DM10: N | DN10: N | DO10: N | DP10: N | DQ10: N | DR10: N | DS10: N | DT10: N | DU10: N | DV10: N | DW10: N | DX10: N | DY10: N | DZ10: N | EA10: N | EB10: N | EC10: N | ED10: N | EE10: N | EF10: N | EG10: N | EH10: N | EI10: N | EJ10: N | EK10: N | EL10: N | EM10: N | EN10: N | EO10: N | EP10: N | EQ10: N | ER10: N | ES10: N | ET10: N | EU10: N | EV10: N | EW10: N | EX10: N | EY10: N | EZ10: N | FA10: N | FB10: N | FC10: N | FD10: N | FE10: N | FF10: N | FG10: N | FH10: N | FI10: N | FJ10: N | FK10: N | FL10: N | FM10: N | FN10: N | FO10: N | FP10: N | FQ10: N | FR10: N | FS10: N | FT10: N | FU10: N | FV10: N | FW10: N | FX10: N | FY10: N | FZ10: N | GA10: N | GB10: N | GC10: N | GD10: N | GE10: N | GF10: N | GG10: N | GH10: N | GI10: N | GJ10: N | GK10: N | GL10: N | GM10: N | GN10: N | GO10: N | GP10: N | GQ10: N | GR10: N | GS10: N | GT10: N | GU10: N | GV10: N | GW10: N | GX10: N | GY10: N | GZ10: N | HA10: N | HB10: N | HC10: N | HD10: N | HE10: N | HF10: N | HG10: N

Sheet Spending data
A1: pwid_vax | B1: Provenance | C1: Units | D1: Uncertainty | E1: Assumption | G1: 2026
A2: Annual spend | C2: $/year | E2: 0 | F2: OR
A3: Unit cost | C3: $/person (one-off) | E3: 40 | F3: OR
A4: Capacity constraint | C4: people/year | F4: OR
A5: Saturation | C5: N.A. | F5: OR
A6: Coverage | C6: people/year | F6: OR
A8: pwid_vax_campaign | B8: Provenance | C8: Units | D8: Uncertainty | E8: Assumption | G8: 2026
A9: Annual spend | C9: $/year | E9: 0 | F9: OR
A10: Unit cost | C10: $/person (one-off) | E10: 50 | F10: OR
A11: Capacity constraint | C11: people/year | F11: OR
A12: Saturation | C12: N.A. | F12: OR
A13: Coverage | C13: people/year | F13: OR
A15: prison_vax_campaign | B15: Provenance | C15: Units | D15: Uncertainty | E15: Assumption | G15: 2026
A16: Annual spend | C16: $/year | E16: 0 | F16: OR
A17: Unit cost | C17: $/person (one-off) | E17: 40 | F17: OR
A18: Capacity constraint | C18: people/year | F18: OR
A19: Saturation | C19: N.A. | F19: OR
A20: Coverage | C20: people/year | F20: OR
A22: teen_vax | B22: Provenance | C22: Units | D22: Uncertainty | E22: Assumption | G22: 2026
A23: Annual spend | C23: $/year | E23: 0 | F23: OR
A24: Unit cost | C24: $/person (one-off) | E24: 50 | F24: OR
A25: Capacity constraint | C25: people/year | F25: OR
A26: Saturation | C26: N.A. | F26: OR
A27: Coverage | C27: people/year | F27: OR
A29: adults_vax | B29: Provenance | C29: Units | D29: Uncertainty | E29: Assumption | G29: 2026
A30: Annual spend | C30: $/year | E30: 0 | F30: OR
A31: Unit cost | C31: $/person (one-off) | E31: 40 | F31: OR
A32: Capacity constraint | C32: people/year | F32: OR
A33: Saturation | C33: N.A. | F33: OR
A34: Coverage | C34: people/year | F34: OR
A36: pwid_counter | B36: Provenance | C36: Units | D36: Uncertainty | E36: Assumption | G36: 2026
A37: Annual spend | C37: $/year | E37: 0 | F37: OR
A38: Unit cost | C38: $/person (one-off) | E38: 40 | F38: OR
A39: Capacity constraint | C39: people/year | F39: OR
A40: Saturation | C40: N.A. | F40: OR
A41: Coverage | C41: people/year | F41: OR
A43: prison_counter | B43: Provenance | C43: Units | D43: Uncertainty | E43: Assumption | G43: 2026
A44: Annual spend | C44: $/year | E44: 0 | F44: OR
A45: Unit cost | C45: $/person (one-off) | E45: 40 | F45: OR
A46: Capacity constraint | C46: people/year | F46: OR
...

Sheet Program effects
A1: Antibody testing rate in F0-F2, undiagnosed, in care | B1: Baseline value | C1: Coverage interaction | D1: Impact interaction | E1: Uncertainty | G1: ='Program targeting'!$A$3 -> pwid_vax | H1: ='Program targeting'!$A$4 -> pwid_vax_campaign | I1: ='Program targeting'!$A$5 -> prison_vax_campaign | J1: ='Program targeting'!$A$6 -> teen_vax | K1: ='Program targeting'!$A$7 -> adults_vax | L1: ='Program targeting'!$A$8 -> pwid_counter | M1: ='Program targeting'!$A$9 -> prison_counter | N1: ='Program targeting'!$A$10 -> status_quo
A2: ='Program targeting'!$C$2 -> People Who Inject Drugs (males) | B2: 0.13 | C2: Random | E2: 0 | H2: 0.2 | L2: 0.2
A3: ='Program targeting'!$D$2 -> People Who Inject Drugs (females) | B3: 0.13 | C3: Random | E3: 0 | H3: 0.2 | L3: 0.2
A4: ='Program targeting'!$E$2 -> General Population 0-9 males | C4: Additive
A5: ='Program targeting'!$F$2 -> General Population 0-9 females | C5: Additive
A6: ='Program targeting'!$G$2 -> General Population 10-17 males | C6: Additive
A7: ='Program targeting'!$H$2 -> General Population 10-17 females | C7: Additive
A8: ='Program targeting'!$I$2 -> General Population 18-64 males | C8: Additive
A9: ='Program targeting'!$J$2 -> General Population 18-64 females | C9: Additive
A10: ='Program targeting'!$K$2 -> General Population 65+ males | C10: Additive
A11: ='Program targeting'!$L$2 -> General Population 65+ females | C11: Additive
A12: ='Program targeting'!$M$2 -> Prisoners (males) | B12: 0.13 | C12: Random | E12: 0 | I12: 0.2 | M12: 0.2
A13: ='Program targeting'!$N$2 -> Prisoners (females) | B13: 0.13 | C13: Random | E13: 0 | I13: 0.2 | M13: 0.2
A15: Antibody testing rate in F3+, undiagnosed, in care | B15: Baseline value | C15: Coverage interaction | D15: Impact interaction | E15: Uncertainty | G15: ='Program targeting'!$A$3 -> pwid_vax | H15: ='Program targeting'!$A$4 -> pwid_vax_campaign | I15: ='Program targeting'!$A$5 -> prison_vax_campaign | J15: ='Program targeting'!$A$6 -> teen_vax | K15: ='Program targeting'!$A$7 -> adults_vax | L15: ='Program targeting'!$A$8 -> pwid_counter | M15: ='Program targeting'!$A$9 -> prison_counter | N15: ='Program targeting'!$A$10 -> status_quo
A16: ='Program targeting'!$C$2 -> People Who Inject Drugs (males) | B16: 0.13 | C16: Random | E16: 0 | H16: 0.2 | L16: 0.2
A17: ='Program targeting'!$D$2 -> People Who Inject Drugs (females) | B17: 0.13 | C17: Random | E17: 0 | H17: 0.2 | L17: 0.2
A18: ='Program targeting'!$E$2 -> General Population 0-9 males | C18: Additive
A19: ='Program targeting'!$F$2 -> General Population 0-9 females | C19: Additive
A20: ='Program targeting'!$G$2 -> General Population 10-17 males | C20: Additive
A21: ='Program targeting'!$H$2 -> General Population 10-17 females | C21: Additive
A22: ='Program targeting'!$I$2 -> General Population 18-64 males | C22: Additive
A23: ='Program targeting'!$J$2 -> General Population 18-64 females | C23: Additive
A24: ='Program targeting'!$K$2 -> General Population 65+ males | C24: Additive
A25: ='Program targeting'!$L$2 -> General Population 65+ females | C25: Additive
A26: ='Program targeting'!$M$2 -> Prisoners (males) | B26: 0.13 | C26: Random | E26: 0 | I26: 0.2 | M26: 0.2
A27: ='Program targeting'!$N$2 -> Prisoners (females) | B27: 0.13 | C27: Random | E27: 0 | I27: 0.2 | M27: 0.2
A29: RNA testing rate in F0-F2, Ab diagnosed, in care | B29: Baseline value | C29: Coverage interaction | D29: Impact interaction | E29: Uncertainty | G29: ='Program targeting'!$A$3 -> pwid_vax | H29: ='Program targeting'!$A$4 -> pwid_vax_campaign | I29: ='Program targeting'!$A$5 -> prison_vax_campaign | J29: ='Program targeting'!$A$6 -> teen_vax | K29: ='Program targeting'!$A$7 -> adults_vax | L29: ='Program targeting'!$A$8 -> pwid_counter | M29: ='Program targeting'!$A$9 -> prison_counter | N29: ='Program targeting'!$A$10 -> status_quo
A30: ='Program targeting'!$C$2 -> People Who Inject Drugs (males) | B30: 0.2 | C30: Random | E30: 0 | H30: 0.2 | L30: 0.2
A31: ='Program targeting'!$D$2 -> People Who Inject Drugs (females) | B31: 0.2 | C31: Random | E31: 0 | H31: 0.2 | L31: 0.2
A32: ='Program targeting'!$E$2 -> General Population 0-9 males | C32: Additive
A33: ='Program targeting'!$F$2 -> General Population 0-9 females | C33: Additive
A34: ='Program targeting'!$G$2 -> General Population 10-17 males | C34: Additive
A35: ='Program targeting'!$H$2 -> General Population 10-17 females | C35: Additive
A36: ='Program targeting'!$I$2 -> General Population 18-64 males | C36: Additive
A37: ='Program targeting'!$J$2 -> General Population 18-64 females | C37: Additive
A38: ='Program targeting'!$K$2 -> General Population 65+ males | C38: Additive
A39: ='Program targeting'!$L$2 -> General Population 65+ females | C39: Additive
A40: ='Program targeting'!$M$2 -> Prisoners (males) | B40: 0.2 | C40: Random | E40: 0 | I40: 0.2 | M40: 0.2
A41: ='Program targeting'!$N$2 -> Prisoners (females) | B41: 0.2 | C41: Random | E41: 0 | I41: 0.2 | M41: 0.2
A43: RNA testing rate in F3+, Ab diagnosed, in care | B43: Baseline value | C43: Coverage interaction | D43: Impact interaction | E43: Uncertainty | G43: ='Program targeting'!$A$3 -> pwid_vax | H43: ='Program targeting'!$A$4 -> pwid_vax_campaign | I43: ='Program targeting'!$A$5 -> prison_vax_campaign | J43: ='Program targeting'!$A$6 -> teen_vax | K43: ='Program targeting'!$A$7 -> adults_vax | L43: ='Program targeting'!$A$8 -> pwid_counter | M43: ='Program targeting'!$A$9 -> prison_counter | N43: ='Program targeting'!$A$10 -> status_quo
...
